Workbook

Sheet THÔNG SỐ CHO TRƯỚC
B1: BÀI TẬP LỚN LÝ THUYẾT Ô TÔ - TÍNH TOÁN ĐỘNG LỰC HỌC Ô TÔ TẢI
B2: NHÓM SỐ 2 - ĐỘNG CƠ DIESEL
B5: THÔNG SỐ CHO TRƯỚC
B6: STT | C6: Tên thông số / Đại lượng | D6: Ký hiệu | E6: Giá trị | F6: Đơn vị | G6: Nguồn gốc / Ghi chú
B7: 1 | C7: Loại ô tô | D7: - | E7: Tải | F7: - | G7: Đề bài cho
B8: 2 | C8: Số người chở (kể cả người lái) | E8: 2 | F8: người | G8: Đề bài cho
B9: 3 | C9: Tải trọng bản thân | E9: 3450 | F9: kG | G9: Đề bài cho
B10: 4 | C10: Tải trọng định mức | E10: 4100 | F10: kG | G10: Đề bài cho
B11: 5 | C11: Hệ số phân bố cầu trước | E11: 0.3 | F11: - | G11: Đề bài cho
B12: 6 | C12: Hệ số phân bố cầu sau | E12: 0.7 | F12: - | G12: Đề bài cho
B13: 7 | C13: Vận tốc cực đại | E13: 95 | F13: km/h | G13: Đề bài cho
B14: 8 | C14: Sức cản lớn nhất của đường | E14: 0.31 | F14: - | G14: Đề bài cho
B15: 9 | C15: Lắp động cơ đốt trong | D15: - | E15: Diesel | F15: - | G15: Đề bài cho
B19: THÔNG SỐ CẦN CHỌN
B20: STT | C20: Tên thông số / Đại lượng | D20: Ký hiệu | E20: Giá trị | F20: Đơn vị | G20: Nguồn gốc / Ghi chú
B21: 10 | C21: Khối lượng một người | E21: 65 | F21: kG | G21: Tra chọn theo tiêu chuẩn thiết kế
B22: 11 | C22: Độ dốc | D22: i | E22: 0 | F22: độ | G22: Xe chỉ có đạt được vận tốc max khi đi trên đường bằng phẳng
B23: 12 | C23: Hệ số cản lăn | D23: f | E23: 0.015 | F23: - | G23: Tra chọn đường nhựa tốt
B24: 13 | C24: Hệ số cản mặt đường ở v_max | D24: Ψ | E24: =E23*(1+(($E$13/3.6)^(2))/1500) -> 0.021963735 | F24: - | G24: Công thức
B25: 14 | C25: Hệ số cản không khí | D25: K | E25: 0.65 | F25: N.s2/m4 | G25: Tra chọn sơ bộ cho xe tải
B26: 15 | C26: Diện tích cản chính diện | D26: F | E26: 4.5 | F26: m2 | G26: Tra chọn sơ bộ theo B*H
B27: 16 | C27: Hiệu suất hệ thống truyền lực | E27: 0.85 | F27: - | G27: Tra chọn sơ bộ với ô tô truyền lực chính hai cấp
B28: 17 | C28: Tỷ lệ số vòng quay cực đại | D28: λ | E28: 0.9 | F28: - | G28: Tra cứu - chọn số liệu
B29: 18 | C29: Số vòng quay lớn nhất của động cơ | E29: 2600 | F29: vòng/phút | G29: Tra cứu - chọn số liệu
B30: 19 | C30: Hệ số thực nghiệm Leyderman a | D30: a | E30: 0.5 | F30: - | G30: Tra cứu - chọn số liệu với động cơ diesel buồng cháy trực tiếp
B31: 20 | C31: Hệ số thực nghiệm Leyderman b | D31: b | E31: 1.5 | F31: - | G31: Tra cứu - chọn số liệu với động cơ diesel buồng cháy trực tiếp
B32: 21 | C32: Hệ số thực nghiệm Leyderman c | D32: c | E32: 1 | F32: - | G32: Tra cứu - chọn số liệu với động cơ diesel buồng cháy trực tiếp
B33: 22 | C33: Hệ số biến dạng lốp | D33: λ | E33: 0.95 | F33: - | G33: Tra cứu - chọn số liệu

Sheet TÍNH TOÁN 
B1: BÀI TẬP LỚN LÝ THUYẾT Ô TÔ - TÍNH TOÁN ĐỘNG LỰC HỌC Ô TÔ TẢI
B2: NHÓM SỐ 2 - ĐỘNG CƠ DIESEL
B4: TÍNH TOÁN TRỌNG LƯỢNG
B5: STT | C5: Tên thông số / Đại lượng | D5: Ký hiệu | E5: Giá trị | F5: Đơn vị | G5: Công thức / Nguồn (Trang cắt ảnh)
B6: 1 | C6: Trọng lượng toàn bộ | D6: G | E6: ='THÔNG SỐ CHO TRƯỚC'!E9+('THÔNG SỐ CHO TRƯỚC'!E8*'THÔNG SỐ CHO TRƯỚC'!E21)+'THÔNG SỐ CHO TRƯỚC'!E10 -> 7680 | F6: kG | G6: Tra cứu công thức
B7: 2 | C7: Tải trọng phân bố lên cầu trước | E7: =E6*'THÔNG SỐ CHO TRƯỚC'!E11 -> 2304 | F7: kG | G7: Tỉ lệ phân bố cho trước của cầu trước là 0.3
B8: 3 | C8: Tải trọng phân bố lên cầu sau | E8: =E6*'THÔNG SỐ CHO TRƯỚC'!E12 -> 5376 | F8: kG | G8: Tỉ lệ phân bố cho trước của cầu sau là 0.7
B9: 4 | C9: Số lốp xe ở cầu sau (bánh kép) | E9: 4 | F9: lốp | G9: Tra cứu công thức
B10: 5 | C10: Tải trọng tác dụng lên 1 lốp sau | E10: =E8/4 -> 1344 | F10: kG | G10: Xe tải để chịu được tải trọng lớn ở phía sau thì bắt buộc cầu sau phải dùng lốp kép (mỗi bên 2 lốp, tổng là 4 lốp).
B11: 6 | C11: Ký hiệu lốp chọn sơ bộ | D11: _ | E11: 8.25-16 | F11: _ | G11: Tra cứu
B12: 7 | C12: Bề mặt lốp | D12: B | E12: =8.25 -> 8.25 | F12: inch | G12: Từ ký hiệu lốp
B13: 8 | C13: Đường kính vành | D13: d | E13: 16 | F13: inch | G13: Từ ký hiệu lốp
B14: 9 | C14: Bán kính thiết kế | E14: =(E12+(E13/2))*0.0254 -> 0.41275 | F14: m | G14: Tra cứu công thức
B15: 10 | C15: Bán kính làm việc trung bình | E15: =E14*'THÔNG SỐ CHO TRƯỚC'!E33 -> 0.3921125 | F15: m | G15: Tra cứu công thức
B21: TÍNH TOÁN TRỌNG LƯỢNG
B22: STT | C22: Tên thông số / Đại lượng | D22: Ký hiệu | E22: Giá trị | F22: Đơn vị | G22: Công thức / Nguồn (Trang cắt ảnh)
B23: 11 | C23: Công suất thắng lực cản lăn | E23: =((E6*9.81)*'THÔNG SỐ CHO TRƯỚC'!E24*('THÔNG SỐ CHO TRƯỚC'!E13/3.6))/(1000) -> 43.667419 | F23: kW | G23: Tách từ công thức tổng Nv
B24: 12 | C24: Công suất thắng lực cản không khí | E24: =('THÔNG SỐ CHO TRƯỚC'!E25*'THÔNG SỐ CHO TRƯỚC'!E26*('THÔNG SỐ CHO TRƯỚC'!E13/3.6)^(3))/(1000) -> 53.751326 | F24: kW | G24: Tách từ công thức tổng Nv
B25: 13 | C25: Công suất tổng cộng tại bánh xe chủ động | E25: =E24+E23 -> 97.418745 | F25: kW | G25: Tách từ công thức tổng Nv
B26: 14 | C26: Công suất yêu cầu ở v_max | E26: =E25/'THÔNG SỐ CHO TRƯỚC'!E27 -> 114.61029 | F26: kW | G26: Tra cứu công thức
B27: 15 | C27: Công suất cực đại động cơ | E27: =E26/('THÔNG SỐ CHO TRƯỚC'!E30*'THÔNG SỐ CHO TRƯỚC'!E28+'THÔNG SỐ CHO TRƯỚC'!E31*('THÔNG SỐ CHO TRƯỚC'!E28^(2))-'THÔNG SỐ CHO TRƯỚC'!E32*('THÔNG SỐ CHO TRƯỚC'!E28^(3))) -> 122.44689 | F27: kW | G27: Tra cứu công thức
B28: 16 | C28: Vòng quay định mức | E28: ='THÔNG SỐ CHO TRƯỚC'!E29/'THÔNG SỐ CHO TRƯỚC'!E28 -> 2888.8889 | F28: vòng/phút | G28: Tra cứu công thức
B31: Đặc tính tốc độ ngoài của động cơ
B32: Cách thực hiện | E32: Ta chọn lần lượt các giá trị ne trong khoảng cầm chừng đến khi đạt cực đại sau đó áp dụng công thức để tính Ne , Me để vẽ được đồ thị
B33: Khoảng chọn ne | E33: Đồ thị: 800–2600 vòng/phút; thêm điểm 2470 vòng/phút
B34: ne ( vòng/phút ) | C34: Ne (kW) | E34: Me (N.m)
B35: 800 | C35: =$E$27 * ('THÔNG SỐ CHO TRƯỚC'!$E$30 * (B35/$E$28) + 'THÔNG SỐ CHO TRƯỚC'!$E$31 * (B35/$E$28)^2 - 'THÔNG SỐ CHO TRƯỚC'!$E$32 * (B35/$E$28)^3) -> 28.438889 | E35: =(10000 * C35) / (1.047 * B35) -> 339.52828
B36: 1200 | C36: =$E$27 * ('THÔNG SỐ CHO TRƯỚC'!$E$30 * (B36/$E$28) + 'THÔNG SỐ CHO TRƯỚC'!$E$31 * (B36/$E$28)^2 - 'THÔNG SỐ CHO TRƯỚC'!$E$32 * (B36/$E$28)^3) -> 48.346513 | E36: =(10000 * C36) / (1.047 * B36) -> 384.80192
B37: 1600 | C37: =$E$27 * ('THÔNG SỐ CHO TRƯỚC'!$E$30 * (B37/$E$28) + 'THÔNG SỐ CHO TRƯỚC'!$E$31 * (B37/$E$28)^2 - 'THÔNG SỐ CHO TRƯỚC'!$E$32 * (B37/$E$28)^3) -> 69.445945 | E37: =(10000 * C37) / (1.047 * B37) -> 414.55316
B38: 2000 | C38: =$E$27 * ('THÔNG SỐ CHO TRƯỚC'!$E$30 * (B38/$E$28) + 'THÔNG SỐ CHO TRƯỚC'!$E$31 * (B38/$E$28)^2 - 'THÔNG SỐ CHO TRƯỚC'!$E$32 * (B38/$E$28)^3) -> 89.786954 | E38: =(10000 * C38) / (1.047 * B38) -> 428.78202
B39: 2166.6667 | C39: =$E$27 * ('THÔNG SỐ CHO TRƯỚC'!$E$30 * (B39/$E$28) + 'THÔNG SỐ CHO TRƯỚC'!$E$31 * (B39/$E$28)^2 - 'THÔNG SỐ CHO TRƯỚC'!$E$32 * (B39/$E$28)^3) -> 97.574864 | E39: =(10000 * C39) / (1.047 * B39) -> 430.12944
B40: 2400 | C40: =$E$27 * ('THÔNG SỐ CHO TRƯỚC'!$E$30 * (B40/$E$28) + 'THÔNG SỐ CHO TRƯỚC'!$E$31 * (B40/$E$28)^2 - 'THÔNG SỐ CHO TRƯỚC'!$E$32 * (B40/$E$28)^3) -> 107.41931 | E40: =(10000 * C40) / (1.047 * B40) -> 427.48848
B41: 2600 | C41: =$E$27 * ('THÔNG SỐ CHO TRƯỚC'!$E$30 * (B41/$E$28) + 'THÔNG SỐ CHO TRƯỚC'!$E$31 * (B41/$E$28)^2 - 'THÔNG SỐ CHO TRƯỚC'!$E$32 * (B41/$E$28)^3) -> 114.61029 | E41: =(10000 * C41) / (1.047 * B41) -> 421.02082
B42: =0.95*2600 -> 2470 | C42: =$E$27 * ('THÔNG SỐ CHO TRƯỚC'!$E$30 * (B42/$E$28) + 'THÔNG SỐ CHO TRƯỚC'!$E$31 * (B42/$E$28)^2 - 'THÔNG SỐ CHO TRƯỚC'!$E$32 * (B42/$E$28)^3) -> 110.08112 | E42: =(10000 * C42) / (1.047 * B42) -> 425.66622
B44: STT | C44: Tên thông số / Đại lượng | D44: Ký hiệu | E44: Giá trị | F44: Đơn vị | G44: Công thức / Nguồn (Trang cắt ảnh)
B45: 17 | C45: Tỷ số truyền của hộp số ở số truyền cao nhất | E45: 1 | F45: - | G45: Chọn theo sách
B46: 18 | C46: Tỷ số truyền của hộp số phụ hay hộp phân phối ở số cau | E46: =1.25 -> 1.25 | F46: - | G46: chọn theo sách
B47: 19 | C47: Vận tốc cực đại | D47: vmax | E47: =95/3.6 -> 26.388889 | F47: m/s | G47: Đề bài cho
B48: 20 | C48: Tỷ số truyền của truyền lực chính | E48: =(2*PI()*E15*'THÔNG SỐ CHO TRƯỚC'!E29)/(60*'TÍNH TOÁN '!E45*'TÍNH TOÁN '!E46*'TÍNH TOÁN '!E47) -> 3.2365441 | F48: - | G48: Tra cứu công thức
B49: 21 | C49: Số cấp | D49: n | E49: 5 | F49: - | G49: tra theo sách
...

Sheet HD_THAM_KHAO
A1: CÁCH ĐỌC BẢN EXCEL ĐÃ CHỈNH
A4: Bản tham khảo này làm gì
A5: Giữ hai sheet nguồn và ảnh công thức. Sửa hoành độ điểm cuối số V ở ba đồ thị D, 1/j và thời gian từ 95 về đúng 90,25 km/h. Giữ bảng tích phân thưa làm đối chiếu; bổ sung lưới mịn và hành trình tăng tốc liên tục qua năm tay số.
A9: Giữ bộ thông số mới của bạn
A10: f0=0,015; η=0,85; ihI=6,5; ihV=1 (truyền thẳng); ip=1,25; δk=1,05+0,05ihk². Giữ phép đổi mômen Me=10000Ne/(1,047n) để đối chiếu đúng file nguồn. Không áp dụng kết quả 104,015 s của phương án cũ.
A14: Giả thiết bổ sung cho hành trình
A15: Chọn chuyển I→II→III→IV→V tại 2.600 vòng/phút theo miền bảng nguồn; ngắt lực kéo 1 s/lần; δcoast=1,05. Đây là lịch tham khảo, chưa tối ưu. Bắt đầu số I ở 800 vòng/phút; kết thúc tại 0,95vmax=90,25 km/h; chưa gồm khởi hành bằng ly hợp trượt.
A19: Phân biệt hai loại thời gian
A20: Bảng C189:G194 nguồn đặt t=0 riêng cho từng số. Nó là thời gian riêng τk(v), không phải toàn bộ quá trình. Khi nối số phải dùng t(v)=t_vào_số+τk(v)−τk(v_vào_số), cộng cả thời gian ngắt lực kéo và vào số mới tại vận tốc đã giảm.
A24: Công thức hình thang của bạn đúng
A25: Δt=(1/jA+1/jB)(vB−vA)/2; tB=tA+Δt. ΔS=(vA/jA+vB/jB)(vB−vA)/2; SB=SA+ΔS. Tất cả vận tốc trong phép tính là m/s. Việc dùng các khoảng quá rộng, nhất là đi xuyên ngưỡng đổi f, mới làm sai số lớn.
A29: Tại sao có hai dòng ở 22,2 m/s
... A65: Mở bằng Excel hoặc phần mềm tương thích .xlsx. File có giá trị lưu sẵn cho từng công thức để đọc ngay; các phần mềm khác nhau có thể hiển thị ảnh trong ô của nguồn khác nhau. Bản gốc được giữ riêng và không ghi đè.
B69: THAM_SO_MOI
B70: TICH_PHAN_SO_V
B71: HANH_TRINH
B72: TONG_HOP
B73: DO_THI_MOI

Sheet THAM_SO_MOI
A1: THÔNG SỐ LIÊN KẾT VÀ GIẢ THIẾT BỔ SUNG
A2: Các ô công thức liên kết dữ liệu nguồn. Chỉnh đầu vào xe ở hai sheet gốc; chỉnh lịch chuyển số tại các ô màu xanh tại đây. Kiểm tra trạng thái lưới tại TONG_HOP sau mỗi lần đổi.
A5: Mã | B5: Đại lượng | C5: Giá trị | D5: Đơn vị | E5: Cơ sở / cách dùng
A6: m0 | B6: Khối lượng bản thân | C6: ='THÔNG SỐ CHO TRƯỚC'!E9 -> 3450 | D6: kg | E6: Theo Excel nguồn
A7: payload | B7: Khối lượng hàng | C7: ='THÔNG SỐ CHO TRƯỚC'!E10 -> 4100 | D7: kg | E7: Theo Excel nguồn
A8: persons | B8: Số người | C8: ='THÔNG SỐ CHO TRƯỚC'!E8 -> 2 | D8: người | E8: Theo Excel nguồn
A9: person_mass | B9: Khối lượng mỗi người | C9: ='THÔNG SỐ CHO TRƯỚC'!E21 -> 65 | D9: kg | E9: Theo Excel nguồn
A10: gravity | B10: Gia tốc trọng trường | C10: 9.81 | D10: m/s² | E10: Hằng số dùng trong nguồn
A11: mass | B11: Khối lượng toàn tải | C11: ='THAM_SO_MOI'!$C$6+'THAM_SO_MOI'!$C$7+'THAM_SO_MOI'!$C$8*'THAM_SO_MOI'!$C$9 -> 7680 | D11: kg | E11: Bản thân + hàng + người
A12: weight | B12: Trọng lượng toàn tải | C12: ='THAM_SO_MOI'!$C$11*'THAM_SO_MOI'!$C$10 -> 75340.8 | D12: N | E12: M g
A13: f0 | B13: Hệ số cản lăn cơ sở | C13: ='THÔNG SỐ CHO TRƯỚC'!E23 -> 0.015 | D13: — | E13: Giữ 0,015 của file mới
A14: threshold | B14: Ngưỡng đổi nhánh cản lăn | C14: 22.2 | D14: m/s | E14: Giữ quy luật IF của nguồn; tách tích phân
A15: K | B15: Hệ số cản không khí | C15: ='THÔNG SỐ CHO TRƯỚC'!E25 -> 0.65 | D15: N·s²/m⁴ | E15: Theo Excel nguồn
A16: F | B16: Diện tích cản chính diện | C16: ='THÔNG SỐ CHO TRƯỚC'!E26 -> 4.5 | D16: m² | E16: Theo Excel nguồn
A17: eta | B17: Hiệu suất truyền lực | C17: ='THÔNG SỐ CHO TRƯỚC'!E27 -> 0.85 | D17: — | E17: Theo Excel nguồn
A18: vmax_kmh | B18: Vận tốc cực đại danh nghĩa | C18: ='THÔNG SỐ CHO TRƯỚC'!E13 -> 95 | D18: km/h | E18: Theo đề
A19: vmax | B19: Vận tốc cực đại danh nghĩa SI | C19: ='THAM_SO_MOI'!$C$18/3.6 -> 26.388889 | D19: m/s | E19: vmax(km/h)/3,6
A20: lambda_v | B20: Tỷ số nv/nN | C20: ='THÔNG SỐ CHO TRƯỚC'!E28 -> 0.9 | D20: — | E20: Theo nguồn
A21: nv | B21: Vòng tua tại vmax danh nghĩa | C21: ='THÔNG SỐ CHO TRƯỚC'!E29 -> 2600 | D21: v/ph | E21: 2.600 vòng/phút
A22: nN | B22: Vòng tua chuẩn đặc tính | C22: ='THAM_SO_MOI'!$C$21/'THAM_SO_MOI'!$C$20 -> 2888.8889 | D22: v/ph | E22: nv/λ; không gọi nv là nN
A23: a | B23: Hệ số đa thức a | C23: ='THÔNG SỐ CHO TRƯỚC'!E30 -> 0.5 | D23: — | E23: Theo nguồn
A24: b | B24: Hệ số đa thức b | C24: ='THÔNG SỐ CHO TRƯỚC'!E31 -> 1.5 | D24: — | E24: Theo nguồn
A25: c | B25: Hệ số đa thức c | C25: ='THÔNG SỐ CHO TRƯỚC'!E32 -> 1 | D25: — | E25: Theo nguồn
A26: rb | B26: Bán kính lăn | C26: ='TÍNH TOÁN '!E15 -> 0.3921125 | D26: m | E26: Theo nguồn
A27: ip | B27: Tỷ số hộp số phụ | C27: ='TÍNH TOÁN '!E46 -> 1.25 | D27: — | E27: Theo nguồn
A28: ih1 | B28: Tỷ số số I | C28: ='TÍNH TOÁN '!E57 -> 6.5 | D28: — | E28: Giữ 6,5
A29: top | B29: Tỷ số số V | C29: ='TÍNH TOÁN '!E61 -> 1 | D29: — | E29: Giữ truyền thẳng 1
A30: i0 | B30: Tỷ số truyền lực chính | C30: ='TÍNH TOÁN '!E48 -> 3.2365441 | D30: — | E30: Theo nguồn
A31: coef | B31: Hệ số đổi Ne(kW)/n sang Me | C31: =10000/1.047 -> 9551.0984 | D31: — | E31: Giữ xấp xỉ của nguồn; cao hơn hệ số chính xác 0,0188683%
A32: nmin | B32: Vòng tua bắt đầu pha số I | C32: 800 | D32: v/ph | E32: Giả thiết tham khảo; chưa gồm khởi hành ly hợp trượt
A33: nshift | B33: Vòng tua chuyển I→II→III→IV→V | C33: 2600 | D33: v/ph | E33: Chọn 2.600 theo giới hạn bảng nguồn; chưa tối ưu
A34: shift_seconds | B34: Thời gian ngắt lực kéo mỗi lần | C34: 1 | D34: s | E34: Giả thiết bổ sung: 1 giây/lần
A35: delta_coast | B35: Hệ số quán tính lúc ngắt lực kéo | C35: 1.05 | D35: — | E35: Giả thiết bổ sung: 1,05
A36: target_factor | B36: Tỷ lệ vận tốc kết thúc / vmax | C36: 0.95 | D36: — | E36: Giữ 0,95 của nguồn
A37: target | B37: Vận tốc kết thúc SI | C37: ='THAM_SO_MOI'!$C$36*'THAM_SO_MOI'!$C$19 -> 25.069444 | D37: m/s | E37: 0,95 vmax
A38: fvmax | B38: f tại vmax danh nghĩa | C38: =IF('THAM_SO_MOI'!$C$19<='THAM_SO_MOI'!$C$14,'THAM_SO_MOI'!$C$13,'THAM_SO_MOI'!$C$13*(1+'THAM_SO_MOI'!$C$19^2/1500)) -> 0.021963735 | D38: — | E38: Theo quy luật IF của nguồn
A39: Nv | B39: Công suất cần tại vmax | C39: =('THAM_SO_MOI'!$C$12*'THAM_SO_MOI'!$C$38+'THAM_SO_MOI'!$C$15*'THAM_SO_MOI'!$C$16*'THAM_SO_MOI'!$C$19^2)*'THAM_SO_MOI'!$C$19/(1000*'THAM_SO_MOI'!$C$17) -> 114.61029 | D39: kW | E39: (Gf+KFv²)v/(1000η)
A40: Nmax | B40: Tham số công suất chuẩn | C40: ='THAM_SO_MOI'!$C$39/('THAM_SO_MOI'!$C$23*'THAM_SO_MOI'!$C$20+'THAM_SO_MOI'!$C$24*'THAM_SO_MOI'!$C$20^2-'THAM_SO_MOI'!$C$25*'THAM_SO_MOI'!$C$20^3) -> 122.44689 | D40: kW | E40: Theo đa thức nguồn; chỉ dùng miền n≤nN
A41: Pphi | B41: Giới hạn bám tĩnh | C41: ='TÍNH TOÁN '!F113 -> 39553.92 | D41: N | E41: Giữ m=1, cầu sau chủ động
A42: N | B42: Số khoảng mỗi miền trơn | C42: 800 | D42: khoảng | E42: Cấu trúc lưới: 800. Không đổi ô này riêng; cần tạo lại lưới.
...

Sheet TICH_PHAN_SO_V
A1: TÍCH PHÂN RIÊNG SỐ V — TÁCH NGƯỠNG CẢN LĂN
A2: Đây là phép kiểm tra riêng số V từ 800 vòng/phút đến 0,95 vmax, chưa phải quá trình tăng tốc toàn xe. Hai dòng cùng v=22,2 có 1/j khác nhau nhưng Δt=ΔS=0 ở dòng bắt đầu nhánh trên.
A5: Pha | B5: Số | C5: Loại | D5: Nhánh f | E5: n (v/ph) | F5: v (m/s) | G5: v (km/h) | H5: δ | I5: f(v) | J5: Ne (kW) | K5: Me (N·m) | L5: Pk (N) | M5: Pw (N) | N5: Pf (N) | O5: Pc (N) | P5: j (m/s²) | Q5: 1/j (s²/m) | R5: Δv (m/s) | S5: Δt (s) | T5: ΔS (m) | U5: t tích lũy (s) | V5: S tích lũy (m) | W5: k1 (m/s²) | X5: v2 RK4 | Y5: k2 (m/s²) | Z5: v3 RK4 | AA5: k3 (m/s²) | AB5: v4 RK4 | AC5: k4 (m/s²)
A6: Số V riêng | B6: 5 | C6: kéo | D6: low | E6: =60*F6*'THAM_SO_MOI'!$C$53/(2*PI()*'THAM_SO_MOI'!$C$26) -> 800 | F6: ='THAM_SO_MOI'!$E$53+('THAM_SO_MOI'!$C$14-'THAM_SO_MOI'!$E$53)*0/'THAM_SO_MOI'!$C$42 -> 8.1196581 | G6: =3.6*F6 -> 29.230769 | H6: ='THAM_SO_MOI'!$D$53 -> 1.1 | I6: =IF(F6>'THAM_SO_MOI'!$C$14,'THAM_SO_MOI'!$C$13*(1+F6^2/1500),'THAM_SO_MOI'!$C$13) -> 0.015 | J6: ='THAM_SO_MOI'!$C$40*('THAM_SO_MOI'!$C$23*(E6/'THAM_SO_MOI'!$C$22)+'THAM_SO_MOI'!$C$24*(E6/'THAM_SO_MOI'!$C$22)^2-'THAM_SO_MOI'!$C$25*(E6/'THAM_SO_MOI'!$C$22)^3) -> 28.438889 | K6: ='THAM_SO_MOI'!$C$31*J6/E6 -> 339.52828 | L6: =K6*'THAM_SO_MOI'!$C$53*'THAM_SO_MOI'!$C$17/'THAM_SO_MOI'!$C$26 -> 2977.6644 | M6: ='THAM_SO_MOI'!$C$15*'THAM_SO_MOI'!$C$16*F6^2 -> 192.84188 | N6: ='THAM_SO_MOI'!$C$12*I6 -> 1130.112 | O6: =M6+N6 -> 1322.9539 | P6: =(MIN(L6,'THAM_SO_MOI'!$C$41)-O6)/('THAM_SO_MOI'!$C$11*H6) -> 0.19587009 | Q6: =IF(P6>0,1/P6,NA()) -> 5.1054248 | R6: =0 -> 0 | S6: =0 -> 0 | T6: =0 -> 0 | U6: =S6 -> 0 | V6: =T6 -> 0
A7: Số V riêng | B7: 5 | C7: kéo | D7: low | E7: =60*F7*'THAM_SO_MOI'!$C$53/(2*PI()*'THAM_SO_MOI'!$C$26) -> 801.73411 | F7: ='THAM_SO_MOI'!$E$53+('THAM_SO_MOI'!$C$14-'THAM_SO_MOI'!$E$53)*1/'THAM_SO_MOI'!$C$42 -> 8.1372585 | G7: =3.6*F7 -> 29.294131 | H7: ='THAM_SO_MOI'!$D$53 -> 1.1 | I7: =IF(F7>'THAM_SO_MOI'!$C$14,'THAM_SO_MOI'!$C$13*(1+F7^2/1500),'THAM_SO_MOI'!$C$13) -> 0.015 | J7: ='THAM_SO_MOI'!$C$40*('THAM_SO_MOI'!$C$23*(E7/'THAM_SO_MOI'!$C$22)+'THAM_SO_MOI'!$C$24*(E7/'THAM_SO_MOI'!$C$22)^2-'THAM_SO_MOI'!$C$25*(E7/'THAM_SO_MOI'!$C$22)^3) -> 28.519822 | K7: ='THAM_SO_MOI'!$C$31*J7/E7 -> 339.75806 | L7: =K7*'THAM_SO_MOI'!$C$53*'THAM_SO_MOI'!$C$17/'THAM_SO_MOI'!$C$26 -> 2979.6795 | M7: ='THAM_SO_MOI'!$C$15*'THAM_SO_MOI'!$C$16*F7^2 -> 193.67881 | N7: ='THAM_SO_MOI'!$C$12*I7 -> 1130.112 | O7: =M7+N7 -> 1323.7908 | P7: =(MIN(L7,'THAM_SO_MOI'!$C$41)-O7)/('THAM_SO_MOI'!$C$11*H7) -> 0.19600955 | Q7: =IF(P7>0,1/P7,NA()) -> 5.1017922 | R7: =F7-F6 -> 0.017600427 | S7: =0.5*(Q6+Q7)*R7 -> 0.089825691 | T7: =0.5*(F6*Q6+F7*Q7)*R7 -> 0.7301441 | U7: =U6+S7 -> 0.089825691 | V7: =V6+T7 -> 0.7301441
A8: Số V riêng | B8: 5 | C8: kéo | D8: low | E8: =60*F8*'THAM_SO_MOI'!$C$53/(2*PI()*'THAM_SO_MOI'!$C$26) -> 803.46821 | F8: ='THAM_SO_MOI'!$E$53+('THAM_SO_MOI'!$C$14-'THAM_SO_MOI'!$E$53)*2/'THAM_SO_MOI'!$C$42 -> 8.154859 | G8: =3.6*F8 -> 29.357492 | H8: ='THAM_SO_MOI'!$D$53 -> 1.1 | I8: =IF(F8>'THAM_SO_MOI'!$C$14,'THAM_SO_MOI'!$C$13*(1+F8^2/1500),'THAM_SO_MOI'!$C$13) -> 0.015 | J8: ='THAM_SO_MOI'!$C$40*('THAM_SO_MOI'!$C$23*(E8/'THAM_SO_MOI'!$C$22)+'THAM_SO_MOI'!$C$24*(E8/'THAM_SO_MOI'!$C$22)^2-'THAM_SO_MOI'!$C$25*(E8/'THAM_SO_MOI'!$C$22)^3) -> 28.600813 | K8: ='THAM_SO_MOI'!$C$31*J8/E8 -> 339.98754 | L8: =K8*'THAM_SO_MOI'!$C$53*'THAM_SO_MOI'!$C$17/'THAM_SO_MOI'!$C$26 -> 2981.6921 | M8: ='THAM_SO_MOI'!$C$15*'THAM_SO_MOI'!$C$16*F8^2 -> 194.51755 | N8: ='THAM_SO_MOI'!$C$12*I8 -> 1130.112 | O8: =M8+N8 -> 1324.6295 | P8: =(MIN(L8,'THAM_SO_MOI'!$C$41)-O8)/('THAM_SO_MOI'!$C$11*H8) -> 0.1961485 | Q8: =IF(P8>0,1/P8,NA()) -> 5.0981782 | R8: =F8-F7 -> 0.017600427 | S8: =0.5*(Q7+Q8)*R8 -> 0.089761919 | T8: =0.5*(F7*Q7+F8*Q8)*R8 -> 0.73120559 | U8: =U7+S8 -> 0.17958761 | V8: =V7+T8 -> 1.4613497
A9: Số V riêng | B9: 5 | C9: kéo | D9: low | E9: =60*F9*'THAM_SO_MOI'!$C$53/(2*PI()*'THAM_SO_MOI'!$C$26) -> 805.20232 | F9: ='THAM_SO_MOI'!$E$53+('THAM_SO_MOI'!$C$14-'THAM_SO_MOI'!$E$53)*3/'THAM_SO_MOI'!$C$42 -> 8.1724594 | G9: =3.6*F9 -> 29.420854 | H9: ='THAM_SO_MOI'!$D$53 -> 1.1 | I9: =IF(F9>'THAM_SO_MOI'!$C$14,'THAM_SO_MOI'!$C$13*(1+F9^2/1500),'THAM_SO_MOI'!$C$13) -> 0.015 | J9: ='THAM_SO_MOI'!$C$40*('THAM_SO_MOI'!$C$23*(E9/'THAM_SO_MOI'!$C$22)+'THAM_SO_MOI'!$C$24*(E9/'THAM_SO_MOI'!$C$22)^2-'THAM_SO_MOI'!$C$25*(E9/'THAM_SO_MOI'!$C$22)^3) -> 28.681863 | K9: ='THAM_SO_MOI'!$C$31*J9/E9 -> 340.21673 | L9: =K9*'THAM_SO_MOI'!$C$53*'THAM_SO_MOI'!$C$17/'THAM_SO_MOI'!$C$26 -> 2983.7021 | M9: ='THAM_SO_MOI'!$C$15*'THAM_SO_MOI'!$C$16*F9^2 -> 195.3581 | N9: ='THAM_SO_MOI'!$C$12*I9 -> 1130.112 | O9: =M9+N9 -> 1325.4701 | P9: =(MIN(L9,'THAM_SO_MOI'!$C$41)-O9)/('THAM_SO_MOI'!$C$11*H9) -> 0.19628693 | Q9: =IF(P9>0,1/P9,NA()) -> 5.0945828 | R9: =F9-F8 -> 0.017600427 | S9: =0.5*(Q8+Q9)*R9 -> 0.089698475 | T9: =0.5*(F8*Q8+F9*Q9)*R9 -> 0.7322675 | U9: =U8+S9 -> 0.26928608 | V9: =V8+T9 -> 2.1936172
A10: Số V riêng | B10: 5 | C10: kéo | D10: low | E10: =60*F10*'THAM_SO_MOI'!$C$53/(2*PI()*'THAM_SO_MOI'!$C$26) -> 806.93642 | F10: ='THAM_SO_MOI'!$E$53+('THAM_SO_MOI'!$C$14-'THAM_SO_MOI'!$E$53)*4/'THAM_SO_MOI'!$C$42 -> 8.1900598 | G10: =3.6*F10 -> 29.484215 | H10: ='THAM_SO_MOI'!$D$53 -> 1.1 | I10: =IF(F10>'THAM_SO_MOI'!$C$14,'THAM_SO_MOI'!$C$13*(1+F10^2/1500),'THAM_SO_MOI'!$C$13) -> 0.015 | J10: ='THAM_SO_MOI'!$C$40*('THAM_SO_MOI'!$C$23*(E10/'THAM_SO_MOI'!$C$22)+'THAM_SO_MOI'!$C$24*(E10/'THAM_SO_MOI'!$C$22)^2-'THAM_SO_MOI'!$C$25*(E10/'THAM_SO_MOI'!$C$22)^3) -> 28.762972 | K10: ='THAM_SO_MOI'!$C$31*J10/E10 -> 340.44563 | L10: =K10*'THAM_SO_MOI'!$C$53*'THAM_SO_MOI'!$C$17/'THAM_SO_MOI'!$C$26 -> 2985.7095 | M10: ='THAM_SO_MOI'!$C$15*'THAM_SO_MOI'!$C$16*F10^2 -> 196.20046 | N10: ='THAM_SO_MOI'!$C$12*I10 -> 1130.112 | O10: =M10+N10 -> 1326.3125 | P10: =(MIN(L10,'THAM_SO_MOI'!$C$41)-O10)/('THAM_SO_MOI'!$C$11*H10) -> 0.19642484 | Q10: =IF(P10>0,1/P10,NA()) -> 5.0910058 | R10: =F10-F9 -> 0.017600427 | S10: =0.5*(Q9+Q10)*R10 -> 0.089635356 | T10: =0.5*(F9*Q9+F10*Q10)*R10 -> 0.73332984 | U10: =U9+S10 -> 0.35892144 | V10: =V9+T10 -> 2.926947
A11: Số V riêng | B11: 5 | C11: kéo | D11: low | E11: =60*F11*'THAM_SO_MOI'!$C$53/(2*PI()*'THAM_SO_MOI'!$C$26) -> 808.67053 | F11: ='THAM_SO_MOI'!$E$53+('THAM_SO_MOI'!$C$14-'THAM_SO_MOI'!$E$53)*5/'THAM_SO_MOI'!$C$42 -> 8.2076603 | G11: =3.6*F11 -> 29.547577 | H11: ='THAM_SO_MOI'!$D$53 -> 1.1 | I11: =IF(F11>'THAM_SO_MOI'!$C$14,'THAM_SO_MOI'!$C$13*(1+F11^2/1500),'THAM_SO_MOI'!$C$13) -> 0.015 | J11: ='THAM_SO_MOI'!$C$40*('THAM_SO_MOI'!$C$23*(E11/'THAM_SO_MOI'!$C$22)+'THAM_SO_MOI'!$C$24*(E11/'THAM_SO_MOI'!$C$22)^2-'THAM_SO_MOI'!$C$25*(E11/'THAM_SO_MOI'!$C$22)^3) -> 28.84414 | K11: ='THAM_SO_MOI'!$C$31*J11/E11 -> 340.67424 | L11: =K11*'THAM_SO_MOI'!$C$53*'THAM_SO_MOI'!$C$17/'THAM_SO_MOI'!$C$26 -> 2987.7144 | M11: ='THAM_SO_MOI'!$C$15*'THAM_SO_MOI'!$C$16*F11^2 -> 197.04463 | N11: ='THAM_SO_MOI'!$C$12*I11 -> 1130.112 | O11: =M11+N11 -> 1327.1566 | P11: =(MIN(L11,'THAM_SO_MOI'!$C$41)-O11)/('THAM_SO_MOI'!$C$11*H11) -> 0.19656223 | Q11: =IF(P11>0,1/P11,NA()) -> 5.0874473 | R11: =F11-F10 -> 0.017600427 | S11: =0.5*(Q10+Q11)*R11 -> 0.089572562 | T11: =0.5*(F10*Q10+F11*Q11)*R11 -> 0.73439262 | U11: =U10+S11 -> 0.448494 | V11: =V10+T11 -> 3.6613397
A12: Số V riêng | B12: 5 | C12: kéo | D12: low | E12: =60*F12*'THAM_SO_MOI'!$C$53/(2*PI()*'THAM_SO_MOI'!$C$26) -> 810.40463 | F12: ='THAM_SO_MOI'!$E$53+('THAM_SO_MOI'!$C$14-'THAM_SO_MOI'!$E$53)*6/'THAM_SO_MOI'!$C$42 -> 8.2252607 | G12: =3.6*F12 -> 29.610938 | H12: ='THAM_SO_MOI'!$D$53 -> 1.1 | I12: =IF(F12>'THAM_SO_MOI'!$C$14,'THAM_SO_MOI'!$C$13*(1+F12^2/1500),'THAM_SO_MOI'!$C$13) -> 0.015 | J12: ='THAM_SO_MOI'!$C$40*('THAM_SO_MOI'!$C$23*(E12/'THAM_SO_MOI'!$C$22)+'THAM_SO_MOI'!$C$24*(E12/'THAM_SO_MOI'!$C$22)^2-'THAM_SO_MOI'!$C$25*(E12/'THAM_SO_MOI'!$C$22)^3) -> 28.925365 | K12: ='THAM_SO_MOI'!$C$31*J12/E12 -> 340.90255 | L12: =K12*'THAM_SO_MOI'!$C$53*'THAM_SO_MOI'!$C$17/'THAM_SO_MOI'!$C$26 -> 2989.7167 | M12: ='THAM_SO_MOI'!$C$15*'THAM_SO_MOI'!$C$16*F12^2 -> 197.89062 | N12: ='THAM_SO_MOI'!$C$12*I12 -> 1130.112 | O12: =M12+N12 -> 1328.0026 | P12: =(MIN(L12,'THAM_SO_MOI'!$C$41)-O12)/('THAM_SO_MOI'!$C$11*H12) -> 0.19669911 | Q12: =IF(P12>0,1/P12,NA()) -> 5.083907 | R12: =F12-F11 -> 0.017600427 | S12: =0.5*(Q11+Q12)*R12 -> 0.089510091 | T12: =0.5*(F11*Q11+F12*Q12)*R12 -> 0.73545585 | U12: =U11+S12 -> 0.53800409 | V12: =V11+T12 -> 4.3967955
A13: Số V riêng | B13: 5 | C13: kéo | D13: low | E13: =60*F13*'THAM_SO_MOI'!$C$53/(2*PI()*'THAM_SO_MOI'!$C$26) -> 812.13874 | F13: ='THAM_SO_MOI'!$E$53+('THAM_SO_MOI'!$C$14-'THAM_SO_MOI'!$E$53)*7/'THAM_SO_MOI'!$C$42 -> 8.2428611 | G13: =3.6*F13 -> 29.6743 | H13: ='THAM_SO_MOI'!$D$53 -> 1.1 | I13: =IF(F13>'THAM_SO_MOI'!$C$14,'THAM_SO_MOI'!$C$13*(1+F13^2/1500),'THAM_SO_MOI'!$C$13) -> 0.015 | J13: ='THAM_SO_MOI'!$C$40*('THAM_SO_MOI'!$C$23*(E13/'THAM_SO_MOI'!$C$22)+'THAM_SO_MOI'!$C$24*(E13/'THAM_SO_MOI'!$C$22)^2-'THAM_SO_MOI'!$C$25*(E13/'THAM_SO_MOI'!$C$22)^3) -> 29.006649 | K13: ='THAM_SO_MOI'!$C$31*J13/E13 -> 341.13058 | L13: =K13*'THAM_SO_MOI'!$C$53*'THAM_SO_MOI'!$C$17/'THAM_SO_MOI'!$C$26 -> 2991.7165 | M13: ='THAM_SO_MOI'!$C$15*'THAM_SO_MOI'!$C$16*F13^2 -> 198.73842 | N13: ='THAM_SO_MOI'!$C$12*I13 -> 1130.112 | O13: =M13+N13 -> 1328.8504 | P13: =(MIN(L13,'THAM_SO_MOI'!$C$41)-O13)/('THAM_SO_MOI'!$C$11*H13) -> 0.19683547 | Q13: =IF(P13>0,1/P13,NA()) -> 5.0803851 | R13: =F13-F12 -> 0.017600427 | S13: =0.5*(Q12+Q13)*R13 -> 0.089447943 | T13: =0.5*(F12*Q12+F13*Q13)*R13 -> 0.73651954 | U13: =U12+S13 -> 0.62745204 | V13: =V12+T13 -> 5.133315
A14: Số V riêng | B14: 5 | C14: kéo | D14: low | E14: =60*F14*'THAM_SO_MOI'!$C$53/(2*PI()*'THAM_SO_MOI'!$C$26) -> 813.87284 | F14: ='THAM_SO_MOI'!$E$53+('THAM_SO_MOI'!$C$14-'THAM_SO_MOI'!$E$53)*8/'THAM_SO_MOI'!$C$42 -> 8.2604615 | G14: =3.6*F14 -> 29.737662 | H14: ='THAM_SO_MOI'!$D$53 -> 1.1 | I14: =IF(F14>'THAM_SO_MOI'!$C$14,'THAM_SO_MOI'!$C$13*(1+F14^2/1500),'THAM_SO_MOI'!$C$13) -> 0.015 | J14: ='THAM_SO_MOI'!$C$40*('THAM_SO_MOI'!$C$23*(E14/'THAM_SO_MOI'!$C$22)+'THAM_SO_MOI'!$C$24*(E14/'THAM_SO_MOI'!$C$22)^2-'THAM_SO_MOI'!$C$25*(E14/'THAM_SO_MOI'!$C$22)^3) -> 29.08799 | K14: ='THAM_SO_MOI'!$C$31*J14/E14 -> 341.35831 | L14: =K14*'THAM_SO_MOI'!$C$53*'THAM_SO_MOI'!$C$17/'THAM_SO_MOI'!$C$26 -> 2993.7137 | M14: ='THAM_SO_MOI'!$C$15*'THAM_SO_MOI'!$C$16*F14^2 -> 199.58803 | N14: ='THAM_SO_MOI'!$C$12*I14 -> 1130.112 | O14: =M14+N14 -> 1329.7 | P14: =(MIN(L14,'THAM_SO_MOI'!$C$41)-O14)/('THAM_SO_MOI'!$C$11*H14) -> 0.19697131 | Q14: =IF(P14>0,1/P14,NA()) -> 5.0768814 | R14: =F14-F13 -> 0.017600427 | S14: =0.5*(Q13+Q14)*R14 -> 0.089386116 | T14: =0.5*(F13*Q13+F14*Q14)*R14 -> 0.73758368 | U14: =U13+S14 -> 0.71683815 | V14: =V13+T14 -> 5.8708987
A15: Số V riêng | B15: 5 | C15: kéo | D15: low | E15: =60*F15*'THAM_SO_MOI'!$C$53/(2*PI()*'THAM_SO_MOI'!$C$26) -> 815.60695 | F15: ='THAM_SO_MOI'!$E$53+('THAM_SO_MOI'!$C$14-'THAM_SO_MOI'!$E$53)*9/'THAM_SO_MOI'!$C$42 -> 8.278062 | G15: =3.6*F15 -> 29.801023 | H15: ='THAM_SO_MOI'!$D$53 -> 1.1 | I15: =IF(F15>'THAM_SO_MOI'!$C$14,'THAM_SO_MOI'!$C$13*(1+F15^2/1500),'THAM_SO_MOI'!$C$13) -> 0.015 | J15: ='THAM_SO_MOI'!$C$40*('THAM_SO_MOI'!$C$23*(E15/'THAM_SO_MOI'!$C$22)+'THAM_SO_MOI'!$C$24*(E15/'THAM_SO_MOI'!$C$22)^2-'THAM_SO_MOI'!$C$25*(E15/'THAM_SO_MOI'!$C$22)^3) -> 29.16939 | K15: ='THAM_SO_MOI'!$C$31*J15/E15 -> 341.58575 | L15: =K15*'THAM_SO_MOI'!$C$53*'THAM_SO_MOI'!$C$17/'THAM_SO_MOI'!$C$26 -> 2995.7083 | M15: ='THAM_SO_MOI'!$C$15*'THAM_SO_MOI'!$C$16*F15^2 -> 200.43946 | N15: ='THAM_SO_MOI'!$C$12*I15 -> 1130.112 | O15: =M15+N15 -> 1330.5515 | P15: =(MIN(L15,'THAM_SO_MOI'!$C$41)-O15)/('THAM_SO_MOI'!$C$11*H15) -> 0.19710664 | Q15: =IF(P15>0,1/P15,NA()) -> 5.0733958 | R15: =F15-F14 -> 0.017600427 | S15: =0.5*(Q14+Q15)*R15 -> 0.089324608 | T15: =0.5*(F14*Q14+F15*Q15)*R15 -> 0.7386483 | U15: =U14+S15 -> 0.80616276 | V15: =V14+T15 -> 6.609547
A16: Số V riêng | B16: 5 | C16: kéo | D16: low | E16: =60*F16*'THAM_SO_MOI'!$C$53/(2*PI()*'THAM_SO_MOI'!$C$26) -> 817.34105 | F16: ='THAM_SO_MOI'!$E$53+('THAM_SO_MOI'!$C$14-'THAM_SO_MOI'!$E$53)*10/'THAM_SO_MOI'!$C$42 -> 8.2956624 | G16: =3.6*F16 -> 29.864385 | H16: ='THAM_SO_MOI'!$D$53 -> 1.1 | I16: =IF(F16>'THAM_SO_MOI'!$C$14,'THAM_SO_MOI'!$C$13*(1+F16^2/1500),'THAM_SO_MOI'!$C$13) -> 0.015 | J16: ='THAM_SO_MOI'!$C$40*('THAM_SO_MOI'!$C$23*(E16/'THAM_SO_MOI'!$C$22)+'THAM_SO_MOI'!$C$24*(E16/'THAM_SO_MOI'!$C$22)^2-'THAM_SO_MOI'!$C$25*(E16/'THAM_SO_MOI'!$C$22)^3) -> 29.250846 | K16: ='THAM_SO_MOI'!$C$31*J16/E16 -> 341.8129 | L16: =K16*'THAM_SO_MOI'!$C$53*'THAM_SO_MOI'!$C$17/'THAM_SO_MOI'!$C$26 -> 2997.7004 | M16: ='THAM_SO_MOI'!$C$15*'THAM_SO_MOI'!$C$16*F16^2 -> 201.29269 | N16: ='THAM_SO_MOI'!$C$12*I16 -> 1130.112 | O16: =M16+N16 -> 1331.4047 | P16: =(MIN(L16,'THAM_SO_MOI'!$C$41)-O16)/('THAM_SO_MOI'!$C$11*H16) -> 0.19724145 | Q16: =IF(P16>0,1/P16,NA()) -> 5.0699283 | R16: =F16-F15 -> 0.017600427 | S16: =0.5*(Q15+Q16)*R16 -> 0.08926342 | T16: =0.5*(F15*Q15+F16*Q16)*R16 -> 0.73971339 | U16: =U15+S16 -> 0.89542618 | V16: =V15+T16 -> 7.3492604
A17: Số V riêng | B17: 5 | C17: kéo | D17: low | E17: =60*F17*'THAM_SO_MOI'!$C$53/(2*PI()*'THAM_SO_MOI'!$C$26) -> 819.07516 | F17: ='THAM_SO_MOI'!$E$53+('THAM_SO_MOI'!$C$14-'THAM_SO_MOI'!$E$53)*11/'THAM_SO_MOI'!$C$42 -> 8.3132628 | G17: =3.6*F17 -> 29.927746 | H17: ='THAM_SO_MOI'!$D$53 -> 1.1 | I17: =IF(F17>'THAM_SO_MOI'!$C$14,'THAM_SO_MOI'!$C$13*(1+F17^2/1500),'THAM_SO_MOI'!$C$13) -> 0.015 | J17: ='THAM_SO_MOI'!$C$40*('THAM_SO_MOI'!$C$23*(E17/'THAM_SO_MOI'!$C$22)+'THAM_SO_MOI'!$C$24*(E17/'THAM_SO_MOI'!$C$22)^2-'THAM_SO_MOI'!$C$25*(E17/'THAM_SO_MOI'!$C$22)^3) -> 29.332361 | K17: ='THAM_SO_MOI'!$C$31*J17/E17 -> 342.03975 | L17: =K17*'THAM_SO_MOI'!$C$53*'THAM_SO_MOI'!$C$17/'THAM_SO_MOI'!$C$26 -> 2999.69 | M17: ='THAM_SO_MOI'!$C$15*'THAM_SO_MOI'!$C$16*F17^2 -> 202.14774 | N17: ='THAM_SO_MOI'!$C$12*I17 -> 1130.112 | O17: =M17+N17 -> 1332.2597 | P17: =(MIN(L17,'THAM_SO_MOI'!$C$41)-O17)/('THAM_SO_MOI'!$C$11*H17) -> 0.19737574 | Q17: =IF(P17>0,1/P17,NA()) -> 5.0664788 | R17: =F17-F16 -> 0.017600427 | S17: =0.5*(Q16+Q17)*R17 -> 0.089202549 | T17: =0.5*(F16*Q16+F17*Q17)*R17 -> 0.74077897 | U17: =U16+S17 -> 0.98462873 | V17: =V16+T17 -> 8.0900394
A18: Số V riêng | B18: 5 | C18: kéo | D18: low | E18: =60*F18*'THAM_SO_MOI'!$C$53/(2*PI()*'THAM_SO_MOI'!$C$26) -> 820.80926 | F18: ='THAM_SO_MOI'!$E$53+('THAM_SO_MOI'!$C$14-'THAM_SO_MOI'!$E$53)*12/'THAM_SO_MOI'!$C$42 -> 8.3308632 | G18: =3.6*F18 -> 29.991108 | H18: ='THAM_SO_MOI'!$D$53 -> 1.1 | I18: =IF(F18>'THAM_SO_MOI'!$C$14,'THAM_SO_MOI'!$C$13*(1+F18^2/1500),'THAM_SO_MOI'!$C$13) -> 0.015 | J18: ='THAM_SO_MOI'!$C$40*('THAM_SO_MOI'!$C$23*(E18/'THAM_SO_MOI'!$C$22)+'THAM_SO_MOI'!$C$24*(E18/'THAM_SO_MOI'!$C$22)^2-'THAM_SO_MOI'!$C$25*(E18/'THAM_SO_MOI'!$C$22)^3) -> 29.413933 | K18: ='THAM_SO_MOI'!$C$31*J18/E18 -> 342.26632 | L18: =K18*'THAM_SO_MOI'!$C$53*'THAM_SO_MOI'!$C$17/'THAM_SO_MOI'!$C$26 -> 3001.6769 | M18: ='THAM_SO_MOI'!$C$15*'THAM_SO_MOI'!$C$16*F18^2 -> 203.0046 | N18: ='THAM_SO_MOI'!$C$12*I18 -> 1130.112 | O18: =M18+N18 -> 1333.1166 | P18: =(MIN(L18,'THAM_SO_MOI'!$C$41)-O18)/('THAM_SO_MOI'!$C$11*H18) -> 0.19750951 | Q18: =IF(P18>0,1/P18,NA()) -> 5.0630473 | R18: =F18-F17 -> 0.017600427 | S18: =0.5*(Q17+Q18)*R18 -> 0.089141995 | T18: =0.5*(F17*Q17+F18*Q18)*R18 -> 0.74184503 | U18: =U17+S18 -> 1.0737707 | V18: =V17+T18 -> 8.8318844
A19: Số V riêng | B19: 5 | C19: kéo | D19: low | E19: =60*F19*'THAM_SO_MOI'!$C$53/(2*PI()*'THAM_SO_MOI'!$C$26) -> 822.54337 | F19: ='THAM_SO_MOI'!$E$53+('THAM_SO_MOI'!$C$14-'THAM_SO_MOI'!$E$53)*13/'THAM_SO_MOI'!$C$42 -> 8.3484637 | G19: =3.6*F19 -> 30.054469 | H19: ='THAM_SO_MOI'!$D$53 -> 1.1 | I19: =IF(F19>'THAM_SO_MOI'!$C$14,'THAM_SO_MOI'!$C$13*(1+F19^2/1500),'THAM_SO_MOI'!$C$13) -> 0.015 | J19: ='THAM_SO_MOI'!$C$40*('THAM_SO_MOI'!$C$23*(E19/'THAM_SO_MOI'!$C$22)+'THAM_SO_MOI'!$C$24*(E19/'THAM_SO_MOI'!$C$22)^2-'THAM_SO_MOI'!$C$25*(E19/'THAM_SO_MOI'!$C$22)^3) -> 29.495562 | K19: ='THAM_SO_MOI'!$C$31*J19/E19 -> 342.49259 | L19: =K19*'THAM_SO_MOI'!$C$53*'THAM_SO_MOI'!$C$17/'THAM_SO_MOI'!$C$26 -> 3003.6614 | M19: ='THAM_SO_MOI'!$C$15*'THAM_SO_MOI'!$C$16*F19^2 -> 203.86327 | N19: ='THAM_SO_MOI'!$C$12*I19 -> 1130.112 | O19: =M19+N19 -> 1333.9753 | P19: =(MIN(L19,'THAM_SO_MOI'!$C$41)-O19)/('THAM_SO_MOI'!$C$11*H19) -> 0.19764277 | Q19: =IF(P19>0,1/P19,NA()) -> 5.0596337 | R19: =F19-F18 -> 0.017600427 | S19: =0.5*(Q18+Q19)*R19 -> 0.089081756 | T19: =0.5*(F18*Q18+F19*Q19)*R19 -> 0.7429116 | U19: =U18+S19 -> 1.1628525 | V19: =V18+T19 -> 9.574796
A20: Số V riêng | B20: 5 | C20: kéo | D20: low | E20: =60*F20*'THAM_SO_MOI'!$C$53/(2*PI()*'THAM_SO_MOI'!$C$26) -> 824.27747 | F20: ='THAM_SO_MOI'!$E$53+('THAM_SO_MOI'!$C$14-'THAM_SO_MOI'!$E$53)*14/'THAM_SO_MOI'!$C$42 -> 8.3660641 | G20: =3.6*F20 -> 30.117831 | H20: ='THAM_SO_MOI'!$D$53 -> 1.1 | I20: =IF(F20>'THAM_SO_MOI'!$C$14,'THAM_SO_MOI'!$C$13*(1+F20^2/1500),'THAM_SO_MOI'!$C$13) -> 0.015 | J20: ='THAM_SO_MOI'!$C$40*('THAM_SO_MOI'!$C$23*(E20/'THAM_SO_MOI'!$C$22)+'THAM_SO_MOI'!$C$24*(E20/'THAM_SO_MOI'!$C$22)^2-'THAM_SO_MOI'!$C$25*(E20/'THAM_SO_MOI'!$C$22)^3) -> 29.577247 | K20: ='THAM_SO_MOI'!$C$31*J20/E20 -> 342.71857 | L20: =K20*'THAM_SO_MOI'!$C$53*'THAM_SO_MOI'!$C$17/'THAM_SO_MOI'!$C$26 -> 3005.6432 | M20: ='THAM_SO_MOI'!$C$15*'THAM_SO_MOI'!$C$16*F20^2 -> 204.72376 | N20: ='THAM_SO_MOI'!$C$12*I20 -> 1130.112 | O20: =M20+N20 -> 1334.8358 | P20: =(MIN(L20,'THAM_SO_MOI'!$C$41)-O20)/('THAM_SO_MOI'!$C$11*H20) -> 0.1977755 | Q20: =IF(P20>0,1/P20,NA()) -> 5.0562379 | R20: =F20-F19 -> 0.017600427 | S20: =0.5*(Q19+Q20)*R20 -> 0.089021831 | T20: =0.5*(F19*Q19+F20*Q20)*R20 -> 0.74397867 | U20: =U19+S20 -> 1.2518743 | V20: =V19+T20 -> 10.318775
A21: Số V riêng | B21: 5 | C21: kéo | D21: low | E21: =60*F21*'THAM_SO_MOI'!$C$53/(2*PI()*'THAM_SO_MOI'!$C$26) -> 826.01158 | F21: ='THAM_SO_MOI'!$E$53+('THAM_SO_MOI'!$C$14-'THAM_SO_MOI'!$E$53)*15/'THAM_SO_MOI'!$C$42 -> 8.3836645 | G21: =3.6*F21 -> 30.181192 | H21: ='THAM_SO_MOI'!$D$53 -> 1.1 | I21: =IF(F21>'THAM_SO_MOI'!$C$14,'THAM_SO_MOI'!$C$13*(1+F21^2/1500),'THAM_SO_MOI'!$C$13) -> 0.015 | J21: ='THAM_SO_MOI'!$C$40*('THAM_SO_MOI'!$C$23*(E21/'THAM_SO_MOI'!$C$22)+'THAM_SO_MOI'!$C$24*(E21/'THAM_SO_MOI'!$C$22)^2-'THAM_SO_MOI'!$C$25*(E21/'THAM_SO_MOI'!$C$22)^3) -> 29.65899 | K21: ='THAM_SO_MOI'!$C$31*J21/E21 -> 342.94426 | L21: =K21*'THAM_SO_MOI'!$C$53*'THAM_SO_MOI'!$C$17/'THAM_SO_MOI'!$C$26 -> 3007.6225 | M21: ='THAM_SO_MOI'!$C$15*'THAM_SO_MOI'!$C$16*F21^2 -> 205.58606 | N21: ='THAM_SO_MOI'!$C$12*I21 -> 1130.112 | O21: =M21+N21 -> 1335.6981 | P21: =(MIN(L21,'THAM_SO_MOI'!$C$41)-O21)/('THAM_SO_MOI'!$C$11*H21) -> 0.19790773 | Q21: =IF(P21>0,1/P21,NA()) -> 5.0528598 | R21: =F21-F20 -> 0.017600427 | S21: =0.5*(Q20+Q21)*R21 -> 0.08896222 | T21: =0.5*(F20*Q20+F21*Q21)*R21 -> 0.74504626 | U21: =U20+S21 -> 1.3408365 | V21: =V20+T21 -> 11.063821
A22: Số V riêng | B22: 5 | C22: kéo | D22: low | E22: =60*F22*'THAM_SO_MOI'!$C$53/(2*PI()*'THAM_SO_MOI'!$C$26) -> 827.74568 | F22: ='THAM_SO_MOI'!$E$53+('THAM_SO_MOI'!$C$14-'THAM_SO_MOI'!$E$53)*16/'THAM_SO_MOI'!$C$42 -> 8.401265 | G22: =3.6*F22 -> 30.244554 | H22: ='THAM_SO_MOI'!$D$53 -> 1.1 | I22: =IF(F22>'THAM_SO_MOI'!$C$14,'THAM_SO_MOI'!$C$13*(1+F22^2/1500),'THAM_SO_MOI'!$C$13) -> 0.015 | J22: ='THAM_SO_MOI'!$C$40*('THAM_SO_MOI'!$C$23*(E22/'THAM_SO_MOI'!$C$22)+'THAM_SO_MOI'!$C$24*(E22/'THAM_SO_MOI'!$C$22)^2-'THAM_SO_MOI'!$C$25*(E22/'THAM_SO_MOI'!$C$22)^3) -> 29.740789 | K22: ='THAM_SO_MOI'!$C$31*J22/E22 -> 343.16966 | L22: =K22*'THAM_SO_MOI'!$C$53*'THAM_SO_MOI'!$C$17/'THAM_SO_MOI'!$C$26 -> 3009.5993 | M22: ='THAM_SO_MOI'!$C$15*'THAM_SO_MOI'!$C$16*F22^2 -> 206.45016 | N22: ='THAM_SO_MOI'!$C$12*I22 -> 1130.112 | O22: =M22+N22 -> 1336.5622 | P22: =(MIN(L22,'THAM_SO_MOI'!$C$41)-O22)/('THAM_SO_MOI'!$C$11*H22) -> 0.19803943 | Q22: =IF(P22>0,1/P22,NA()) -> 5.0494995 | R22: =F22-F21 -> 0.017600427 | S22: =0.5*(Q21+Q22)*R22 -> 0.088902921 | T22: =0.5*(F21*Q21+F22*Q22)*R22 -> 0.74611437 | U22: =U21+S22 -> 1.4297395 | V22: =V21+T22 -> 11.809935
A23: Số V riêng | B23: 5 | C23: kéo | D23: low | E23: =60*F23*'THAM_SO_MOI'!$C$53/(2*PI()*'THAM_SO_MOI'!$C$26) -> 829.47979 | F23: ='THAM_SO_MOI'!$E$53+('THAM_SO_MOI'!$C$14-'THAM_SO_MOI'!$E$53)*17/'THAM_SO_MOI'!$C$42 -> 8.4188654 | G23: =3.6*F23 -> 30.307915 | H23: ='THAM_SO_MOI'!$D$53 -> 1.1 | I23: =IF(F23>'THAM_SO_MOI'!$C$14,'THAM_SO_MOI'!$C$13*(1+F23^2/1500),'THAM_SO_MOI'!$C$13) -> 0.015 | J23: ='THAM_SO_MOI'!$C$40*('THAM_SO_MOI'!$C$23*(E23/'THAM_SO_MOI'!$C$22)+'THAM_SO_MOI'!$C$24*(E23/'THAM_SO_MOI'!$C$22)^2-'THAM_SO_MOI'!$C$25*(E23/'THAM_SO_MOI'!$C$22)^3) -> 29.822645 | K23: ='THAM_SO_MOI'!$C$31*J23/E23 -> 343.39477 | L23: =K23*'THAM_SO_MOI'!$C$53*'THAM_SO_MOI'!$C$17/'THAM_SO_MOI'!$C$26 -> 3011.5734 | M23: ='THAM_SO_MOI'!$C$15*'THAM_SO_MOI'!$C$16*F23^2 -> 207.31609 | N23: ='THAM_SO_MOI'!$C$12*I23 -> 1130.112 | O23: =M23+N23 -> 1337.4281 | P23: =(MIN(L23,'THAM_SO_MOI'!$C$41)-O23)/('THAM_SO_MOI'!$C$11*H23) -> 0.19817062 | Q23: =IF(P23>0,1/P23,NA()) -> 5.0461568 | R23: =F23-F22 -> 0.017600427 | S23: =0.5*(Q22+Q23)*R23 -> 0.088843933 | T23: =0.5*(F22*Q22+F23*Q23)*R23 -> 0.747183 | U23: =U22+S23 -> 1.5185834 | V23: =V22+T23 -> 12.557118
A24: Số V riêng | B24: 5 | C24: kéo | D24: low | E24: =60*F24*'THAM_SO_MOI'!$C$53/(2*PI()*'THAM_SO_MOI'!$C$26) -> 831.21389 | F24: ='THAM_SO_MOI'!$E$53+('THAM_SO_MOI'!$C$14-'THAM_SO_MOI'!$E$53)*18/'THAM_SO_MOI'!$C$42 -> 8.4364658 | G24: =3.6*F24 -> 30.371277 | H24: ='THAM_SO_MOI'!$D$53 -> 1.1 | I24: =IF(F24>'THAM_SO_MOI'!$C$14,'THAM_SO_MOI'!$C$13*(1+F24^2/1500),'THAM_SO_MOI'!$C$13) -> 0.015 | J24: ='THAM_SO_MOI'!$C$40*('THAM_SO_MOI'!$C$23*(E24/'THAM_SO_MOI'!$C$22)+'THAM_SO_MOI'!$C$24*(E24/'THAM_SO_MOI'!$C$22)^2-'THAM_SO_MOI'!$C$25*(E24/'THAM_SO_MOI'!$C$22)^3) -> 29.904557 | K24: ='THAM_SO_MOI'!$C$31*J24/E24 -> 343.61958 | L24: =K24*'THAM_SO_MOI'!$C$53*'THAM_SO_MOI'!$C$17/'THAM_SO_MOI'!$C$26 -> 3013.5451 | M24: ='THAM_SO_MOI'!$C$15*'THAM_SO_MOI'!$C$16*F24^2 -> 208.18382 | N24: ='THAM_SO_MOI'!$C$12*I24 -> 1130.112 | O24: =M24+N24 -> 1338.2958 | P24: =(MIN(L24,'THAM_SO_MOI'!$C$41)-O24)/('THAM_SO_MOI'!$C$11*H24) -> 0.19830128 | Q24: =IF(P24>0,1/P24,NA()) -> 5.0428317 | R24: =F24-F23 -> 0.017600427 | S24: =0.5*(Q23+Q24)*R24 -> 0.088785254 | T24: =0.5*(F23*Q23+F24*Q24)*R24 -> 0.74825218 | U24: =U23+S24 -> 1.6073686 | V24: =V23+T24 -> 13.30537
A25: Số V riêng | B25: 5 | C25: kéo | D25: low | E25: =60*F25*'THAM_SO_MOI'!$C$53/(2*PI()*'THAM_SO_MOI'!$C$26) -> 832.948 | F25: ='THAM_SO_MOI'!$E$53+('THAM_SO_MOI'!$C$14-'THAM_SO_MOI'!$E$53)*19/'THAM_SO_MOI'!$C$42 -> 8.4540662 | G25: =3.6*F25 -> 30.434638 | H25: ='THAM_SO_MOI'!$D$53 -> 1.1 | I25: =IF(F25>'THAM_SO_MOI'!$C$14,'THAM_SO_MOI'!$C$13*(1+F25^2/1500),'THAM_SO_MOI'!$C$13) -> 0.015 | J25: ='THAM_SO_MOI'!$C$40*('THAM_SO_MOI'!$C$23*(E25/'THAM_SO_MOI'!$C$22)+'THAM_SO_MOI'!$C$24*(E25/'THAM_SO_MOI'!$C$22)^2-'THAM_SO_MOI'!$C$25*(E25/'THAM_SO_MOI'!$C$22)^3) -> 29.986526 | K25: ='THAM_SO_MOI'!$C$31*J25/E25 -> 343.8441 | L25: =K25*'THAM_SO_MOI'!$C$53*'THAM_SO_MOI'!$C$17/'THAM_SO_MOI'!$C$26 -> 3015.5141 | M25: ='THAM_SO_MOI'!$C$15*'THAM_SO_MOI'!$C$16*F25^2 -> 209.05337 | N25: ='THAM_SO_MOI'!$C$12*I25 -> 1130.112 | O25: =M25+N25 -> 1339.1654 | P25: =(MIN(L25,'THAM_SO_MOI'!$C$41)-O25)/('THAM_SO_MOI'!$C$11*H25) -> 0.19843144 | Q25: =IF(P25>0,1/P25,NA()) -> 5.0395241 | R25: =F25-F24 -> 0.017600427 | S25: =0.5*(Q24+Q25)*R25 -> 0.088726885 | T25: =0.5*(F24*Q24+F25*Q25)*R25 -> 0.74932189 | U25: =U24+S25 -> 1.6960955 | V25: =V24+T25 -> 14.054692
A26: Số V riêng | B26: 5 | C26: kéo | D26: low | E26: =60*F26*'THAM_SO_MOI'!$C$53/(2*PI()*'THAM_SO_MOI'!$C$26) -> 834.68211 | F26: ='THAM_SO_MOI'!$E$53+('THAM_SO_MOI'!$C$14-'THAM_SO_MOI'!$E$53)*20/'THAM_SO_MOI'!$C$42 -> 8.4716667 | G26: =3.6*F26 -> 30.498 | H26: ='THAM_SO_MOI'!$D$53 -> 1.1 | I26: =IF(F26>'THAM_SO_MOI'!$C$14,'THAM_SO_MOI'!$C$13*(1+F26^2/1500),'THAM_SO_MOI'!$C$13) -> 0.015 | J26: ='THAM_SO_MOI'!$C$40*('THAM_SO_MOI'!$C$23*(E26/'THAM_SO_MOI'!$C$22)+'THAM_SO_MOI'!$C$24*(E26/'THAM_SO_MOI'!$C$22)^2-'THAM_SO_MOI'!$C$25*(E26/'THAM_SO_MOI'!$C$22)^3) -> 30.06855 | K26: ='THAM_SO_MOI'!$C$31*J26/E26 -> 344.06834 | L26: =K26*'THAM_SO_MOI'!$C$53*'THAM_SO_MOI'!$C$17/'THAM_SO_MOI'!$C$26 -> 3017.4806 | M26: ='THAM_SO_MOI'!$C$15*'THAM_SO_MOI'!$C$16*F26^2 -> 209.92472 | N26: ='THAM_SO_MOI'!$C$12*I26 -> 1130.112 | O26: =M26+N26 -> 1340.0367 | P26: =(MIN(L26,'THAM_SO_MOI'!$C$41)-O26)/('THAM_SO_MOI'!$C$11*H26) -> 0.19856107 | Q26: =IF(P26>0,1/P26,NA()) -> 5.0362339 | R26: =F26-F25 -> 0.017600427 | S26: =0.5*(Q25+Q26)*R26 -> 0.088668823 | T26: =0.5*(F25*Q25+F26*Q26)*R26 -> 0.75039216 | U26: =U25+S26 -> 1.7847643 | V26: =V25+T26 -> 14.805085
A27: Số V riêng | B27: 5 | C27: kéo | D27: low | E27: =60*F27*'THAM_SO_MOI'!$C$53/(2*PI()*'THAM_SO_MOI'!$C$26) -> 836.41621 | F27: ='THAM_SO_MOI'!$E$53+('THAM_SO_MOI'!$C$14-'THAM_SO_MOI'!$E$53)*21/'THAM_SO_MOI'!$C$42 -> 8.4892671 | G27: =3.6*F27 -> 30.561362 | H27: ='THAM_SO_MOI'!$D$53 -> 1.1 | I27: =IF(F27>'THAM_SO_MOI'!$C$14,'THAM_SO_MOI'!$C$13*(1+F27^2/1500),'THAM_SO_MOI'!$C$13) -> 0.015 | J27: ='THAM_SO_MOI'!$C$40*('THAM_SO_MOI'!$C$23*(E27/'THAM_SO_MOI'!$C$22)+'THAM_SO_MOI'!$C$24*(E27/'THAM_SO_MOI'!$C$22)^2-'THAM_SO_MOI'!$C$25*(E27/'THAM_SO_MOI'!$C$22)^3) -> 30.150631 | K27: ='THAM_SO_MOI'!$C$31*J27/E27 -> 344.29227 | L27: =K27*'THAM_SO_MOI'!$C$53*'THAM_SO_MOI'!$C$17/'THAM_SO_MOI'!$C$26 -> 3019.4446 | M27: ='THAM_SO_MOI'!$C$15*'THAM_SO_MOI'!$C$16*F27^2 -> 210.79789 | N27: ='THAM_SO_MOI'!$C$12*I27 -> 1130.112 | O27: =M27+N27 -> 1340.9099 | P27: =(MIN(L27,'THAM_SO_MOI'!$C$41)-O27)/('THAM_SO_MOI'!$C$11*H27) -> 0.19869019 | Q27: =IF(P27>0,1/P27,NA()) -> 5.0329612 | R27: =F27-F26 -> 0.017600427 | S27: =0.5*(Q26+Q27)*R27 -> 0.088611069 | T27: =0.5*(F26*Q26+F27*Q27)*R27 -> 0.75146298 | U27: =U26+S27 -> 1.8733754 | V27: =V26+T27 -> 15.556548
A28: Số V riêng | B28: 5 | C28: kéo | D28: low | E28: =60*F28*'THAM_SO_MOI'!$C$53/(2*PI()*'THAM_SO_MOI'!$C$26) -> 838.15032 | F28: ='THAM_SO_MOI'!$E$53+('THAM_SO_MOI'!$C$14-'THAM_SO_MOI'!$E$53)*22/'THAM_SO_MOI'!$C$42 -> 8.5068675 | G28: =3.6*F28 -> 30.624723 | H28: ='THAM_SO_MOI'!$D$53 -> 1.1 | I28: =IF(F28>'THAM_SO_MOI'!$C$14,'THAM_SO_MOI'!$C$13*(1+F28^2/1500),'THAM_SO_MOI'!$C$13) -> 0.015 | J28: ='THAM_SO_MOI'!$C$40*('THAM_SO_MOI'!$C$23*(E28/'THAM_SO_MOI'!$C$22)+'THAM_SO_MOI'!$C$24*(E28/'THAM_SO_MOI'!$C$22)^2-'THAM_SO_MOI'!$C$25*(E28/'THAM_SO_MOI'!$C$22)^3) -> 30.232767 | K28: ='THAM_SO_MOI'!$C$31*J28/E28 -> 344.51592 | L28: =K28*'THAM_SO_MOI'!$C$53*'THAM_SO_MOI'!$C$17/'THAM_SO_MOI'!$C$26 -> 3021.406 | M28: ='THAM_SO_MOI'!$C$15*'THAM_SO_MOI'!$C$16*F28^2 -> 211.67288 | N28: ='THAM_SO_MOI'!$C$12*I28 -> 1130.112 | O28: =M28+N28 -> 1341.7849 | P28: =(MIN(L28,'THAM_SO_MOI'!$C$41)-O28)/('THAM_SO_MOI'!$C$11*H28) -> 0.19881879 | Q28: =IF(P28>0,1/P28,NA()) -> 5.0297058 | R28: =F28-F27 -> 0.017600427 | S28: =0.5*(Q27+Q28)*R28 -> 0.088553619 | T28: =0.5*(F27*Q27+F28*Q28)*R28 -> 0.75253437 | U28: =U27+S28 -> 1.961929 | V28: =V27+T28 -> 16.309082
A29: Số V riêng | B29: 5 | C29: kéo | D29: low | E29: =60*F29*'THAM_SO_MOI'!$C$53/(2*PI()*'THAM_SO_MOI'!$C$26) -> 839.88442 | F29: ='THAM_SO_MOI'!$E$53+('THAM_SO_MOI'!$C$14-'THAM_SO_MOI'!$E$53)*23/'THAM_SO_MOI'!$C$42 -> 8.5244679 | G29: =3.6*F29 -> 30.688085 | H29: ='THAM_SO_MOI'!$D$53 -> 1.1 | I29: =IF(F29>'THAM_SO_MOI'!$C$14,'THAM_SO_MOI'!$C$13*(1+F29^2/1500),'THAM_SO_MOI'!$C$13) -> 0.015 | J29: ='THAM_SO_MOI'!$C$40*('THAM_SO_MOI'!$C$23*(E29/'THAM_SO_MOI'!$C$22)+'THAM_SO_MOI'!$C$24*(E29/'THAM_SO_MOI'!$C$22)^2-'THAM_SO_MOI'!$C$25*(E29/'THAM_SO_MOI'!$C$22)^3) -> 30.314958 | K29: ='THAM_SO_MOI'!$C$31*J29/E29 -> 344.73928 | L29: =K29*'THAM_SO_MOI'!$C$53*'THAM_SO_MOI'!$C$17/'THAM_SO_MOI'!$C$26 -> 3023.3648 | M29: ='THAM_SO_MOI'!$C$15*'THAM_SO_MOI'!$C$16*F29^2 -> 212.54967 | N29: ='THAM_SO_MOI'!$C$12*I29 -> 1130.112 | O29: =M29+N29 -> 1342.6617 | P29: =(MIN(L29,'THAM_SO_MOI'!$C$41)-O29)/('THAM_SO_MOI'!$C$11*H29) -> 0.19894687 | Q29: =IF(P29>0,1/P29,NA()) -> 5.0264676 | R29: =F29-F28 -> 0.017600427 | S29: =0.5*(Q28+Q29)*R29 -> 0.088496475 | T29: =0.5*(F28*Q28+F29*Q29)*R29 -> 0.75360633 | U29: =U28+S29 -> 2.0504255 | V29: =V28+T29 -> 17.062688
A30: Số V riêng | B30: 5 | C30: kéo | D30: low | E30: =60*F30*'THAM_SO_MOI'!$C$53/(2*PI()*'THAM_SO_MOI'!$C$26) -> 841.61853 | F30: ='THAM_SO_MOI'!$E$53+('THAM_SO_MOI'!$C$14-'THAM_SO_MOI'!$E$53)*24/'THAM_SO_MOI'!$C$42 -> 8.5420684 | G30: =3.6*F30 -> 30.751446 | H30: ='THAM_SO_MOI'!$D$53 -> 1.1 | I30: =IF(F30>'THAM_SO_MOI'!$C$14,'THAM_SO_MOI'!$C$13*(1+F30^2/1500),'THAM_SO_MOI'!$C$13) -> 0.015 | J30: ='THAM_SO_MOI'!$C$40*('THAM_SO_MOI'!$C$23*(E30/'THAM_SO_MOI'!$C$22)+'THAM_SO_MOI'!$C$24*(E30/'THAM_SO_MOI'!$C$22)^2-'THAM_SO_MOI'!$C$25*(E30/'THAM_SO_MOI'!$C$22)^3) -> 30.397205 | K30: ='THAM_SO_MOI'!$C$31*J30/E30 -> 344.96234 | L30: =K30*'THAM_SO_MOI'!$C$53*'THAM_SO_MOI'!$C$17/'THAM_SO_MOI'!$C$26 -> 3025.3211 | M30: ='THAM_SO_MOI'!$C$15*'THAM_SO_MOI'!$C$16*F30^2 -> 213.42828 | N30: ='THAM_SO_MOI'!$C$12*I30 -> 1130.112 | O30: =M30+N30 -> 1343.5403 | P30: =(MIN(L30,'THAM_SO_MOI'!$C$41)-O30)/('THAM_SO_MOI'!$C$11*H30) -> 0.19907443 | Q30: =IF(P30>0,1/P30,NA()) -> 5.0232467 | R30: =F30-F29 -> 0.017600427 | S30: =0.5*(Q29+Q30)*R30 -> 0.088439634 | T30: =0.5*(F29*Q29+F30*Q30)*R30 -> 0.75467886 | U30: =U29+S30 -> 2.1388651 | V30: =V29+T30 -> 17.817367
A31: Số V riêng | B31: 5 | C31: kéo | D31: low | E31: =60*F31*'THAM_SO_MOI'!$C$53/(2*PI()*'THAM_SO_MOI'!$C$26) -> 843.35263 | F31: ='THAM_SO_MOI'!$E$53+('THAM_SO_MOI'!$C$14-'THAM_SO_MOI'!$E$53)*25/'THAM_SO_MOI'!$C$42 -> 8.5596688 | G31: =3.6*F31 -> 30.814808 | H31: ='THAM_SO_MOI'!$D$53 -> 1.1 | I31: =IF(F31>'THAM_SO_MOI'!$C$14,'THAM_SO_MOI'!$C$13*(1+F31^2/1500),'THAM_SO_MOI'!$C$13) -> 0.015 | J31: ='THAM_SO_MOI'!$C$40*('THAM_SO_MOI'!$C$23*(E31/'THAM_SO_MOI'!$C$22)+'THAM_SO_MOI'!$C$24*(E31/'THAM_SO_MOI'!$C$22)^2-'THAM_SO_MOI'!$C$25*(E31/'THAM_SO_MOI'!$C$22)^3) -> 30.479508 | K31: ='THAM_SO_MOI'!$C$31*J31/E31 -> 345.18511 | L31: =K31*'THAM_SO_MOI'!$C$53*'THAM_SO_MOI'!$C$17/'THAM_SO_MOI'!$C$26 -> 3027.2748 | M31: ='THAM_SO_MOI'!$C$15*'THAM_SO_MOI'!$C$16*F31^2 -> 214.3087 | N31: ='THAM_SO_MOI'!$C$12*I31 -> 1130.112 | O31: =M31+N31 -> 1344.4207 | P31: =(MIN(L31,'THAM_SO_MOI'!$C$41)-O31)/('THAM_SO_MOI'!$C$11*H31) -> 0.19920148 | Q31: =IF(P31>0,1/P31,NA()) -> 5.020043 | R31: =F31-F30 -> 0.017600427 | S31: =0.5*(Q30+Q31)*R31 -> 0.088383096 | T31: =0.5*(F30*Q30+F31*Q31)*R31 -> 0.75575199 | U31: =U30+S31 -> 2.2272482 | V31: =V30+T31 -> 18.573119
A32: Số V riêng | B32: 5 | C32: kéo | D32: low | E32: =60*F32*'THAM_SO_MOI'!$C$53/(2*PI()*'THAM_SO_MOI'!$C$26) -> 845.08674 | F32: ='THAM_SO_MOI'!$E$53+('THAM_SO_MOI'!$C$14-'THAM_SO_MOI'!$E$53)*26/'THAM_SO_MOI'!$C$42 -> 8.5772692 | G32: =3.6*F32 -> 30.878169 | H32: ='THAM_SO_MOI'!$D$53 -> 1.1 | I32: =IF(F32>'THAM_SO_MOI'!$C$14,'THAM_SO_MOI'!$C$13*(1+F32^2/1500),'THAM_SO_MOI'!$C$13) -> 0.015 | J32: ='THAM_SO_MOI'!$C$40*('THAM_SO_MOI'!$C$23*(E32/'THAM_SO_MOI'!$C$22)+'THAM_SO_MOI'!$C$24*(E32/'THAM_SO_MOI'!$C$22)^2-'THAM_SO_MOI'!$C$25*(E32/'THAM_SO_MOI'!$C$22)^3) -> 30.561865 | K32: ='THAM_SO_MOI'!$C$31*J32/E32 -> 345.4076 | L32: =K32*'THAM_SO_MOI'!$C$53*'THAM_SO_MOI'!$C$17/'THAM_SO_MOI'!$C$26 -> 3029.226 | M32: ='THAM_SO_MOI'!$C$15*'THAM_SO_MOI'!$C$16*F32^2 -> 215.19093 | N32: ='THAM_SO_MOI'!$C$12*I32 -> 1130.112 | O32: =M32+N32 -> 1345.3029 | P32: =(MIN(L32,'THAM_SO_MOI'!$C$41)-O32)/('THAM_SO_MOI'!$C$11*H32) -> 0.19932801 | Q32: =IF(P32>0,1/P32,NA()) -> 5.0168564 | R32: =F32-F31 -> 0.017600427 | S32: =0.5*(Q31+Q32)*R32 -> 0.088326859 | T32: =0.5*(F31*Q31+F32*Q32)*R32 -> 0.75682571 | U32: =U31+S32 -> 2.3155751 | V32: =V31+T32 -> 19.329945
A33: Số V riêng | B33: 5 | C33: kéo | D33: low | E33: =60*F33*'THAM_SO_MOI'!$C$53/(2*PI()*'THAM_SO_MOI'!$C$26) -> 846.82084 | F33: ='THAM_SO_MOI'!$E$53+('THAM_SO_MOI'!$C$14-'THAM_SO_MOI'!$E$53)*27/'THAM_SO_MOI'!$C$42 -> 8.5948697 | G33: =3.6*F33 -> 30.941531 | H33: ='THAM_SO_MOI'!$D$53 -> 1.1 | I33: =IF(F33>'THAM_SO_MOI'!$C$14,'THAM_SO_MOI'!$C$13*(1+F33^2/1500),'THAM_SO_MOI'!$C$13) -> 0.015 | J33: ='THAM_SO_MOI'!$C$40*('THAM_SO_MOI'!$C$23*(E33/'THAM_SO_MOI'!$C$22)+'THAM_SO_MOI'!$C$24*(E33/'THAM_SO_MOI'!$C$22)^2-'THAM_SO_MOI'!$C$25*(E33/'THAM_SO_MOI'!$C$22)^3) -> 30.644277 | K33: ='THAM_SO_MOI'!$C$31*J33/E33 -> 345.62978 | L33: =K33*'THAM_SO_MOI'!$C$53*'THAM_SO_MOI'!$C$17/'THAM_SO_MOI'!$C$26 -> 3031.1746 | M33: ='THAM_SO_MOI'!$C$15*'THAM_SO_MOI'!$C$16*F33^2 -> 216.07497 | N33: ='THAM_SO_MOI'!$C$12*I33 -> 1130.112 | O33: =M33+N33 -> 1346.187 | P33: =(MIN(L33,'THAM_SO_MOI'!$C$41)-O33)/('THAM_SO_MOI'!$C$11*H33) -> 0.19945402 | Q33: =IF(P33>0,1/P33,NA()) -> 5.0136868 | R33: =F33-F32 -> 0.017600427 | S33: =0.5*(Q32+Q33)*R33 -> 0.088270923 | T33: =0.5*(F32*Q32+F33*Q33)*R33 -> 0.75790003 | U33: =U32+S33 -> 2.403846 | V33: =V32+T33 -> 20.087845
A34: Số V riêng | B34: 5 | C34: kéo | D34: low | E34: =60*F34*'THAM_SO_MOI'!$C$53/(2*PI()*'THAM_SO_MOI'!$C$26) -> 848.55495 | F34: ='THAM_SO_MOI'!$E$53+('THAM_SO_MOI'!$C$14-'THAM_SO_MOI'!$E$53)*28/'THAM_SO_MOI'!$C$42 -> 8.6124701 | G34: =3.6*F34 -> 31.004892 | H34: ='THAM_SO_MOI'!$D$53 -> 1.1 | I34: =IF(F34>'THAM_SO_MOI'!$C$14,'THAM_SO_MOI'!$C$13*(1+F34^2/1500),'THAM_SO_MOI'!$C$13) -> 0.015 | J34: ='THAM_SO_MOI'!$C$40*('THAM_SO_MOI'!$C$23*(E34/'THAM_SO_MOI'!$C$22)+'THAM_SO_MOI'!$C$24*(E34/'THAM_SO_MOI'!$C$22)^2-'THAM_SO_MOI'!$C$25*(E34/'THAM_SO_MOI'!$C$22)^3) -> 30.726744 | K34: ='THAM_SO_MOI'!$C$31*J34/E34 -> 345.85168 | L34: =K34*'THAM_SO_MOI'!$C$53*'THAM_SO_MOI'!$C$17/'THAM_SO_MOI'!$C$26 -> 3033.1206 | M34: ='THAM_SO_MOI'!$C$15*'THAM_SO_MOI'!$C$16*F34^2 -> 216.96082 | N34: ='THAM_SO_MOI'!$C$12*I34 -> 1130.112 | O34: =M34+N34 -> 1347.0728 | P34: =(MIN(L34,'THAM_SO_MOI'!$C$41)-O34)/('THAM_SO_MOI'!$C$11*H34) -> 0.19957952 | Q34: =IF(P34>0,1/P34,NA()) -> 5.0105342 | R34: =F34-F33 -> 0.017600427 | S34: =0.5*(Q33+Q34)*R34 -> 0.088215286 | T34: =0.5*(F33*Q33+F34*Q34)*R34 -> 0.75897496 | U34: =U33+S34 -> 2.4920613 | V34: =V33+T34 -> 20.84682
A35: Số V riêng | B35: 5 | C35: kéo | D35: low | E35: =60*F35*'THAM_SO_MOI'!$C$53/(2*PI()*'THAM_SO_MOI'!$C$26) -> 850.28905 | F35: ='THAM_SO_MOI'!$E$53+('THAM_SO_MOI'!$C$14-'THAM_SO_MOI'!$E$53)*29/'THAM_SO_MOI'!$C$42 -> 8.6300705 | G35: =3.6*F35 -> 31.068254 | H35: ='THAM_SO_MOI'!$D$53 -> 1.1 | I35: =IF(F35>'THAM_SO_MOI'!$C$14,'THAM_SO_MOI'!$C$13*(1+F35^2/1500),'THAM_SO_MOI'!$C$13) -> 0.015 | J35: ='THAM_SO_MOI'!$C$40*('THAM_SO_MOI'!$C$23*(E35/'THAM_SO_MOI'!$C$22)+'THAM_SO_MOI'!$C$24*(E35/'THAM_SO_MOI'!$C$22)^2-'THAM_SO_MOI'!$C$25*(E35/'THAM_SO_MOI'!$C$22)^3) -> 30.809266 | K35: ='THAM_SO_MOI'!$C$31*J35/E35 -> 346.07329 | L35: =K35*'THAM_SO_MOI'!$C$53*'THAM_SO_MOI'!$C$17/'THAM_SO_MOI'!$C$26 -> 3035.0641 | M35: ='THAM_SO_MOI'!$C$15*'THAM_SO_MOI'!$C$16*F35^2 -> 217.84849 | N35: ='THAM_SO_MOI'!$C$12*I35 -> 1130.112 | O35: =M35+N35 -> 1347.9605 | P35: =(MIN(L35,'THAM_SO_MOI'!$C$41)-O35)/('THAM_SO_MOI'!$C$11*H35) -> 0.1997045 | Q35: =IF(P35>0,1/P35,NA()) -> 5.0073985 | R35: =F35-F34 -> 0.017600427 | S35: =0.5*(Q34+Q35)*R35 -> 0.088159948 | T35: =0.5*(F34*Q34+F35*Q35)*R35 -> 0.7600505 | U35: =U34+S35 -> 2.5802213 | V35: =V34+T35 -> 21.60687
A36: Số V riêng | B36: 5 | C36: kéo | D36: low | E36: =60*F36*'THAM_SO_MOI'!$C$53/(2*PI()*'THAM_SO_MOI'!$C$26) -> 852.02316 | F36: ='THAM_SO_MOI'!$E$53+('THAM_SO_MOI'!$C$14-'THAM_SO_MOI'!$E$53)*30/'THAM_SO_MOI'!$C$42 -> 8.6476709 | G36: =3.6*F36 -> 31.131615 | H36: ='THAM_SO_MOI'!$D$53 -> 1.1 | I36: =IF(F36>'THAM_SO_MOI'!$C$14,'THAM_SO_MOI'!$C$13*(1+F36^2/1500),'THAM_SO_MOI'!$C$13) -> 0.015 | J36: ='THAM_SO_MOI'!$C$40*('THAM_SO_MOI'!$C$23*(E36/'THAM_SO_MOI'!$C$22)+'THAM_SO_MOI'!$C$24*(E36/'THAM_SO_MOI'!$C$22)^2-'THAM_SO_MOI'!$C$25*(E36/'THAM_SO_MOI'!$C$22)^3) -> 30.891842 | K36: ='THAM_SO_MOI'!$C$31*J36/E36 -> 346.2946 | L36: =K36*'THAM_SO_MOI'!$C$53*'THAM_SO_MOI'!$C$17/'THAM_SO_MOI'!$C$26 -> 3037.005 | M36: ='THAM_SO_MOI'!$C$15*'THAM_SO_MOI'!$C$16*F36^2 -> 218.73797 | N36: ='THAM_SO_MOI'!$C$12*I36 -> 1130.112 | O36: =M36+N36 -> 1348.85 | P36: =(MIN(L36,'THAM_SO_MOI'!$C$41)-O36)/('THAM_SO_MOI'!$C$11*H36) -> 0.19982896 | Q36: =IF(P36>0,1/P36,NA()) -> 5.0042797 | R36: =F36-F35 -> 0.017600427 | S36: =0.5*(Q35+Q36)*R36 -> 0.088104908 | T36: =0.5*(F35*Q35+F36*Q36)*R36 -> 0.76112667 | U36: =U35+S36 -> 2.6683262 | V36: =V35+T36 -> 22.367997
A37: Số V riêng | B37: 5 | C37: kéo | D37: low | E37: =60*F37*'THAM_SO_MOI'!$C$53/(2*PI()*'THAM_SO_MOI'!$C$26) -> 853.75726 | F37: ='THAM_SO_MOI'!$E$53+('THAM_SO_MOI'!$C$14-'THAM_SO_MOI'!$E$53)*31/'THAM_SO_MOI'!$C$42 -> 8.6652714 | G37: =3.6*F37 -> 31.194977 | H37: ='THAM_SO_MOI'!$D$53 -> 1.1 | I37: =IF(F37>'THAM_SO_MOI'!$C$14,'THAM_SO_MOI'!$C$13*(1+F37^2/1500),'THAM_SO_MOI'!$C$13) -> 0.015 | J37: ='THAM_SO_MOI'!$C$40*('THAM_SO_MOI'!$C$23*(E37/'THAM_SO_MOI'!$C$22)+'THAM_SO_MOI'!$C$24*(E37/'THAM_SO_MOI'!$C$22)^2-'THAM_SO_MOI'!$C$25*(E37/'THAM_SO_MOI'!$C$22)^3) -> 30.974472 | K37: ='THAM_SO_MOI'!$C$31*J37/E37 -> 346.51562 | L37: =K37*'THAM_SO_MOI'!$C$53*'THAM_SO_MOI'!$C$17/'THAM_SO_MOI'!$C$26 -> 3038.9434 | M37: ='THAM_SO_MOI'!$C$15*'THAM_SO_MOI'!$C$16*F37^2 -> 219.62926 | N37: ='THAM_SO_MOI'!$C$12*I37 -> 1130.112 | O37: =M37+N37 -> 1349.7413 | P37: =(MIN(L37,'THAM_SO_MOI'!$C$41)-O37)/('THAM_SO_MOI'!$C$11*H37) -> 0.1999529 | Q37: =IF(P37>0,1/P37,NA()) -> 5.0011778 | R37: =F37-F36 -> 0.017600427 | S37: =0.5*(Q36+Q37)*R37 -> 0.088050164 | T37: =0.5*(F36*Q36+F37*Q37)*R37 -> 0.76220346 | U37: =U36+S37 -> 2.7563763 | V37: =V36+T37 -> 23.1302
A38: Số V riêng | B38: 5 | C38: kéo | D38: low | E38: =60*F38*'THAM_SO_MOI'!$C$53/(2*PI()*'THAM_SO_MOI'!$C$26) -> 855.49137 | F38: ='THAM_SO_MOI'!$E$53+('THAM_SO_MOI'!$C$14-'THAM_SO_MOI'!$E$53)*32/'THAM_SO_MOI'!$C$42 -> 8.6828718 | G38: =3.6*F38 -> 31.258338 | H38: ='THAM_SO_MOI'!$D$53 -> 1.1 | I38: =IF(F38>'THAM_SO_MOI'!$C$14,'THAM_SO_MOI'!$C$13*(1+F38^2/1500),'THAM_SO_MOI'!$C$13) -> 0.015 | J38: ='THAM_SO_MOI'!$C$40*('THAM_SO_MOI'!$C$23*(E38/'THAM_SO_MOI'!$C$22)+'THAM_SO_MOI'!$C$24*(E38/'THAM_SO_MOI'!$C$22)^2-'THAM_SO_MOI'!$C$25*(E38/'THAM_SO_MOI'!$C$22)^3) -> 31.057156 | K38: ='THAM_SO_MOI'!$C$31*J38/E38 -> 346.73635 | L38: =K38*'THAM_SO_MOI'!$C$53*'THAM_SO_MOI'!$C$17/'THAM_SO_MOI'!$C$26 -> 3040.8792 | M38: ='THAM_SO_MOI'!$C$15*'THAM_SO_MOI'!$C$16*F38^2 -> 220.52237 | N38: ='THAM_SO_MOI'!$C$12*I38 -> 1130.112 | O38: =M38+N38 -> 1350.6344 | P38: =(MIN(L38,'THAM_SO_MOI'!$C$41)-O38)/('THAM_SO_MOI'!$C$11*H38) -> 0.20007633 | Q38: =IF(P38>0,1/P38,NA()) -> 4.9980926 | R38: =F38-F37 -> 0.017600427 | S38: =0.5*(Q37+Q38)*R38 -> 0.087995716 | T38: =0.5*(F37*Q37+F38*Q38)*R38 -> 0.7632809 | U38: =U37+S38 -> 2.844372 | V38: =V37+T38 -> 23.893481
A39: Số V riêng | B39: 5 | C39: kéo | D39: low | E39: =60*F39*'THAM_SO_MOI'!$C$53/(2*PI()*'THAM_SO_MOI'!$C$26) -> 857.22547 | F39: ='THAM_SO_MOI'!$E$53+('THAM_SO_MOI'!$C$14-'THAM_SO_MOI'!$E$53)*33/'THAM_SO_MOI'!$C$42 -> 8.7004722 | G39: =3.6*F39 -> 31.3217 | H39: ='THAM_SO_MOI'!$D$53 -> 1.1 | I39: =IF(F39>'THAM_SO_MOI'!$C$14,'THAM_SO_MOI'!$C$13*(1+F39^2/1500),'THAM_SO_MOI'!$C$13) -> 0.015 | J39: ='THAM_SO_MOI'!$C$40*('THAM_SO_MOI'!$C$23*(E39/'THAM_SO_MOI'!$C$22)+'THAM_SO_MOI'!$C$24*(E39/'THAM_SO_MOI'!$C$22)^2-'THAM_SO_MOI'!$C$25*(E39/'THAM_SO_MOI'!$C$22)^3) -> 31.139895 | K39: ='THAM_SO_MOI'!$C$31*J39/E39 -> 346.95679 | L39: =K39*'THAM_SO_MOI'!$C$53*'THAM_SO_MOI'!$C$17/'THAM_SO_MOI'!$C$26 -> 3042.8124 | M39: ='THAM_SO_MOI'!$C$15*'THAM_SO_MOI'!$C$16*F39^2 -> 221.41728 | N39: ='THAM_SO_MOI'!$C$12*I39 -> 1130.112 | O39: =M39+N39 -> 1351.5293 | P39: =(MIN(L39,'THAM_SO_MOI'!$C$41)-O39)/('THAM_SO_MOI'!$C$11*H39) -> 0.20019923 | Q39: =IF(P39>0,1/P39,NA()) -> 4.9950241 | R39: =F39-F38 -> 0.017600427 | S39: =0.5*(Q38+Q39)*R39 -> 0.087941562 | T39: =0.5*(F38*Q38+F39*Q39)*R39 -> 0.76435897 | U39: =U38+S39 -> 2.9323136 | V39: =V38+T39 -> 24.65784
A40: Số V riêng | B40: 5 | C40: kéo | D40: low | E40: =60*F40*'THAM_SO_MOI'!$C$53/(2*PI()*'THAM_SO_MOI'!$C$26) -> 858.95958 | F40: ='THAM_SO_MOI'!$E$53+('THAM_SO_MOI'!$C$14-'THAM_SO_MOI'!$E$53)*34/'THAM_SO_MOI'!$C$42 -> 8.7180726 | G40: =3.6*F40 -> 31.385062 | H40: ='THAM_SO_MOI'!$D$53 -> 1.1 | I40: =IF(F40>'THAM_SO_MOI'!$C$14,'THAM_SO_MOI'!$C$13*(1+F40^2/1500),'THAM_SO_MOI'!$C$13) -> 0.015 | J40: ='THAM_SO_MOI'!$C$40*('THAM_SO_MOI'!$C$23*(E40/'THAM_SO_MOI'!$C$22)+'THAM_SO_MOI'!$C$24*(E40/'THAM_SO_MOI'!$C$22)^2-'THAM_SO_MOI'!$C$25*(E40/'THAM_SO_MOI'!$C$22)^3) -> 31.222687 | K40: ='THAM_SO_MOI'!$C$31*J40/E40 -> 347.17694 | L40: =K40*'THAM_SO_MOI'!$C$53*'THAM_SO_MOI'!$C$17/'THAM_SO_MOI'!$C$26 -> 3044.7431 | M40: ='THAM_SO_MOI'!$C$15*'THAM_SO_MOI'!$C$16*F40^2 -> 222.31401 | N40: ='THAM_SO_MOI'!$C$12*I40 -> 1130.112 | O40: =M40+N40 -> 1352.426 | P40: =(MIN(L40,'THAM_SO_MOI'!$C$41)-O40)/('THAM_SO_MOI'!$C$11*H40) -> 0.20032163 | Q40: =IF(P40>0,1/P40,NA()) -> 4.9919723 | R40: =F40-F39 -> 0.017600427 | S40: =0.5*(Q39+Q40)*R40 -> 0.087887702 | T40: =0.5*(F39*Q39+F40*Q40)*R40 -> 0.7654377 | U40: =U39+S40 -> 3.0202013 | V40: =V39+T40 -> 25.423278
A41: Số V riêng | B41: 5 | C41: kéo | D41: low | E41: =60*F41*'THAM_SO_MOI'!$C$53/(2*PI()*'THAM_SO_MOI'!$C$26) -> 860.69368 | F41: ='THAM_SO_MOI'!$E$53+('THAM_SO_MOI'!$C$14-'THAM_SO_MOI'!$E$53)*35/'THAM_SO_MOI'!$C$42 -> 8.7356731 | G41: =3.6*F41 -> 31.448423 | H41: ='THAM_SO_MOI'!$D$53 -> 1.1 | I41: =IF(F41>'THAM_SO_MOI'!$C$14,'THAM_SO_MOI'!$C$13*(1+F41^2/1500),'THAM_SO_MOI'!$C$13) -> 0.015 | J41: ='THAM_SO_MOI'!$C$40*('THAM_SO_MOI'!$C$23*(E41/'THAM_SO_MOI'!$C$22)+'THAM_SO_MOI'!$C$24*(E41/'THAM_SO_MOI'!$C$22)^2-'THAM_SO_MOI'!$C$25*(E41/'THAM_SO_MOI'!$C$22)^3) -> 31.305533 | K41: ='THAM_SO_MOI'!$C$31*J41/E41 -> 347.39679 | L41: =K41*'THAM_SO_MOI'!$C$53*'THAM_SO_MOI'!$C$17/'THAM_SO_MOI'!$C$26 -> 3046.6712 | M41: ='THAM_SO_MOI'!$C$15*'THAM_SO_MOI'!$C$16*F41^2 -> 223.21255 | N41: ='THAM_SO_MOI'!$C$12*I41 -> 1130.112 | O41: =M41+N41 -> 1353.3246 | P41: =(MIN(L41,'THAM_SO_MOI'!$C$41)-O41)/('THAM_SO_MOI'!$C$11*H41) -> 0.2004435 | Q41: =IF(P41>0,1/P41,NA()) -> 4.988937 | R41: =F41-F40 -> 0.017600427 | S41: =0.5*(Q40+Q41)*R41 -> 0.087834135 | T41: =0.5*(F40*Q40+F41*Q41)*R41 -> 0.76651709 | U41: =U40+S41 -> 3.1080354 | V41: =V40+T41 -> 26.189795
A42: Số V riêng | B42: 5 | C42: kéo | D42: low | E42: =60*F42*'THAM_SO_MOI'!$C$53/(2*PI()*'THAM_SO_MOI'!$C$26) -> 862.42779 | F42: ='THAM_SO_MOI'!$E$53+('THAM_SO_MOI'!$C$14-'THAM_SO_MOI'!$E$53)*36/'THAM_SO_MOI'!$C$42 -> 8.7532735 | G42: =3.6*F42 -> 31.511785 | H42: ='THAM_SO_MOI'!$D$53 -> 1.1 | I42: =IF(F42>'THAM_SO_MOI'!$C$14,'THAM_SO_MOI'!$C$13*(1+F42^2/1500),'THAM_SO_MOI'!$C$13) -> 0.015 | J42: ='THAM_SO_MOI'!$C$40*('THAM_SO_MOI'!$C$23*(E42/'THAM_SO_MOI'!$C$22)+'THAM_SO_MOI'!$C$24*(E42/'THAM_SO_MOI'!$C$22)^2-'THAM_SO_MOI'!$C$25*(E42/'THAM_SO_MOI'!$C$22)^3) -> 31.388432 | K42: ='THAM_SO_MOI'!$C$31*J42/E42 -> 347.61636 | L42: =K42*'THAM_SO_MOI'!$C$53*'THAM_SO_MOI'!$C$17/'THAM_SO_MOI'!$C$26 -> 3048.5968 | M42: ='THAM_SO_MOI'!$C$15*'THAM_SO_MOI'!$C$16*F42^2 -> 224.11291 | N42: ='THAM_SO_MOI'!$C$12*I42 -> 1130.112 | O42: =M42+N42 -> 1354.2249 | P42: =(MIN(L42,'THAM_SO_MOI'!$C$41)-O42)/('THAM_SO_MOI'!$C$11*H42) -> 0.20056486 | Q42: =IF(P42>0,1/P42,NA()) -> 4.9859184 | R42: =F42-F41 -> 0.017600427 | S42: =0.5*(Q41+Q42)*R42 -> 0.087780859 | T42: =0.5*(F41*Q41+F42*Q42)*R42 -> 0.76759714 | U42: =U41+S42 -> 3.1958163 | V42: =V41+T42 -> 26.957392
...

Sheet HANH_TRINH
A1: HÀNH TRÌNH LIÊN TỤC QUA NĂM TAY SỐ
A2: Giả thiết tham khảo: chuyển số ở 2.600 vòng/phút, ngắt 1 giây/lần, δcoast=1,05. t và S không đặt lại về 0 khi vào số mới. Chưa gồm khởi hành ly hợp trượt; chưa tối ưu lịch chuyển số.
A5: Pha | B5: Số | C5: Loại | D5: Nhánh f | E5: n (v/ph) | F5: v (m/s) | G5: v (km/h) | H5: δ | I5: f(v) | J5: Ne (kW) | K5: Me (N·m) | L5: Pk (N) | M5: Pw (N) | N5: Pf (N) | O5: Pc (N) | P5: j (m/s²) | Q5: 1/j (s²/m) | R5: Δv (m/s) | S5: Δt (s) | T5: ΔS (m) | U5: t tích lũy (s) | V5: S tích lũy (m) | W5: k1 (m/s²) | X5: v2 RK4 | Y5: k2 (m/s²) | Z5: v3 RK4 | AA5: k3 (m/s²) | AB5: v4 RK4 | AC5: k4 (m/s²)
A6: Kéo 1 | B6: 1 | C6: kéo | D6: low | E6: =60*F6*'THAM_SO_MOI'!$C$49/(2*PI()*'THAM_SO_MOI'!$C$26) -> 800 | F6: ='THAM_SO_MOI'!$E$49+('THAM_SO_MOI'!$F$49-'THAM_SO_MOI'!$E$49)*0/'THAM_SO_MOI'!$C$42 -> 1.2491782 | G6: =3.6*F6 -> 4.4970414 | H6: ='THAM_SO_MOI'!$D$49 -> 3.1625 | I6: =IF(F6>'THAM_SO_MOI'!$C$14,'THAM_SO_MOI'!$C$13*(1+F6^2/1500),'THAM_SO_MOI'!$C$13) -> 0.015 | J6: ='THAM_SO_MOI'!$C$40*('THAM_SO_MOI'!$C$23*(E6/'THAM_SO_MOI'!$C$22)+'THAM_SO_MOI'!$C$24*(E6/'THAM_SO_MOI'!$C$22)^2-'THAM_SO_MOI'!$C$25*(E6/'THAM_SO_MOI'!$C$22)^3) -> 28.438889 | K6: ='THAM_SO_MOI'!$C$31*J6/E6 -> 339.52828 | L6: =K6*'THAM_SO_MOI'!$C$49*'THAM_SO_MOI'!$C$17/'THAM_SO_MOI'!$C$26 -> 19354.818 | M6: ='THAM_SO_MOI'!$C$15*'THAM_SO_MOI'!$C$16*F6^2 -> 4.5643049 | N6: ='THAM_SO_MOI'!$C$12*I6 -> 1130.112 | O6: =M6+N6 -> 1134.6763 | P6: =(MIN(L6,'THAM_SO_MOI'!$C$41)-O6)/('THAM_SO_MOI'!$C$11*H6) -> 0.75017054 | Q6: =IF(P6>0,1/P6,NA()) -> 1.3330302 | R6: =0 -> 0 | S6: =0 -> 0 | T6: =0 -> 0 | U6: =S6 -> 0 | V6: =T6 -> 0
