Workbook
Name delta_1: 'Thong_so'!$E$78
Name delta_2: 'Thong_so'!$E$79
Name delta_3: 'Thong_so'!$E$80
Name delta_4: 'Thong_so'!$E$81
Name delta_5: 'Thong_so'!$E$82
Name h_1: 'Thong_so'!$B$78
Name h_2: 'Thong_so'!$B$79
Name h_3: 'Thong_so'!$B$80
Name h_4: 'Thong_so'!$B$81
Name h_5: 'Thong_so'!$B$82
Name it_1: 'Thong_so'!$D$78
Name it_2: 'Thong_so'!$D$79
Name it_3: 'Thong_so'!$D$80
Name it_4: 'Thong_so'!$D$81
Name it_5: 'Thong_so'!$D$82
Name p_a: 'Thong_so'!$C$23
Name p_b: 'Thong_so'!$C$24
Name p_c: 'Thong_so'!$C$25
Name p_coast_dt: 'Thong_so'!$C$39
Name p_delta_coast: 'Thong_so'!$C$36
Name p_distance: 'Thong_so'!$C$73
Name p_drive_intervals_per_smooth_segment: 'Thong_so'!$C$38
Name p_eta: 'Thong_so'!$C$19
Name p_f0: 'Thong_so'!$C$15
Name p_F: 'Thong_so'!$C$18
Name p_front_fraction: 'Thong_so'!$C$11
Name p_fvmax: 'Thong_so'!$C$49
Name p_G1: 'Thong_so'!$C$42
Name p_G2: 'Thong_so'!$C$43
Name p_grade_at_torque_peak_percent: 'Thong_so'!$C$71
Name p_gravity: 'Thong_so'!$C$10
Name p_i0: 'Thong_so'!$C$56
Name p_ih1: 'Thong_so'!$C$30
Name p_ih_max: 'Thong_so'!$C$62
Name p_ih_min: 'Thong_so'!$C$61
Name p_ip: 'Thong_so'!$C$29
Name p_iR: 'Thong_so'!$C$58
Name p_K: 'Thong_so'!$C$17
Name p_lambda_t: 'Thong_so'!$C$28
Name p_lambda_v: 'Thong_so'!$C$20
Name p_m0: 'Thong_so'!$C$6
Name p_M: 'Thong_so'!$C$40
Name p_mb: 'Thong_so'!$C$33
Name p_Mmax: 'Thong_so'!$C$60
Name p_nM: 'Thong_so'!$C$55
Name p_Nmax: 'Thong_so'!$C$54
Name p_nmin: 'Thong_so'!$C$22
Name p_nN: 'Thong_so'!$C$46
Name p_nshift: 'Thong_so'!$C$34
Name p_payload: 'Thong_so'!$C$7
Name p_Pcmax: 'Thong_so'!$C$52
Name p_peak_D1: 'Thong_so'!$C$70
Name p_peak_margin: 'Thong_so'!$C$68
Name p_peak_pk1: 'Thong_so'!$C$66
Name p_peak_pkR: 'Thong_so'!$C$69
Name p_peak_required: 'Thong_so'!$C$67
Name p_peak_v1: 'Thong_so'!$C$65
Name p_person_mass: 'Thong_so'!$C$9
Name p_persons: 'Thong_so'!$C$8
Name p_Pfmax: 'Thong_so'!$C$50

Sheet Huong_dan
A1: HƯỚNG DẪN SỬ DỤNG BẢNG TÍNH NHÓM 2
A4: Mục đích
A5: Bản bổ sung dùng đầu vào của Nhom2.xlsx để đồng bộ số liệu, chuẩn hóa phép đổi mômen và tính thêm gia tốc, chuyển số, thời gian/quãng đường. Excel gốc không bị sửa hoặc xuất lại; ảnh trong ô/richData của tệp gốc được giữ nguyên trong tệp gốc.
A9: Kết quả đang lưu
A10: M = 7680 kg; Nmax = 133.424118 kW. Tăng tốc từ 4.251748 đến 90.25 km/h: t = 104.015378947 s; S = 1933.367599598 m. Chưa tính xuất phát bằng ly hợp trượt; không gọi là 0–95 km/h.
A14: Chuẩn hóa so với Excel gốc
A15: Me = 60000·Ne/(2πn) thay hệ số 10000/1,047; mômen gốc cao hơn khoảng 0,0188683%. Dùng nN = 2600/0,9 và vmax = 95/3,6 chính xác, chỉ làm tròn hiển thị. Các lựa chọn 65 kg/người, f0=0,018, η=0,85, rb=0,3921125, ip=1,25 và các tỷ số hộp số được giữ.
A19: Giả thiết bổ sung
A20: δh = 1,05 + 0,05(ih·ip)²; δcoast=1,05; chuyển số ở 2340 vòng/phút; ngắt lực kéo 1 giây/lần; 4 lần chuyển; điểm kết thúc 0,95vmax. Đây là giả thiết được nêu thêm vì Excel gốc chưa có δ, gia tốc hay tích phân tăng tốc. Chưa tối ưu lịch chuyển số.
A24: Những gì Excel tự cập nhật
A25: Thong_so, Dong_co, Van_toc_Pk_D, Can_chuyen_dong và Gia_toc có công thức kèm cache. Khi Excel tính lại, các công thức có thể đổi theo đầu vào. Phần SUMIF trong Tong_hop chỉ cộng lại dữ liệu tĩnh của Tang_toc_chi_tiet.
A29: QUAN TRỌNG: khi thay đầu vào
... A75: Thong_so: nguồn và giả thiết; Dong_co: Ne/Me/Nk; Van_toc_Pk_D: 5 trục vận tốc; Can_chuyen_dong: lực/công suất cản; Gia_toc: j,1/j; Tang_toc_chi_tiet: toàn bộ 10.010 dòng; Tong_hop: 9 pha / 4 lần chuyển / kiểm tra; Do_thi: 4 đồ thị XY.
B79: Thong_so
B80: Dong_co
B81: Van_toc_Pk_D
B82: Can_chuyen_dong
B83: Gia_toc
B84: Tang_toc_chi_tiet
B85: Tong_hop
B86: Do_thi

Sheet Thong_so
A1: THÔNG SỐ VÀ CƠ SỞ TÍNH TOÁN
A2: Ô xanh nhạt: đầu vào/giả thiết. Ô xanh lá: công thức có giá trị lưu sẵn. Ô vàng nhạt: kết quả tích phân tĩnh, không tự cập nhật khi đổi đầu vào. Không dùng bản đã sửa ô Excel để thay cho chạy lại bộ tính.
A5: Mã biến | B5: Đại lượng | C5: Giá trị | D5: Đơn vị | E5: Nguồn / cách tính | F5: Phạm vi
A6: m0 | B6: Khối lượng bản thân | C6: 3450 | D6: kg | E6: THÔNG SỐ CHO TRƯỚC!E9 | F6: Đầu vào / giả thiết đã công bố
A7: payload | B7: Tải hàng định mức | C7: 4100 | D7: kg | E7: THÔNG SỐ CHO TRƯỚC!E10 | F7: Đầu vào / giả thiết đã công bố
A8: persons | B8: Số người | C8: 2 | D8: người | E8: THÔNG SỐ CHO TRƯỚC!E8 | F8: Đầu vào / giả thiết đã công bố
A9: person_mass | B9: Khối lượng mỗi người | C9: 65 | D9: kg | E9: THÔNG SỐ CHO TRƯỚC!E21 | F9: Đầu vào / giả thiết đã công bố
A10: g | B10: Gia tốc trọng trường | C10: 9.81 | D10: m/s² | E10: Hệ số 9,81 trong Excel nguồn | F10: Đầu vào / giả thiết đã công bố
A11: front_fraction | B11: Tỷ lệ tải tĩnh cầu trước | C11: 0.3 | D11: — | E11: THÔNG SỐ CHO TRƯỚC!E11 | F11: Đầu vào / giả thiết đã công bố
A12: rear_fraction | B12: Tỷ lệ tải tĩnh cầu sau | C12: 0.7 | D12: — | E12: THÔNG SỐ CHO TRƯỚC!E12 | F12: Đầu vào / giả thiết đã công bố
A13: vmax_kmh | B13: Vận tốc cực đại yêu cầu | C13: 95 | D13: km/h | E13: THÔNG SỐ CHO TRƯỚC!E13 | F13: Đầu vào / giả thiết đã công bố
A14: psi_max | B14: Hệ số cản đường lớn nhất | C14: 0.31 | D14: — | E14: THÔNG SỐ CHO TRƯỚC!E14 | F14: Đầu vào / giả thiết đã công bố
A15: f0 | B15: Hệ số cản lăn cơ sở | C15: 0.018 | D15: — | E15: THÔNG SỐ CHO TRƯỚC!E23 | F15: Đầu vào / giả thiết đã công bố
A16: threshold | B16: Ngưỡng ghép mô hình cản lăn | C16: 22.2 | D16: m/s | E16: Theo hai miền công thức Excel/Word | F16: Đầu vào / giả thiết đã công bố
A17: K | B17: Hệ số cản không khí | C17: 0.65 | D17: N·s²/m⁴ | E17: THÔNG SỐ CHO TRƯỚC!E25 | F17: Đầu vào / giả thiết đã công bố
... A39: coast_dt | B39: Bước thời gian khi chuyển số | C39: 0.01 | D39: s | E39: THIẾT LẬP TÍCH PHÂN: 0,01 | F39: Đầu vào / giả thiết đã công bố
A40: M | B40: Khối lượng toàn tải | C40: =p_m0+p_persons*p_person_mass+p_payload -> 7680 | D40: kg | E40: Tính từ đầu vào Excel | F40: Công thức; liên kết đầu vào
A41: G | B41: Trọng lượng toàn bộ | C41: =p_M*p_gravity -> 75340.8 | D41: N | E41: G=M·g | F41: Công thức; liên kết đầu vào
A42: G1 | B42: Tải tĩnh cầu trước | C42: =p_weight*p_front_fraction -> 22602.24 | D42: N | E42: G1=G·tỷ lệ trước | F42: Công thức; liên kết đầu vào
A43: G2 | B43: Tải tĩnh cầu sau | C43: =p_weight*p_rear_fraction -> 52738.56 | D43: N | E43: G2=G·tỷ lệ sau | F43: Công thức; liên kết đầu vào
A44: W | B44: Nhân tố cản không khí KF | C44: =p_K*p_F -> 2.925 | D44: N·s²/m² | E44: W=K·F | F44: Công thức; liên kết đầu vào
A45: vmax | B45: Vận tốc cực đại chính xác | C45: =p_vmax_kmh/3.6 -> 26.388889 | D45: m/s | E45: 95/3,6; không nhập lại 26,39 | F45: Công thức; liên kết đầu vào
A46: nN | B46: Vòng tua công suất cực đại | C46: =p_rpm_vmax/p_lambda_v -> 2888.8889 | D46: vòng/phút | E46: nv/lambda_v; giữ số chưa làm tròn | F46: Công thức; liên kết đầu vào
A47: r0 | B47: Bán kính hình học xấp xỉ | C47: =(p_tire_width_in+p_rim_in/2)*0.0254 -> 0.41275 | D47: m | E47: (B+d/2)·0,0254 | F47: Công thức; liên kết đầu vào
A48: rb | B48: Bán kính lăn giả thiết | C48: =p_lambda_t*p_r0 -> 0.3921125 | D48: m | E48: lambda_t·r0; không phải bán kính tĩnh catalogue | F48: Công thức; liên kết đầu vào
A49: fvmax | B49: Hệ số cản lăn tại vmax | C49: =IF(p_vmax<=p_threshold,p_f0,p_f0*(1+p_vmax^2/1500)) -> 0.026356481 | D49: — | E49: Theo luật ghép | F49: Công thức; liên kết đầu vào
A50: Pfmax | B50: Cản lăn tại vmax | C50: =p_weight*p_fvmax -> 1985.7184 | D50: N | E50: G·f(vmax) | F50: Công thức; liên kết đầu vào
A51: Pwmax | B51: Cản không khí tại vmax | C51: =p_W*p_vmax^2 -> 2036.8924 | D51: N | E51: W·vmax² | F51: Công thức; liên kết đầu vào
A52: Pcmax | B52: Tổng cản tại vmax | C52: =p_Pfmax+p_Pwmax -> 4022.6108 | D52: N | E52: Pf+Pw | F52: Công thức; liên kết đầu vào
A53: Nv | B53: Công suất động cơ tại vmax | C53: =p_Pcmax*p_vmax/(1000*p_eta) -> 124.88497 | D53: kW | E53: Pc·vmax/(1000·eta) | F53: Công thức; liên kết đầu vào
A54: Nmax | B54: Tham số công suất cực đại động cơ | C54: =p_power_vmax/(p_a*p_lambda_v+p_b*p_lambda_v^2-p_c*p_lambda_v^3) -> 133.42412 | D54: kW | E54: Nv/(aλ+bλ²−cλ³) | F54: Công thức; liên kết đầu vào
A55: nM | B55: Vòng tua mômen cực đại | C55: =p_b*p_nN/(2*p_c) -> 2166.6667 | D55: vòng/phút | E55: b·nN/(2c) | F55: Công thức; liên kết đầu vào
A56: i0 | B56: Tỷ số truyền lực chính | C56: =2*PI()*p_rb*p_rpm_vmax/(60*p_top*p_ip*p_vmax) -> 4.0456802 | D56: — | E56: Điều kiện đạt vmax ở số V | F56: Công thức; liên kết đầu vào
A57: q | B57: Công bội số I–IV | C57: =p_ih1^(1/3) -> 1.7651742 | D57: — | E57: (ih1/1)^(1/3) | F57: Công thức; liên kết đầu vào
A58: iR | B58: Tỷ số truyền số lùi | C58: =1.2*p_ih1 -> 6.6 | D58: — | E58: GIẢ THIẾT BỔ SUNG: 1,2·ih1 | F58: Công thức; liên kết đầu vào
A59: Pphi | B59: Giới hạn bám tĩnh | C59: =p_phi*p_mb*p_G2 -> 39553.92 | D59: N | E59: phi·mb·G2 | F59: Công thức; liên kết đầu vào
A60: Mmax | B60: Mômen cực đại chuẩn hóa | C60: =60000/(2*PI())*p_Nmax/p_nN*(p_a+p_b*(p_nM/p_nN)-p_c*(p_nM/p_nN)^2) -> 468.60166 | D60: N·m | E60: Hệ số chuẩn 60000/(2π) | F60: Công thức; liên kết đầu vào
A61: ih_min | B61: Cận số I theo sức cản (bỏ Pw) | C61: =p_psi_max*p_weight*p_rb/(p_Mmax*p_i0*p_ip*p_eta) -> 4.5465115 | D61: — | E61: psi_max·G·rb/(Mmax·i0·ip·eta) | F61: Công thức; liên kết đầu vào
A62: ih_max | B62: Cận số I theo bám | C62: =p_Pphi*p_rb/(p_Mmax*p_i0*p_ip*p_eta) -> 7.6997373 | D62: — | E62: Pphi·rb/(Mmax·i0·ip·eta) | F62: Công thức; liên kết đầu vào
A63: vstart | B63: Vận tốc bắt đầu tích phân | C63: =2*PI()*p_nmin*p_rb/(60*p_i0*p_ih1*p_ip) -> 1.1810412 | D63: m/s | E63: Số I, nmin; chưa xét trượt ly hợp | F63: Công thức; liên kết đầu vào
...

Sheet Dong_co
A1: ĐẶC TÍNH NGOÀI ĐỘNG CƠ — CÔNG THỨC CHUẨN
A2: Ne tính kW; Me = 60000·Ne/(2πn), N·m. Điểm nM, nv và nN dùng số chưa làm tròn. Công thức có cache để đọc ngay cả khi ứng dụng chưa tính lại.
A5: n, vòng/phút | B5: x = n/nN | C5: Ne, kW | D5: Me, N·m | E5: Nk, kW | F5: Điểm / ý nghĩa
A6: 800 | B6: =A6/p_nN -> 0.27692308 | C6: =p_Nmax*(p_a*B6+p_b*B6^2-p_c*B6^3) -> 30.988404 | D6: =60000*C6/(2*PI()*A6) -> 369.89683 | E6: =p_eta*C6 -> 26.340144 | F6: Điểm khảo sát
A7: 1200 | B7: =A7/p_nN -> 0.41538462 | C7: =p_Nmax*(p_a*B7+p_b*B7^2-p_c*B7^3) -> 52.680725 | D7: =60000*C7/(2*PI()*A7) -> 419.21989 | E7: =p_eta*C7 -> 44.778616 | F7: Điểm khảo sát
A8: 1600 | B8: =A8/p_nN -> 0.55384615 | C8: =p_Nmax*(p_a*B8+p_b*B8^2-p_c*B8^3) -> 75.671698 | D8: =60000*C8/(2*PI()*A8) -> 451.63218 | E8: =p_eta*C8 -> 64.320943 | F8: Điểm khảo sát
A9: 2000 | B9: =A9/p_nN -> 0.69230769 | C9: =p_Nmax*(p_a*B9+p_b*B9^2-p_c*B9^3) -> 97.836256 | D9: =60000*C9/(2*PI()*A9) -> 467.13371 | E9: =p_eta*C9 -> 83.160818 | F9: Điểm khảo sát
A10: =p_nM -> 2166.6667 | B10: =A10/p_nN -> 0.75 | C10: =p_Nmax*(p_a*B10+p_b*B10^2-p_c*B10^3) -> 106.32234 | D10: =60000*C10/(2*PI()*A10) -> 468.60166 | E10: =p_eta*C10 -> 90.373993 | F10: Mômen cực đại giải tích
A11: 2400 | B11: =A11/p_nN -> 0.83076923 | C11: =p_Nmax*(p_a*B11+p_b*B11^2-p_c*B11^3) -> 117.04933 | D11: =60000*C11/(2*PI()*A11) -> 465.72448 | E11: =p_eta*C11 -> 99.49193 | F11: Điểm khảo sát
A12: =p_rpm_vmax -> 2600 | B12: =A12/p_nN -> 0.9 | C12: =p_Nmax*(p_a*B12+p_b*B12^2-p_c*B12^3) -> 124.88497 | D12: =60000*C12/(2*PI()*A12) -> 458.67833 | E12: =p_eta*C12 -> 106.15223 | F12: Điểm đạt 95 km/h ở số V
A13: =p_nN -> 2888.8889 | B13: =A13/p_nN -> 1 | C13: =p_Nmax*(p_a*B13+p_b*B13^2-p_c*B13^3) -> 133.42412 | D13: =60000*C13/(2*PI()*A13) -> 441.03686 | E13: =p_eta*C13 -> 113.4105 | F13: Vòng tua định mức chính xác

Sheet Van_toc_Pk_D
A1: VẬN TỐC, LỰC KÉO VÀ NHÂN TỐ ĐỘNG LỰC HỌC
A2: Mỗi dòng có cùng n, nhưng mỗi tay số có v riêng. Khi vẽ XY: số I dùng cột vI riêng, số II dùng vII riêng… Không dùng một cột v chung cho cả năm đường Pk hoặc D.
A4: n, vòng/phút | B4: SỐ 1 | G4: SỐ 2 | L4: SỐ 3 | Q4: SỐ 4 | V4: SỐ 5
B5: v, m/s | C5: v, km/h | D5: Pk, N | E5: D | F5: Dφ tại v của số này | G5: v, m/s | H5: v, km/h | I5: Pk, N | J5: D | K5: Dφ tại v của số này | L5: v, m/s | M5: v, km/h | N5: Pk, N | O5: D | P5: Dφ tại v của số này | Q5: v, m/s | R5: v, km/h | S5: Pk, N | T5: D | U5: Dφ tại v của số này | V5: v, m/s | W5: v, km/h | X5: Pk, N | Y5: D | Z5: Dφ tại v của số này
A6: ='Dong_co'!A6 -> 800 | B6: =2*PI()*$A6*p_rb/(60*it_1) -> 1.1810412 | C6: =3.6*B6 -> 4.2517483 | D6: ='Dong_co'!D6*it_1*p_eta/p_rb -> 22302.477 | E6: =(D6-p_W*B6^2)/p_weight -> 0.29596708 | F6: =(p_Pphi-p_W*B6^2)/p_weight -> 0.52494585 | G6: =2*PI()*$A6*p_rb/(60*it_2) -> 2.0847434 | H6: =3.6*G6 -> 7.5050762 | I6: ='Dong_co'!D6*it_2*p_eta/p_rb -> 12634.717 | J6: =(I6-p_W*G6^2)/p_weight -> 0.16753213 | K6: =(p_Pphi-p_W*G6^2)/p_weight -> 0.52483127 | L6: =2*PI()*$A6*p_rb/(60*it_3) -> 3.6799352 | M6: =3.6*L6 -> 13.247767 | N6: ='Dong_co'!D6*it_3*p_eta/p_rb -> 7157.7738 | O6: =(N6-p_W*L6^2)/p_weight -> 0.094479534 | P6: =(p_Pphi-p_W*L6^2)/p_weight -> 0.52447425 | Q6: =2*PI()*$A6*p_rb/(60*it_4) -> 6.4957265 | R6: =3.6*Q6 -> 23.384615 | S6: ='Dong_co'!D6*it_4*p_eta/p_rb -> 4054.9958 | T6: =(S6-p_W*Q6^2)/p_weight -> 0.052183903 | U6: =(p_Pphi-p_W*Q6^2)/p_weight -> 0.52336186 | V6: =2*PI()*$A6*p_rb/(60*it_5) -> 8.1196581 | W6: =3.6*V6 -> 29.230769 | X6: ='Dong_co'!D6*it_5*p_eta/p_rb -> 3243.9966 | Y6: =(X6-p_W*V6^2)/p_weight -> 0.04049804 | Z6: =(p_Pphi-p_W*V6^2)/p_weight -> 0.52244041
A7: ='Dong_co'!A7 -> 1200 | B7: =2*PI()*$A7*p_rb/(60*it_1) -> 1.7715618 | C7: =3.6*B7 -> 6.3776224 | D7: ='Dong_co'!D7*it_1*p_eta/p_rb -> 25276.35 | E7: =(D7-p_W*B7^2)/p_weight -> 0.33537168 | F7: =(p_Pphi-p_W*B7^2)/p_weight -> 0.52487815 | G7: =2*PI()*$A7*p_rb/(60*it_2) -> 3.1271151 | H7: =3.6*G7 -> 11.257614 | I7: ='Dong_co'!D7*it_2*p_eta/p_rb -> 14319.465 | J7: =(I7-p_W*G7^2)/p_weight -> 0.18968291 | K7: =(p_Pphi-p_W*G7^2)/p_weight -> 0.52462035 | L7: =2*PI()*$A7*p_rb/(60*it_3) -> 5.5199028 | M7: =3.6*L7 -> 19.87165 | N7: ='Dong_co'!D7*it_3*p_eta/p_rb -> 8112.211 | O7: =(N7-p_W*L7^2)/p_weight -> 0.10649062 | P7: =(p_Pphi-p_W*L7^2)/p_weight -> 0.52381707 | Q7: =2*PI()*$A7*p_rb/(60*it_4) -> 9.7435897 | R7: =3.6*Q7 -> 35.076923 | S7: ='Dong_co'!D7*it_4*p_eta/p_rb -> 4595.7001 | T7: =(S7-p_W*Q7^2)/p_weight -> 0.057313006 | U7: =(p_Pphi-p_W*Q7^2)/p_weight -> 0.52131418 | V7: =2*PI()*$A7*p_rb/(60*it_5) -> 12.179487 | W7: =3.6*V7 -> 43.846154 | X7: ='Dong_co'!D7*it_5*p_eta/p_rb -> 3676.56 | Y7: =(X7-p_W*V7^2)/p_weight -> 0.04303997 | Z7: =(p_Pphi-p_W*V7^2)/p_weight -> 0.51924091
A8: ='Dong_co'!A8 -> 1600 | B8: =2*PI()*$A8*p_rb/(60*it_1) -> 2.3620824 | C8: =3.6*B8 -> 8.5034965 | D8: ='Dong_co'!D8*it_1*p_eta/p_rb -> 27230.61 | E8: =(D8-p_W*B8^2)/p_weight -> 0.36121584 | F8: =(p_Pphi-p_W*B8^2)/p_weight -> 0.52478339 | G8: =2*PI()*$A8*p_rb/(60*it_2) -> 4.1694868 | H8: =3.6*G8 -> 15.010152 | I8: ='Dong_co'!D8*it_2*p_eta/p_rb -> 15426.585 | J8: =(I8-p_W*G8^2)/p_weight -> 0.20408245 | K8: =(p_Pphi-p_W*G8^2)/p_weight -> 0.52432507 | L8: =2*PI()*$A8*p_rb/(60*it_3) -> 7.3598703 | M8: =3.6*L8 -> 26.495533 | N8: ='Dong_co'!D8*it_3*p_eta/p_rb -> 8739.4126 | O8: =(N8-p_W*L8^2)/p_weight -> 0.11389542 | P8: =(p_Pphi-p_W*L8^2)/p_weight -> 0.52289702 | Q8: =2*PI()*$A8*p_rb/(60*it_4) -> 12.991453 | R8: =3.6*Q8 -> 46.769231 | S8: ='Dong_co'!D8*it_4*p_eta/p_rb -> 4951.02 | T8: =(S8-p_W*Q8^2)/p_weight -> 0.05916243 | U8: =(p_Pphi-p_W*Q8^2)/p_weight -> 0.51844744 | V8: =2*PI()*$A8*p_rb/(60*it_5) -> 16.239316 | W8: =3.6*V8 -> 58.461538 | X8: ='Dong_co'!D8*it_5*p_eta/p_rb -> 3960.816 | Y8: =(X8-p_W*V8^2)/p_weight -> 0.042333616 | Z8: =(p_Pphi-p_W*V8^2)/p_weight -> 0.51476162
A9: ='Dong_co'!A9 -> 2000 | B9: =2*PI()*$A9*p_rb/(60*it_1) -> 2.952603 | C9: =3.6*B9 -> 10.629371 | D9: ='Dong_co'!D9*it_1*p_eta/p_rb -> 28165.256 | E9: =(D9-p_W*B9^2)/p_weight -> 0.37349957 | F9: =(p_Pphi-p_W*B9^2)/p_weight -> 0.52466154 | G9: =2*PI()*$A9*p_rb/(60*it_2) -> 5.2118585 | H9: =3.6*G9 -> 18.76269 | I9: ='Dong_co'!D9*it_2*p_eta/p_rb -> 15956.078 | J9: =(I9-p_W*G9^2)/p_weight -> 0.21073076 | K9: =(p_Pphi-p_W*G9^2)/p_weight -> 0.52394542 | L9: =2*PI()*$A9*p_rb/(60*it_3) -> 9.1998379 | M9: =3.6*L9 -> 33.119417 | N9: ='Dong_co'!D9*it_3*p_eta/p_rb -> 9039.3786 | O9: =(N9-p_W*L9^2)/p_weight -> 0.11669395 | P9: =(p_Pphi-p_W*L9^2)/p_weight -> 0.52171409 | Q9: =2*PI()*$A9*p_rb/(60*it_4) -> 16.239316 | R9: =3.6*Q9 -> 58.461538 | S9: ='Dong_co'!D9*it_4*p_eta/p_rb -> 5120.9556 | T9: =(S9-p_W*Q9^2)/p_weight -> 0.057732173 | U9: =(p_Pphi-p_W*Q9^2)/p_weight -> 0.51476162 | V9: =2*PI()*$A9*p_rb/(60*it_5) -> 20.299145 | W9: =3.6*V9 -> 73.076923 | X9: ='Dong_co'!D9*it_5*p_eta/p_rb -> 4096.7645 | Y9: =(X9-p_W*V9^2)/p_weight -> 0.038378976 | Z9: =(p_Pphi-p_W*V9^2)/p_weight -> 0.50900254
A10: ='Dong_co'!A10 -> 2166.6667 | B10: =2*PI()*$A10*p_rb/(60*it_1) -> 3.1986532 | C10: =3.6*B10 -> 11.515152 | D10: ='Dong_co'!D10*it_1*p_eta/p_rb -> 28253.764 | E10: =(D10-p_W*B10^2)/p_weight -> 0.37461558 | F10: =(p_Pphi-p_W*B10^2)/p_weight -> 0.52460278 | G10: =2*PI()*$A10*p_rb/(60*it_2) -> 5.64618 | H10: =3.6*G10 -> 20.326248 | I10: ='Dong_co'!D10*it_2*p_eta/p_rb -> 16006.219 | J10: =(I10-p_W*G10^2)/p_weight -> 0.2112132 | K10: =(p_Pphi-p_W*G10^2)/p_weight -> 0.52376233 | L10: =2*PI()*$A10*p_rb/(60*it_3) -> 9.9664911 | M10: =3.6*L10 -> 35.879368 | N10: ='Dong_co'!D10*it_3*p_eta/p_rb -> 9067.7844 | O10: =(N10-p_W*L10^2)/p_weight -> 0.11650051 | P10: =(p_Pphi-p_W*L10^2)/p_weight -> 0.52114362 | Q10: =2*PI()*$A10*p_rb/(60*it_4) -> 17.592593 | R10: =3.6*Q10 -> 63.333333 | S10: ='Dong_co'!D10*it_4*p_eta/p_rb -> 5137.048 | T10: =(S10-p_W*Q10^2)/p_weight -> 0.056168271 | U10: =(p_Pphi-p_W*Q10^2)/p_weight -> 0.51298413 | V10: =2*PI()*$A10*p_rb/(60*it_5) -> 21.990741 | W10: =3.6*V10 -> 79.166667 | X10: ='Dong_co'!D10*it_5*p_eta/p_rb -> 4109.6384 | Y10: =(X10-p_W*V10^2)/p_weight -> 0.035772514 | Z10: =(p_Pphi-p_W*V10^2)/p_weight -> 0.5062252
A11: ='Dong_co'!A11 -> 2400 | B11: =2*PI()*$A11*p_rb/(60*it_1) -> 3.5431235 | C11: =3.6*B11 -> 12.755245 | D11: ='Dong_co'!D11*it_1*p_eta/p_rb -> 28080.288 | E11: =(D11-p_W*B11^2)/p_weight -> 0.37222286 | F11: =(p_Pphi-p_W*B11^2)/p_weight -> 0.52451262 | G11: =2*PI()*$A11*p_rb/(60*it_2) -> 6.2542302 | H11: =3.6*G11 -> 22.515229 | I11: ='Dong_co'!D11*it_2*p_eta/p_rb -> 15907.942 | J11: =(I11-p_W*G11^2)/p_weight -> 0.20962784 | K11: =(p_Pphi-p_W*G11^2)/p_weight -> 0.5234814 | L11: =2*PI()*$A11*p_rb/(60*it_3) -> 11.039806 | M11: =3.6*L11 -> 39.7433 | N11: ='Dong_co'!D11*it_3*p_eta/p_rb -> 9012.1089 | O11: =(N11-p_W*L11^2)/p_weight -> 0.11488619 | P11: =(p_Pphi-p_W*L11^2)/p_weight -> 0.52026829 | Q11: =2*PI()*$A11*p_rb/(60*it_4) -> 19.487179 | R11: =3.6*Q11 -> 70.153846 | S11: ='Dong_co'!D11*it_4*p_eta/p_rb -> 5105.5069 | T11: =(S11-p_W*Q11^2)/p_weight -> 0.053022236 | U11: =(p_Pphi-p_W*Q11^2)/p_weight -> 0.51025674 | V11: =2*PI()*$A11*p_rb/(60*it_5) -> 24.358974 | W11: =3.6*V11 -> 87.692308 | X11: ='Dong_co'!D11*it_5*p_eta/p_rb -> 4084.4055 | Y11: =(X11-p_W*V11^2)/p_weight -> 0.031176051 | Z11: =(p_Pphi-p_W*V11^2)/p_weight -> 0.50196365
A12: ='Dong_co'!A12 -> 2600 | B12: =2*PI()*$A12*p_rb/(60*it_1) -> 3.8383838 | C12: =3.6*B12 -> 13.818182 | D12: ='Dong_co'!D12*it_1*p_eta/p_rb -> 27655.449 | E12: =(D12-p_W*B12^2)/p_weight -> 0.36649935 | F12: =(p_Pphi-p_W*B12^2)/p_weight -> 0.524428 | G12: =2*PI()*$A12*p_rb/(60*it_2) -> 6.775416 | H12: =3.6*G12 -> 24.391498 | I12: ='Dong_co'!D12*it_2*p_eta/p_rb -> 15667.264 | J12: =(I12-p_W*G12^2)/p_weight -> 0.20616967 | K12: =(p_Pphi-p_W*G12^2)/p_weight -> 0.52321775 | L12: =2*PI()*$A12*p_rb/(60*it_3) -> 11.959789 | M12: =3.6*L12 -> 43.055241 | N12: ='Dong_co'!D12*it_3*p_eta/p_rb -> 8875.7608 | O12: =(N12-p_W*L12^2)/p_weight -> 0.11225496 | P12: =(p_Pphi-p_W*L12^2)/p_weight -> 0.51944681 | Q12: =2*PI()*$A12*p_rb/(60*it_4) -> 21.111111 | R12: =3.6*Q12 -> 76 | S12: ='Dong_co'!D12*it_4*p_eta/p_rb -> 5028.2635 | T12: =(S12-p_W*Q12^2)/p_weight -> 0.049437388 | U12: =(p_Pphi-p_W*Q12^2)/p_weight -> 0.50769714 | V12: =2*PI()*$A12*p_rb/(60*it_5) -> 26.388889 | W12: =3.6*V12 -> 95 | X12: ='Dong_co'!D12*it_5*p_eta/p_rb -> 4022.6108 | Y12: =(X12-p_W*V12^2)/p_weight -> 0.026356481 | Z12: =(p_Pphi-p_W*V12^2)/p_weight -> 0.49796429
A13: ='Dong_co'!A13 -> 2888.8889 | B13: =2*PI()*$A13*p_rb/(60*it_1) -> 4.2648709 | C13: =3.6*B13 -> 15.353535 | D13: ='Dong_co'!D13*it_1*p_eta/p_rb -> 26591.778 | E13: =(D13-p_W*B13^2)/p_weight -> 0.35224705 | F13: =(p_Pphi-p_W*B13^2)/p_weight -> 0.52429383 | G13: =2*PI()*$A13*p_rb/(60*it_2) -> 7.52824 | H13: =3.6*G13 -> 27.101664 | I13: ='Dong_co'!D13*it_2*p_eta/p_rb -> 15064.677 | J13: =(I13-p_W*G13^2)/p_weight -> 0.19775346 | K13: =(p_Pphi-p_W*G13^2)/p_weight -> 0.5227997 | L13: =2*PI()*$A13*p_rb/(60*it_3) -> 13.288655 | M13: =3.6*L13 -> 47.839157 | N13: ='Dong_co'!D13*it_3*p_eta/p_rb -> 8534.3853 | O13: =(N13-p_W*L13^2)/p_weight -> 0.10642128 | P13: =(p_Pphi-p_W*L13^2)/p_weight -> 0.51814421 | Q13: =2*PI()*$A13*p_rb/(60*it_4) -> 23.45679 | R13: =3.6*Q13 -> 84.444444 | S13: ='Dong_co'!D13*it_4*p_eta/p_rb -> 4834.8687 | T13: =(S13-p_W*Q13^2)/p_weight -> 0.04281176 | U13: =(p_Pphi-p_W*Q13^2)/p_weight -> 0.50363845 | V13: =2*PI()*$A13*p_rb/(60*it_5) -> 29.320988 | W13: =3.6*V13 -> 105.55556 | X13: ='Dong_co'!D13*it_5*p_eta/p_rb -> 3867.895 | Y13: =(X13-p_W*V13^2)/p_weight -> 0.017961225 | Z13: =(p_Pphi-p_W*V13^2)/p_weight -> 0.49162257

Sheet Can_chuyen_dong
A1: LỰC CẢN, CÔNG SUẤT CẢN VÀ GIỚI HẠN BÁM
A2: Hai dòng 22,200− và 22,200+ là giới hạn hai phía của mô hình f(v). Không nội suy cản lăn qua bước nhảy. vmax và vận tốc kết thúc dùng giá trị chính xác, chỉ làm tròn khi hiển thị.
A5: Vị trí / nhãn | B5: v, m/s | C5: v, km/h | D5: f(v) | E5: Pf, N | F5: Pw, N | G5: Pc, N | H5: Pφ, N | I5: Dφ | J5: Nf, kW | K5: Nw, kW | L5: Nc, kW
B6: 0 | C6: =3.6*B6 -> 0 | D6: =IF(B6<=p_threshold,p_f0,p_f0*(1+B6^2/1500)) -> 0.018 | E6: =p_weight*D6 -> 1356.1344 | F6: =p_W*B6^2 -> 0 | G6: =E6+F6 -> 1356.1344 | H6: =p_Pphi -> 39553.92 | I6: =(H6-F6)/p_weight -> 0.525 | J6: =E6*B6/1000 -> 0 | K6: =F6*B6/1000 -> 0 | L6: =J6+K6 -> 0
B7: 5 | C7: =3.6*B7 -> 18 | D7: =IF(B7<=p_threshold,p_f0,p_f0*(1+B7^2/1500)) -> 0.018 | E7: =p_weight*D7 -> 1356.1344 | F7: =p_W*B7^2 -> 73.125 | G7: =E7+F7 -> 1429.2594 | H7: =p_Pphi -> 39553.92 | I7: =(H7-F7)/p_weight -> 0.52402941 | J7: =E7*B7/1000 -> 6.780672 | K7: =F7*B7/1000 -> 0.365625 | L7: =J7+K7 -> 7.146297
B8: 10 | C8: =3.6*B8 -> 36 | D8: =IF(B8<=p_threshold,p_f0,p_f0*(1+B8^2/1500)) -> 0.018 | E8: =p_weight*D8 -> 1356.1344 | F8: =p_W*B8^2 -> 292.5 | G8: =E8+F8 -> 1648.6344 | H8: =p_Pphi -> 39553.92 | I8: =(H8-F8)/p_weight -> 0.52111764 | J8: =E8*B8/1000 -> 13.561344 | K8: =F8*B8/1000 -> 2.925 | L8: =J8+K8 -> 16.486344
B9: 15 | C9: =3.6*B9 -> 54 | D9: =IF(B9<=p_threshold,p_f0,p_f0*(1+B9^2/1500)) -> 0.018 | E9: =p_weight*D9 -> 1356.1344 | F9: =p_W*B9^2 -> 658.125 | G9: =E9+F9 -> 2014.2594 | H9: =p_Pphi -> 39553.92 | I9: =(H9-F9)/p_weight -> 0.51626469 | J9: =E9*B9/1000 -> 20.342016 | K9: =F9*B9/1000 -> 9.871875 | L9: =J9+K9 -> 30.213891
B10: 20 | C10: =3.6*B10 -> 72 | D10: =IF(B10<=p_threshold,p_f0,p_f0*(1+B10^2/1500)) -> 0.018 | E10: =p_weight*D10 -> 1356.1344 | F10: =p_W*B10^2 -> 1170 | G10: =E10+F10 -> 2526.1344 | H10: =p_Pphi -> 39553.92 | I10: =(H10-F10)/p_weight -> 0.50947057 | J10: =E10*B10/1000 -> 27.122688 | K10: =F10*B10/1000 -> 23.4 | L10: =J10+K10 -> 50.522688
A11: 22,200− | B11: =p_threshold -> 22.2 | C11: =3.6*B11 -> 79.92 | D11: =IF(B11<=p_threshold,p_f0,p_f0*(1+B11^2/1500)) -> 0.018 | E11: =p_weight*D11 -> 1356.1344 | F11: =p_W*B11^2 -> 1441.557 | G11: =E11+F11 -> 2797.6914 | H11: =p_Pphi -> 39553.92 | I11: =(H11-F11)/p_weight -> 0.50586618 | J11: =E11*B11/1000 -> 30.106184 | K11: =F11*B11/1000 -> 32.002565 | L11: =J11+K11 -> 62.108749
A12: 22,200+ | B12: =p_threshold -> 22.2 | C12: =3.6*B12 -> 79.92 | D12: =p_f0*(1+B12^2/1500) -> 0.02391408 | E12: =p_weight*D12 -> 1801.7059 | F12: =p_W*B12^2 -> 1441.557 | G12: =E12+F12 -> 3243.2629 | H12: =p_Pphi -> 39553.92 | I12: =(H12-F12)/p_weight -> 0.50586618 | J12: =E12*B12/1000 -> 39.997871 | K12: =F12*B12/1000 -> 32.002565 | L12: =J12+K12 -> 72.000437
B13: 24 | C13: =3.6*B13 -> 86.4 | D13: =IF(B13<=p_threshold,p_f0,p_f0*(1+B13^2/1500)) -> 0.024912 | E13: =p_weight*D13 -> 1876.89 | F13: =p_W*B13^2 -> 1684.8 | G13: =E13+F13 -> 3561.69 | H13: =p_Pphi -> 39553.92 | I13: =(H13-F13)/p_weight -> 0.50263761 | J13: =E13*B13/1000 -> 45.04536 | K13: =F13*B13/1000 -> 40.4352 | L13: =J13+K13 -> 85.48056
A14: v kết thúc | B14: =p_target -> 25.069444 | C14: =3.6*B14 -> 90.25 | D14: =IF(B14<=p_threshold,p_f0,p_f0*(1+B14^2/1500)) -> 0.025541725 | E14: =p_weight*D14 -> 1924.334 | F14: =p_W*B14^2 -> 1838.2954 | G14: =E14+F14 -> 3762.6293 | H14: =p_Pphi -> 39553.92 | I14: =(H14-F14)/p_weight -> 0.50060027 | J14: =E14*B14/1000 -> 48.241983 | K14: =F14*B14/1000 -> 46.085043 | L14: =J14+K14 -> 94.327027
A15: vmax | B15: =p_vmax -> 26.388889 | C15: =3.6*B15 -> 95 | D15: =IF(B15<=p_threshold,p_f0,p_f0*(1+B15^2/1500)) -> 0.026356481 | E15: =p_weight*D15 -> 1985.7184 | F15: =p_W*B15^2 -> 2036.8924 | G15: =E15+F15 -> 4022.6108 | H15: =p_Pphi -> 39553.92 | I15: =(H15-F15)/p_weight -> 0.49796429 | J15: =E15*B15/1000 -> 52.400902 | K15: =F15*B15/1000 -> 53.751326 | L15: =J15+K15 -> 106.15223

Sheet Gia_toc
A1: GIA TỐC VÀ GIA TỐC NGƯỢC THEO TỪNG TAY SỐ
A2: δh = 1,05 + 0,05(ih·ip)² là giả thiết bổ sung. Chỉ tích phân 1/j trong miền j>0; ∞ là điểm j=0, dấu — là j<0. Những điểm ngoài khả năng tăng tốc vẫn được giữ để đọc đặc tính.
A5: SỐ 1
A6: n, vòng/phút | B6: v, m/s | C6: v, km/h | D6: f(v) | E6: δh | F6: Pk, N | G6: Pc, N | H6: j, m/s² | I6: 1/j, s²/m | J6: Miền
A7: ='Dong_co'!A6 -> 800 | B7: ='Van_toc_Pk_D'!B6 -> 1.1810412 | C7: =3.6*B7 -> 4.2517483 | D7: =IF(B7<=p_threshold,p_f0,p_f0*(1+B7^2/1500)) -> 0.018 | E7: =delta_1 -> 3.4132812 | F7: ='Van_toc_Pk_D'!D6 -> 22302.477 | G7: =p_weight*D7+p_W*B7^2 -> 1360.2144 | H7: =IF(ABS((MIN(F7,p_Pphi)-G7)/(p_M*E7))<1E-10,0,(MIN(F7,p_Pphi)-G7)/(p_M*E7)) -> 0.79889611 | I7: =IF(H7>1E-10,1/H7,IF(ABS(H7)<=1E-10,"∞","—")) -> 1.2517272 | J7: =IF(H7>1E-10,"j > 0",IF(ABS(H7)<=1E-10,"Cân bằng","j < 0")) -> j > 0
A8: ='Dong_co'!A7 -> 1200 | B8: ='Van_toc_Pk_D'!B7 -> 1.7715618 | C8: =3.6*B8 -> 6.3776224 | D8: =IF(B8<=p_threshold,p_f0,p_f0*(1+B8^2/1500)) -> 0.018 | E8: =delta_1 -> 3.4132812 | F8: ='Van_toc_Pk_D'!D7 -> 25276.35 | G8: =p_weight*D8+p_W*B8^2 -> 1365.3143 | H8: =IF(ABS((MIN(F8,p_Pphi)-G8)/(p_M*E8))<1E-10,0,(MIN(F8,p_Pphi)-G8)/(p_M*E8)) -> 0.91214755 | I8: =IF(H8>1E-10,1/H8,IF(ABS(H8)<=1E-10,"∞","—")) -> 1.0963139 | J8: =IF(H8>1E-10,"j > 0",IF(ABS(H8)<=1E-10,"Cân bằng","j < 0")) -> j > 0
A9: ='Dong_co'!A8 -> 1600 | B9: ='Van_toc_Pk_D'!B8 -> 2.3620824 | C9: =3.6*B9 -> 8.5034965 | D9: =IF(B9<=p_threshold,p_f0,p_f0*(1+B9^2/1500)) -> 0.018 | E9: =delta_1 -> 3.4132812 | F9: ='Van_toc_Pk_D'!D8 -> 27230.61 | G9: =p_weight*D9+p_W*B9^2 -> 1372.4542 | H9: =IF(ABS((MIN(F9,p_Pphi)-G9)/(p_M*E9))<1E-10,0,(MIN(F9,p_Pphi)-G9)/(p_M*E9)) -> 0.98642541 | I9: =IF(H9>1E-10,1/H9,IF(ABS(H9)<=1E-10,"∞","—")) -> 1.0137614 | J9: =IF(H9>1E-10,"j > 0",IF(ABS(H9)<=1E-10,"Cân bằng","j < 0")) -> j > 0
A10: ='Dong_co'!A9 -> 2000 | B10: ='Van_toc_Pk_D'!B9 -> 2.952603 | C10: =3.6*B10 -> 10.629371 | D10: =IF(B10<=p_threshold,p_f0,p_f0*(1+B10^2/1500)) -> 0.018 | E10: =delta_1 -> 3.4132812 | F10: ='Van_toc_Pk_D'!D9 -> 28165.256 | G10: =p_weight*D10+p_W*B10^2 -> 1381.6342 | H10: =IF(ABS((MIN(F10,p_Pphi)-G10)/(p_M*E10))<1E-10,0,(MIN(F10,p_Pphi)-G10)/(p_M*E10)) -> 1.0217297 | I10: =IF(H10>1E-10,1/H10,IF(ABS(H10)<=1E-10,"∞","—")) -> 0.97873246 | J10: =IF(H10>1E-10,"j > 0",IF(ABS(H10)<=1E-10,"Cân bằng","j < 0")) -> j > 0
A11: ='Dong_co'!A10 -> 2166.6667 | B11: ='Van_toc_Pk_D'!B10 -> 3.1986532 | C11: =3.6*B11 -> 11.515152 | D11: =IF(B11<=p_threshold,p_f0,p_f0*(1+B11^2/1500)) -> 0.018 | E11: =delta_1 -> 3.4132812 | F11: ='Van_toc_Pk_D'!D10 -> 28253.764 | G11: =p_weight*D11+p_W*B11^2 -> 1386.0612 | H11: =IF(ABS((MIN(F11,p_Pphi)-G11)/(p_M*E11))<1E-10,0,(MIN(F11,p_Pphi)-G11)/(p_M*E11)) -> 1.0249372 | I11: =IF(H11>1E-10,1/H11,IF(ABS(H11)<=1E-10,"∞","—")) -> 0.97566957 | J11: =IF(H11>1E-10,"j > 0",IF(ABS(H11)<=1E-10,"Cân bằng","j < 0")) -> j > 0
A12: ='Dong_co'!A11 -> 2400 | B12: ='Van_toc_Pk_D'!B11 -> 3.5431235 | C12: =3.6*B12 -> 12.755245 | D12: =IF(B12<=p_threshold,p_f0,p_f0*(1+B12^2/1500)) -> 0.018 | E12: =delta_1 -> 3.4132812 | F12: ='Van_toc_Pk_D'!D11 -> 28080.288 | G12: =p_weight*D12+p_W*B12^2 -> 1392.854 | H12: =IF(ABS((MIN(F12,p_Pphi)-G12)/(p_M*E12))<1E-10,0,(MIN(F12,p_Pphi)-G12)/(p_M*E12)) -> 1.0180603 | I12: =IF(H12>1E-10,1/H12,IF(ABS(H12)<=1E-10,"∞","—")) -> 0.98226004 | J12: =IF(H12>1E-10,"j > 0",IF(ABS(H12)<=1E-10,"Cân bằng","j < 0")) -> j > 0
A13: ='Dong_co'!A12 -> 2600 | B13: ='Van_toc_Pk_D'!B12 -> 3.8383838 | C13: =3.6*B13 -> 13.818182 | D13: =IF(B13<=p_threshold,p_f0,p_f0*(1+B13^2/1500)) -> 0.018 | E13: =delta_1 -> 3.4132812 | F13: ='Van_toc_Pk_D'!D12 -> 27655.449 | G13: =p_weight*D13+p_W*B13^2 -> 1399.229 | H13: =IF(ABS((MIN(F13,p_Pphi)-G13)/(p_M*E13))<1E-10,0,(MIN(F13,p_Pphi)-G13)/(p_M*E13)) -> 1.0016106 | I13: =IF(H13>1E-10,1/H13,IF(ABS(H13)<=1E-10,"∞","—")) -> 0.998392 | J13: =IF(H13>1E-10,"j > 0",IF(ABS(H13)<=1E-10,"Cân bằng","j < 0")) -> j > 0
A14: ='Dong_co'!A13 -> 2888.8889 | B14: ='Van_toc_Pk_D'!B13 -> 4.2648709 | C14: =3.6*B14 -> 15.353535 | D14: =IF(B14<=p_threshold,p_f0,p_f0*(1+B14^2/1500)) -> 0.018 | E14: =delta_1 -> 3.4132812 | F14: ='Van_toc_Pk_D'!D13 -> 26591.778 | G14: =p_weight*D14+p_W*B14^2 -> 1409.3376 | H14: =IF(ABS((MIN(F14,p_Pphi)-G14)/(p_M*E14))<1E-10,0,(MIN(F14,p_Pphi)-G14)/(p_M*E14)) -> 0.96064852 | I14: =IF(H14>1E-10,1/H14,IF(ABS(H14)<=1E-10,"∞","—")) -> 1.0409635 | J14: =IF(H14>1E-10,"j > 0",IF(ABS(H14)<=1E-10,"Cân bằng","j < 0")) -> j > 0
A17: SỐ 2
A18: n, vòng/phút | B18: v, m/s | C18: v, km/h | D18: f(v) | E18: δh | F18: Pk, N | G18: Pc, N | H18: j, m/s² | I18: 1/j, s²/m | J18: Miền
A19: ='Dong_co'!A6 -> 800 | B19: ='Van_toc_Pk_D'!G6 -> 2.0847434 | C19: =3.6*B19 -> 7.5050762 | D19: =IF(B19<=p_threshold,p_f0,p_f0*(1+B19^2/1500)) -> 0.018 | E19: =delta_2 -> 1.8084733 | F19: ='Van_toc_Pk_D'!I6 -> 12634.717 | G19: =p_weight*D19+p_W*B19^2 -> 1368.8469 | H19: =IF(ABS((MIN(F19,p_Pphi)-G19)/(p_M*E19))<1E-10,0,(MIN(F19,p_Pphi)-G19)/(p_M*E19)) -> 0.81113183 | I19: =IF(H19>1E-10,1/H19,IF(ABS(H19)<=1E-10,"∞","—")) -> 1.2328452 | J19: =IF(H19>1E-10,"j > 0",IF(ABS(H19)<=1E-10,"Cân bằng","j < 0")) -> j > 0
A20: ='Dong_co'!A7 -> 1200 | B20: ='Van_toc_Pk_D'!G7 -> 3.1271151 | C20: =3.6*B20 -> 11.257614 | D20: =IF(B20<=p_threshold,p_f0,p_f0*(1+B20^2/1500)) -> 0.018 | E20: =delta_2 -> 1.8084733 | F20: ='Van_toc_Pk_D'!I7 -> 14319.465 | G20: =p_weight*D20+p_W*B20^2 -> 1384.7375 | H20: =IF(ABS((MIN(F20,p_Pphi)-G20)/(p_M*E20))<1E-10,0,(MIN(F20,p_Pphi)-G20)/(p_M*E20)) -> 0.93128794 | I20: =IF(H20>1E-10,1/H20,IF(ABS(H20)<=1E-10,"∞","—")) -> 1.0737818 | J20: =IF(H20>1E-10,"j > 0",IF(ABS(H20)<=1E-10,"Cân bằng","j < 0")) -> j > 0
A21: ='Dong_co'!A8 -> 1600 | B21: ='Van_toc_Pk_D'!G8 -> 4.1694868 | C21: =3.6*B21 -> 15.010152 | D21: =IF(B21<=p_threshold,p_f0,p_f0*(1+B21^2/1500)) -> 0.018 | E21: =delta_2 -> 1.8084733 | F21: ='Van_toc_Pk_D'!I8 -> 15426.585 | G21: =p_weight*D21+p_W*B21^2 -> 1406.9844 | H21: =IF(ABS((MIN(F21,p_Pphi)-G21)/(p_M*E21))<1E-10,0,(MIN(F21,p_Pphi)-G21)/(p_M*E21)) -> 1.0093978 | I21: =IF(H21>1E-10,1/H21,IF(ABS(H21)<=1E-10,"∞","—")) -> 0.99068974 | J21: =IF(H21>1E-10,"j > 0",IF(ABS(H21)<=1E-10,"Cân bằng","j < 0")) -> j > 0
A22: ='Dong_co'!A9 -> 2000 | B22: ='Van_toc_Pk_D'!G9 -> 5.2118585 | C22: =3.6*B22 -> 18.76269 | D22: =IF(B22<=p_threshold,p_f0,p_f0*(1+B22^2/1500)) -> 0.018 | E22: =delta_2 -> 1.8084733 | F22: ='Van_toc_Pk_D'!I9 -> 15956.078 | G22: =p_weight*D22+p_W*B22^2 -> 1435.5875 | H22: =IF(ABS((MIN(F22,p_Pphi)-G22)/(p_M*E22))<1E-10,0,(MIN(F22,p_Pphi)-G22)/(p_M*E22)) -> 1.0454613 | I22: =IF(H22>1E-10,1/H22,IF(ABS(H22)<=1E-10,"∞","—")) -> 0.95651557 | J22: =IF(H22>1E-10,"j > 0",IF(ABS(H22)<=1E-10,"Cân bằng","j < 0")) -> j > 0
A23: ='Dong_co'!A10 -> 2166.6667 | B23: ='Van_toc_Pk_D'!G10 -> 5.64618 | C23: =3.6*B23 -> 20.326248 | D23: =IF(B23<=p_threshold,p_f0,p_f0*(1+B23^2/1500)) -> 0.018 | E23: =delta_2 -> 1.8084733 | F23: ='Van_toc_Pk_D'!I10 -> 16006.219 | G23: =p_weight*D23+p_W*B23^2 -> 1449.3815 | H23: =IF(ABS((MIN(F23,p_Pphi)-G23)/(p_M*E23))<1E-10,0,(MIN(F23,p_Pphi)-G23)/(p_M*E23)) -> 1.0480783 | I23: =IF(H23>1E-10,1/H23,IF(ABS(H23)<=1E-10,"∞","—")) -> 0.95412722 | J23: =IF(H23>1E-10,"j > 0",IF(ABS(H23)<=1E-10,"Cân bằng","j < 0")) -> j > 0
A24: ='Dong_co'!A11 -> 2400 | B24: ='Van_toc_Pk_D'!G11 -> 6.2542302 | C24: =3.6*B24 -> 22.515229 | D24: =IF(B24<=p_threshold,p_f0,p_f0*(1+B24^2/1500)) -> 0.018 | E24: =delta_2 -> 1.8084733 | F24: ='Van_toc_Pk_D'!I11 -> 15907.942 | G24: =p_weight*D24+p_W*B24^2 -> 1470.5469 | H24: =IF(ABS((MIN(F24,p_Pphi)-G24)/(p_M*E24))<1E-10,0,(MIN(F24,p_Pphi)-G24)/(p_M*E24)) -> 1.0394785 | I24: =IF(H24>1E-10,1/H24,IF(ABS(H24)<=1E-10,"∞","—")) -> 0.96202084 | J24: =IF(H24>1E-10,"j > 0",IF(ABS(H24)<=1E-10,"Cân bằng","j < 0")) -> j > 0
A25: ='Dong_co'!A12 -> 2600 | B25: ='Van_toc_Pk_D'!G12 -> 6.775416 | C25: =3.6*B25 -> 24.391498 | D25: =IF(B25<=p_threshold,p_f0,p_f0*(1+B25^2/1500)) -> 0.018 | E25: =delta_2 -> 1.8084733 | F25: ='Van_toc_Pk_D'!I12 -> 15667.264 | G25: =p_weight*D25+p_W*B25^2 -> 1490.4102 | H25: =IF(ABS((MIN(F25,p_Pphi)-G25)/(p_M*E25))<1E-10,0,(MIN(F25,p_Pphi)-G25)/(p_M*E25)) -> 1.0207198 | I25: =IF(H25>1E-10,1/H25,IF(ABS(H25)<=1E-10,"∞","—")) -> 0.97970081 | J25: =IF(H25>1E-10,"j > 0",IF(ABS(H25)<=1E-10,"Cân bằng","j < 0")) -> j > 0
A26: ='Dong_co'!A13 -> 2888.8889 | B26: ='Van_toc_Pk_D'!G13 -> 7.52824 | C26: =3.6*B26 -> 27.101664 | D26: =IF(B26<=p_threshold,p_f0,p_f0*(1+B26^2/1500)) -> 0.018 | E26: =delta_2 -> 1.8084733 | F26: ='Van_toc_Pk_D'!I13 -> 15064.677 | G26: =p_weight*D26+p_W*B26^2 -> 1521.907 | H26: =IF(ABS((MIN(F26,p_Pphi)-G26)/(p_M*E26))<1E-10,0,(MIN(F26,p_Pphi)-G26)/(p_M*E26)) -> 0.97506636 | I26: =IF(H26>1E-10,1/H26,IF(ABS(H26)<=1E-10,"∞","—")) -> 1.0255712 | J26: =IF(H26>1E-10,"j > 0",IF(ABS(H26)<=1E-10,"Cân bằng","j < 0")) -> j > 0
A29: SỐ 3
A30: n, vòng/phút | B30: v, m/s | C30: v, km/h | D30: f(v) | E30: δh | F30: Pk, N | G30: Pc, N | H30: j, m/s² | I30: 1/j, s²/m | J30: Miền
A31: ='Dong_co'!A6 -> 800 | B31: ='Van_toc_Pk_D'!L6 -> 3.6799352 | C31: =3.6*B31 -> 13.247767 | D31: =IF(B31<=p_threshold,p_f0,p_f0*(1+B31^2/1500)) -> 0.018 | E31: =delta_3 -> 1.293425 | F31: ='Van_toc_Pk_D'!N6 -> 7157.7738 | G31: =p_weight*D31+p_W*B31^2 -> 1395.7445 | H31: =IF(ABS((MIN(F31,p_Pphi)-G31)/(p_M*E31))<1E-10,0,(MIN(F31,p_Pphi)-G31)/(p_M*E31)) -> 0.5800601 | I31: =IF(H31>1E-10,1/H31,IF(ABS(H31)<=1E-10,"∞","—")) -> 1.7239593 | J31: =IF(H31>1E-10,"j > 0",IF(ABS(H31)<=1E-10,"Cân bằng","j < 0")) -> j > 0
A32: ='Dong_co'!A7 -> 1200 | B32: ='Van_toc_Pk_D'!L7 -> 5.5199028 | C32: =3.6*B32 -> 19.87165 | D32: =IF(B32<=p_threshold,p_f0,p_f0*(1+B32^2/1500)) -> 0.018 | E32: =delta_3 -> 1.293425 | F32: ='Van_toc_Pk_D'!N7 -> 8112.211 | G32: =p_weight*D32+p_W*B32^2 -> 1445.2572 | H32: =IF(ABS((MIN(F32,p_Pphi)-G32)/(p_M*E32))<1E-10,0,(MIN(F32,p_Pphi)-G32)/(p_M*E32)) -> 0.67115832 | I32: =IF(H32>1E-10,1/H32,IF(ABS(H32)<=1E-10,"∞","—")) -> 1.4899614 | J32: =IF(H32>1E-10,"j > 0",IF(ABS(H32)<=1E-10,"Cân bằng","j < 0")) -> j > 0
A33: ='Dong_co'!A8 -> 1600 | B33: ='Van_toc_Pk_D'!L8 -> 7.3598703 | C33: =3.6*B33 -> 26.495533 | D33: =IF(B33<=p_threshold,p_f0,p_f0*(1+B33^2/1500)) -> 0.018 | E33: =delta_3 -> 1.293425 | F33: ='Van_toc_Pk_D'!N8 -> 8739.4126 | G33: =p_weight*D33+p_W*B33^2 -> 1514.5749 | H33: =IF(ABS((MIN(F33,p_Pphi)-G33)/(p_M*E33))<1E-10,0,(MIN(F33,p_Pphi)-G33)/(p_M*E33)) -> 0.72732016 | I33: =IF(H33>1E-10,1/H33,IF(ABS(H33)<=1E-10,"∞","—")) -> 1.3749103 | J33: =IF(H33>1E-10,"j > 0",IF(ABS(H33)<=1E-10,"Cân bằng","j < 0")) -> j > 0
A34: ='Dong_co'!A9 -> 2000 | B34: ='Van_toc_Pk_D'!L9 -> 9.1998379 | C34: =3.6*B34 -> 33.119417 | D34: =IF(B34<=p_threshold,p_f0,p_f0*(1+B34^2/1500)) -> 0.018 | E34: =delta_3 -> 1.293425 | F34: ='Van_toc_Pk_D'!N9 -> 9039.3786 | G34: =p_weight*D34+p_W*B34^2 -> 1603.6977 | H34: =IF(ABS((MIN(F34,p_Pphi)-G34)/(p_M*E34))<1E-10,0,(MIN(F34,p_Pphi)-G34)/(p_M*E34)) -> 0.74854562 | I34: =IF(H34>1E-10,1/H34,IF(ABS(H34)<=1E-10,"∞","—")) -> 1.3359239 | J34: =IF(H34>1E-10,"j > 0",IF(ABS(H34)<=1E-10,"Cân bằng","j < 0")) -> j > 0
A35: ='Dong_co'!A10 -> 2166.6667 | B35: ='Van_toc_Pk_D'!L10 -> 9.9664911 | C35: =3.6*B35 -> 35.879368 | D35: =IF(B35<=p_threshold,p_f0,p_f0*(1+B35^2/1500)) -> 0.018 | E35: =delta_3 -> 1.293425 | F35: ='Van_toc_Pk_D'!N10 -> 9067.7844 | G35: =p_weight*D35+p_W*B35^2 -> 1646.6774 | H35: =IF(ABS((MIN(F35,p_Pphi)-G35)/(p_M*E35))<1E-10,0,(MIN(F35,p_Pphi)-G35)/(p_M*E35)) -> 0.74707848 | I35: =IF(H35>1E-10,1/H35,IF(ABS(H35)<=1E-10,"∞","—")) -> 1.3385475 | J35: =IF(H35>1E-10,"j > 0",IF(ABS(H35)<=1E-10,"Cân bằng","j < 0")) -> j > 0
A36: ='Dong_co'!A11 -> 2400 | B36: ='Van_toc_Pk_D'!L11 -> 11.039806 | C36: =3.6*B36 -> 39.7433 | D36: =IF(B36<=p_threshold,p_f0,p_f0*(1+B36^2/1500)) -> 0.018 | E36: =delta_3 -> 1.293425 | F36: ='Van_toc_Pk_D'!N11 -> 9012.1089 | G36: =p_weight*D36+p_W*B36^2 -> 1712.6255 | H36: =IF(ABS((MIN(F36,p_Pphi)-G36)/(p_M*E36))<1E-10,0,(MIN(F36,p_Pphi)-G36)/(p_M*E36)) -> 0.7348347 | I36: =IF(H36>1E-10,1/H36,IF(ABS(H36)<=1E-10,"∞","—")) -> 1.3608503 | J36: =IF(H36>1E-10,"j > 0",IF(ABS(H36)<=1E-10,"Cân bằng","j < 0")) -> j > 0
A37: ='Dong_co'!A12 -> 2600 | B37: ='Van_toc_Pk_D'!L12 -> 11.959789 | C37: =3.6*B37 -> 43.055241 | D37: =IF(B37<=p_threshold,p_f0,p_f0*(1+B37^2/1500)) -> 0.018 | E37: =delta_3 -> 1.293425 | F37: ='Van_toc_Pk_D'!N12 -> 8875.7608 | G37: =p_weight*D37+p_W*B37^2 -> 1774.5163 | H37: =IF(ABS((MIN(F37,p_Pphi)-G37)/(p_M*E37))<1E-10,0,(MIN(F37,p_Pphi)-G37)/(p_M*E37)) -> 0.7148781 | I37: =IF(H37>1E-10,1/H37,IF(ABS(H37)<=1E-10,"∞","—")) -> 1.3988399 | J37: =IF(H37>1E-10,"j > 0",IF(ABS(H37)<=1E-10,"Cân bằng","j < 0")) -> j > 0
A38: ='Dong_co'!A13 -> 2888.8889 | B38: ='Van_toc_Pk_D'!L13 -> 13.288655 | C38: =3.6*B38 -> 47.839157 | D38: =IF(B38<=p_threshold,p_f0,p_f0*(1+B38^2/1500)) -> 0.018 | E38: =delta_3 -> 1.293425 | F38: ='Van_toc_Pk_D'!N13 -> 8534.3853 | G38: =p_weight*D38+p_W*B38^2 -> 1872.6553 | H38: =IF(ABS((MIN(F38,p_Pphi)-G38)/(p_M*E38))<1E-10,0,(MIN(F38,p_Pphi)-G38)/(p_M*E38)) -> 0.67063245 | I38: =IF(H38>1E-10,1/H38,IF(ABS(H38)<=1E-10,"∞","—")) -> 1.4911298 | J38: =IF(H38>1E-10,"j > 0",IF(ABS(H38)<=1E-10,"Cân bằng","j < 0")) -> j > 0
A41: SỐ 4
A42: n, vòng/phút | B42: v, m/s | C42: v, km/h | D42: f(v) | E42: δh | F42: Pk, N | G42: Pc, N | H42: j, m/s² | I42: 1/j, s²/m | J42: Miền
A43: ='Dong_co'!A6 -> 800 | B43: ='Van_toc_Pk_D'!Q6 -> 6.4957265 | C43: =3.6*B43 -> 23.384615 | D43: =IF(B43<=p_threshold,p_f0,p_f0*(1+B43^2/1500)) -> 0.018 | E43: =delta_4 -> 1.128125 | F43: ='Van_toc_Pk_D'!S6 -> 4054.9958 | G43: =p_weight*D43+p_W*B43^2 -> 1479.5532 | H43: =IF(ABS((MIN(F43,p_Pphi)-G43)/(p_M*E43))<1E-10,0,(MIN(F43,p_Pphi)-G43)/(p_M*E43)) -> 0.29725792 | I43: =IF(H43>1E-10,1/H43,IF(ABS(H43)<=1E-10,"∞","—")) -> 3.364082 | J43: =IF(H43>1E-10,"j > 0",IF(ABS(H43)<=1E-10,"Cân bằng","j < 0")) -> j > 0
A44: ='Dong_co'!A7 -> 1200 | B44: ='Van_toc_Pk_D'!Q7 -> 9.7435897 | C44: =3.6*B44 -> 35.076923 | D44: =IF(B44<=p_threshold,p_f0,p_f0*(1+B44^2/1500)) -> 0.018 | E44: =delta_4 -> 1.128125 | F44: ='Van_toc_Pk_D'!S7 -> 4595.7001 | G44: =p_weight*D44+p_W*B44^2 -> 1633.8267 | H44: =IF(ABS((MIN(F44,p_Pphi)-G44)/(p_M*E44))<1E-10,0,(MIN(F44,p_Pphi)-G44)/(p_M*E44)) -> 0.3418598 | I44: =IF(H44>1E-10,1/H44,IF(ABS(H44)<=1E-10,"∞","—")) -> 2.9251757 | J44: =IF(H44>1E-10,"j > 0",IF(ABS(H44)<=1E-10,"Cân bằng","j < 0")) -> j > 0
A45: ='Dong_co'!A8 -> 1600 | B45: ='Van_toc_Pk_D'!Q8 -> 12.991453 | C45: =3.6*B45 -> 46.769231 | D45: =IF(B45<=p_threshold,p_f0,p_f0*(1+B45^2/1500)) -> 0.018 | E45: =delta_4 -> 1.128125 | F45: ='Van_toc_Pk_D'!S8 -> 4951.02 | G45: =p_weight*D45+p_W*B45^2 -> 1849.8096 | H45: =IF(ABS((MIN(F45,p_Pphi)-G45)/(p_M*E45))<1E-10,0,(MIN(F45,p_Pphi)-G45)/(p_M*E45)) -> 0.3579421 | I45: =IF(H45>1E-10,1/H45,IF(ABS(H45)<=1E-10,"∞","—")) -> 2.7937479 | J45: =IF(H45>1E-10,"j > 0",IF(ABS(H45)<=1E-10,"Cân bằng","j < 0")) -> j > 0
A46: ='Dong_co'!A9 -> 2000 | B46: ='Van_toc_Pk_D'!Q9 -> 16.239316 | C46: =3.6*B46 -> 58.461538 | D46: =IF(B46<=p_threshold,p_f0,p_f0*(1+B46^2/1500)) -> 0.018 | E46: =delta_4 -> 1.128125 | F46: ='Van_toc_Pk_D'!S9 -> 5120.9556 | G46: =p_weight*D46+p_W*B46^2 -> 2127.5019 | H46: =IF(ABS((MIN(F46,p_Pphi)-G46)/(p_M*E46))<1E-10,0,(MIN(F46,p_Pphi)-G46)/(p_M*E46)) -> 0.34550481 | I46: =IF(H46>1E-10,1/H46,IF(ABS(H46)<=1E-10,"∞","—")) -> 2.8943157 | J46: =IF(H46>1E-10,"j > 0",IF(ABS(H46)<=1E-10,"Cân bằng","j < 0")) -> j > 0
A47: ='Dong_co'!A10 -> 2166.6667 | B47: ='Van_toc_Pk_D'!Q10 -> 17.592593 | C47: =3.6*B47 -> 63.333333 | D47: =IF(B47<=p_threshold,p_f0,p_f0*(1+B47^2/1500)) -> 0.018 | E47: =delta_4 -> 1.128125 | F47: ='Van_toc_Pk_D'!S10 -> 5137.048 | G47: =p_weight*D47+p_W*B47^2 -> 2261.4199 | H47: =IF(ABS((MIN(F47,p_Pphi)-G47)/(p_M*E47))<1E-10,0,(MIN(F47,p_Pphi)-G47)/(p_M*E47)) -> 0.33190537 | I47: =IF(H47>1E-10,1/H47,IF(ABS(H47)<=1E-10,"∞","—")) -> 3.012907 | J47: =IF(H47>1E-10,"j > 0",IF(ABS(H47)<=1E-10,"Cân bằng","j < 0")) -> j > 0
A48: ='Dong_co'!A11 -> 2400 | B48: ='Van_toc_Pk_D'!Q11 -> 19.487179 | C48: =3.6*B48 -> 70.153846 | D48: =IF(B48<=p_threshold,p_f0,p_f0*(1+B48^2/1500)) -> 0.018 | E48: =delta_4 -> 1.128125 | F48: ='Van_toc_Pk_D'!S11 -> 5105.5069 | G48: =p_weight*D48+p_W*B48^2 -> 2466.9036 | H48: =IF(ABS((MIN(F48,p_Pphi)-G48)/(p_M*E48))<1E-10,0,(MIN(F48,p_Pphi)-G48)/(p_M*E48)) -> 0.30454793 | I48: =IF(H48>1E-10,1/H48,IF(ABS(H48)<=1E-10,"∞","—")) -> 3.2835554 | J48: =IF(H48>1E-10,"j > 0",IF(ABS(H48)<=1E-10,"Cân bằng","j < 0")) -> j > 0
...

Sheet Tang_toc_chi_tiet
A1: DỮ LIỆU TĂNG TỐC CHI TIẾT — 10.010 DÒNG THEO THỨ TỰ THỜI GIAN
A2: DỮ LIỆU TĨNH từ trajectory.csv: đổi đầu vào phải chạy lại calculate.py rồi build_workbook.py. Không sắp xếp theo v. Khi chuyển số (coast), v giảm, t/S tăng; n, D và 1/j để trống vì không dùng đặc tính kéo.
A5: n vòng/phút | B5: Ne kW | C5: Me N·m | D5: v m/s | E5: v_kmh km/h | F5: Pk N | G5: Pw N | H5: Pf N | I5: Pc N | J5: f — | K5: D — | L5: Dphi — | M5: j m/s² | N5: invj s²/m | O5: stage giai đoạn | P5: kind drive/coast | Q5: gear tay số trước chuyển | R5: side low/high | S5: dt s | T5: ds m | U5: t s | V5: S m
A6: 800 | B6: 30.988404 | C6: 369.89683 | D6: 1.1810412 | E6: 4.2517483 | F6: 22302.477 | G6: 4.0799604 | H6: 1356.1344 | I6: 1360.2144 | J6: 0.018 | K6: 0.29596708 | L6: 0.52494585 | M6: 0.79889611 | N6: 1.2517272 | O6: Kéo 1 | P6: drive | Q6: 1 | R6: low | S6: 0 | T6: 0 | U6: 0 | V6: 0
A7: 800.9625 | B7: 31.037344 | C7: 370.03581 | D7: 1.1824621 | E7: 4.2568636 | F7: 22310.857 | G7: 4.0897838 | H7: 1356.1344 | I7: 1360.2242 | J7: 0.018 | K7: 0.29607818 | L7: 0.52494572 | M7: 0.79921539 | N7: 1.2512271 | O7: Kéo 1 | P7: drive | Q7: 1 | R7: low | S7: 0.0017782742 | T7: 0.0021014782 | U7: 0.0017782742 | V7: 0.0021014782
A8: 801.925 | B8: 31.086304 | C8: 370.17469 | D8: 1.1838831 | E8: 4.261979 | F8: 22319.23 | G8: 4.0996189 | H8: 1356.1344 | I8: 1360.234 | J8: 0.018 | K8: 0.29618919 | L8: 0.52494559 | M8: 0.79953446 | N8: 1.2507278 | O8: Kéo 1 | P8: drive | Q8: 1 | R8: low | S8: 0.0017775642 | T8: 0.002103165 | U8: 0.0035558384 | V8: 0.0042046432
A9: 802.8875 | B9: 31.135284 | C9: 370.31348 | D9: 1.185304 | E9: 4.2670944 | F9: 22327.598 | G9: 4.1094658 | H9: 1356.1344 | I9: 1360.2439 | J9: 0.018 | K9: 0.29630013 | L9: 0.52494545 | M9: 0.7998533 | N9: 1.2502293 | O9: Kéo 1 | P9: drive | Q9: 1 | R9: low | S9: 0.0017768552 | T9: 0.0021048509 | U9: 0.0053326936 | V9: 0.0063094941
A10: 803.85 | B10: 31.184283 | C10: 370.45216 | D10: 1.1867249 | E10: 4.2722098 | F10: 22335.96 | G10: 4.1193246 | H10: 1356.1344 | I10: 1360.2537 | J10: 0.018 | K10: 0.29641099 | L10: 0.52494532 | M10: 0.80017191 | N10: 1.2497315 | O10: Kéo 1 | P10: drive | Q10: 1 | R10: low | S10: 0.0017761473 | T10: 0.0021065362 | U10: 0.0071088409 | V10: 0.0084160303
A11: 804.8125 | B11: 31.233303 | C11: 370.59075 | D11: 1.1881459 | E11: 4.2773252 | F11: 22344.316 | G11: 4.1291951 | H11: 1356.1344 | I11: 1360.2636 | J11: 0.018 | K11: 0.29652176 | L11: 0.52494519 | M11: 0.80049029 | N11: 1.2492344 | O11: Kéo 1 | P11: drive | Q11: 1 | R11: low | S11: 0.0017754405 | T11: 0.0021082206 | U11: 0.0088842814 | V11: 0.010524251
A12: 805.775 | B12: 31.282341 | C12: 370.72924 | D12: 1.1895668 | E12: 4.2824406 | F12: 22352.666 | G12: 4.1390775 | H12: 1356.1344 | I12: 1360.2735 | J12: 0.018 | K12: 0.29663246 | L12: 0.52494506 | M12: 0.80080845 | N12: 1.2487381 | O12: Kéo 1 | P12: drive | Q12: 1 | R12: low | S12: 0.0017747347 | T12: 0.0021099044 | U12: 0.010659016 | V12: 0.012634155
A13: 806.7375 | B13: 31.3314 | C13: 370.86764 | D13: 1.1909878 | E13: 4.2875559 | F13: 22361.01 | G13: 4.1489717 | H13: 1356.1344 | I13: 1360.2834 | J13: 0.018 | K13: 0.29674309 | L13: 0.52494493 | M13: 0.80112639 | N13: 1.2482425 | O13: Kéo 1 | P13: drive | Q13: 1 | R13: low | S13: 0.00177403 | T13: 0.0021115874 | U13: 0.012433046 | V13: 0.014745743
A14: 807.7 | B14: 31.380478 | C14: 371.00593 | D14: 1.1924087 | E14: 4.2926713 | F14: 22369.349 | G14: 4.1588777 | H14: 1356.1344 | I14: 1360.2933 | J14: 0.018 | K14: 0.29685363 | L14: 0.5249448 | M14: 0.8014441 | N14: 1.2477477 | O14: Kéo 1 | P14: drive | Q14: 1 | R14: low | S14: 0.0017733263 | T14: 0.0021132696 | U14: 0.014206372 | V14: 0.016859012
A15: 808.6625 | B15: 31.429576 | C15: 371.14413 | D15: 1.1938296 | E15: 4.2977867 | F15: 22377.681 | G15: 4.1687955 | H15: 1356.1344 | I15: 1360.3032 | J15: 0.018 | K15: 0.29696409 | L15: 0.52494467 | M15: 0.80176158 | N15: 1.2472536 | O15: Kéo 1 | P15: drive | Q15: 1 | R15: low | S15: 0.0017726237 | T15: 0.0021149511 | U15: 0.015978996 | V15: 0.018973963
A16: 809.625 | B16: 31.478693 | C16: 371.28223 | D16: 1.1952506 | E16: 4.3029021 | F16: 22386.008 | G16: 4.1787251 | H16: 1356.1344 | I16: 1360.3131 | J16: 0.018 | K16: 0.29707448 | L16: 0.52494454 | M16: 0.80207884 | N16: 1.2467602 | O16: Kéo 1 | P16: drive | Q16: 1 | R16: low | S16: 0.0017719222 | T16: 0.0021166319 | U16: 0.017750918 | V16: 0.021090595
A17: 810.5875 | B17: 31.527829 | C17: 371.42023 | D17: 1.1966715 | E17: 4.3080175 | F17: 22394.328 | G17: 4.1886665 | H17: 1356.1344 | I17: 1360.3231 | J17: 0.018 | K17: 0.29718479 | L17: 0.5249444 | M17: 0.80239587 | N17: 1.2462676 | O17: Kéo 1 | P17: drive | Q17: 1 | R17: low | S17: 0.0017712217 | T17: 0.0021183119 | U17: 0.01952214 | V17: 0.023208907
... A1606: 2340 | B1606: 114.43907 | C1606: 467.01393 | D1606: 3.4545455 | E1606: 12.436364 | F1606: 28158.034 | G1606: 34.906612 | H1606: 1356.1344 | I1606: 1391.041 | J1606: 0.018 | K1606: 0.37327885 | L1606: 0.52453668 | M1606: 1.0210953 | N1606: 0.9793405 | O1606: Kéo 1 | P1606: drive | Q1606: 1 | R1606: low | S1606: 0.001391556 | T1606: 0.0048062047 | U1606: 2.3854873 | V1606: 5.419402
B1607: 0 | C1607: 0 | D1607: 3.4545455 | E1607: 12.436364 | F1607: 0 | G1607: 34.906612 | H1607: 1356.1344 | I1607: 1391.041 | J1607: 0.018 | L1607: 0.52453668 | M1607: -0.17250013 | O1607: Chuyển 1→2 | P1607: coast | Q1607: 1 | S1607: 0 | T1607: 0 | U1607: 2.3854873 | V1607: 5.419402
B1608: 0 | C1608: 0 | D1608: 3.4528205 | E1608: 12.430154 | F1608: 0 | G1608: 34.87176 | H1608: 1356.1344 | I1608: 1391.0062 | J1608: 0.018 | L1608: 0.52453715 | M1608: -0.1724958 | O1608: Chuyển 1→2 | P1608: coast | Q1608: 1 | S1608: 0.01 | T1608: 0.03453683 | U1608: 2.3954873 | V1608: 5.4539389
B1609: 0 | C1609: 0 | D1609: 3.4510955 | E1609: 12.423944 | F1609: 0 | G1609: 34.836927 | H1609: 1356.1344 | I1609: 1390.9713 | J1609: 0.018 | L1609: 0.52453761 | M1609: -0.17249148 | O1609: Chuyển 1→2 | P1609: coast | Q1609: 1 | S1609: 0.01 | T1609: 0.03451958 | U1609: 2.4054873 | V1609: 5.4884584
B1610: 0 | C1610: 0 | D1610: 3.4493706 | E1610: 12.417734 | F1610: 0 | G1610: 34.802112 | H1610: 1356.1344 | I1610: 1390.9365 | J1610: 0.018 | L1610: 0.52453807 | M1610: -0.17248717 | O1610: Chuyển 1→2 | P1610: coast | Q1610: 1 | S1610: 0.01 | T1610: 0.034502331 | U1610: 2.4154873 | V1610: 5.5229608
B1611: 0 | C1611: 0 | D1611: 3.4476458 | E1611: 12.411525 | F1611: 0 | G1611: 34.767315 | H1611: 1356.1344 | I1611: 1390.9017 | J1611: 0.018 | L1611: 0.52453853 | M1611: -0.17248285 | O1611: Chuyển 1→2 | P1611: coast | Q1611: 1 | S1611: 0.01 | T1611: 0.034485082 | U1611: 2.4254873 | V1611: 5.5574458
B1612: 0 | C1612: 0 | D1612: 3.445921 | E1612: 12.405316 | F1612: 0 | G1612: 34.732537 | H1612: 1356.1344 | I1612: 1390.8669 | J1612: 0.018 | L1612: 0.52453899 | M1612: -0.17247854 | O1612: Chuyển 1→2 | P1612: coast | Q1612: 1 | S1612: 0.01 | T1612: 0.034467834 | U1612: 2.4354873 | V1612: 5.5919137
B1613: 0 | C1613: 0 | D1613: 3.4441962 | E1613: 12.399106 | F1613: 0 | G1613: 34.697776 | H1613: 1356.1344 | I1613: 1390.8322 | J1613: 0.018 | L1613: 0.52453946 | M1613: -0.17247423 | O1613: Chuyển 1→2 | P1613: coast | Q1613: 1 | S1613: 0.01 | T1613: 0.034450586 | U1613: 2.4454873 | V1613: 5.6263643
B1614: 0 | C1614: 0 | D1614: 3.4424715 | E1614: 12.392897 | F1614: 0 | G1614: 34.663034 | H1614: 1356.1344 | I1614: 1390.7974 | J1614: 0.018 | L1614: 0.52453992 | M1614: -0.17246992 | O1614: Chuyển 1→2 | P1614: coast | Q1614: 1 | S1614: 0.01 | T1614: 0.034433339 | U1614: 2.4554873 | V1614: 5.6607976
B1615: 0 | C1615: 0 | D1615: 3.4407468 | E1615: 12.386689 | F1615: 0 | G1615: 34.628311 | H1615: 1356.1344 | I1615: 1390.7627 | J1615: 0.018 | L1615: 0.52454038 | M1615: -0.17246561 | O1615: Chuyển 1→2 | P1615: coast | Q1615: 1 | S1615: 0.01 | T1615: 0.034416092 | U1615: 2.4654873 | V1615: 5.6952137
B1616: 0 | C1616: 0 | D1616: 3.4390222 | E1616: 12.38048 | F1616: 0 | G1616: 34.593605 | H1616: 1356.1344 | I1616: 1390.728 | J1616: 0.018 | L1616: 0.52454084 | M1616: -0.17246131 | O1616: Chuyển 1→2 | P1616: coast | Q1616: 1 | S1616: 0.01 | T1616: 0.034398845 | U1616: 2.4754873 | V1616: 5.7296125
B1617: 0 | C1617: 0 | D1617: 3.4372976 | E1617: 12.374271 | F1617: 0 | G1617: 34.558918 | H1617: 1356.1344 | I1617: 1390.6933 | J1617: 0.018 | L1617: 0.5245413 | M1617: -0.17245701 | O1617: Chuyển 1→2 | P1617: coast | Q1617: 1 | S1617: 0.01 | T1617: 0.034381599 | U1617: 2.4854873 | V1617: 5.7639941
B1618: 0 | C1618: 0 | D1618: 3.4355731 | E1618: 12.368063 | F1618: 0 | G1618: 34.524249 | H1618: 1356.1344 | I1618: 1390.6586 | J1618: 0.018 | L1618: 0.52454176 | M1618: -0.17245271 | O1618: Chuyển 1→2 | P1618: coast | Q1618: 1 | S1618: 0.01 | T1618: 0.034364353 | U1618: 2.4954873 | V1618: 5.7983585
... B1707: 0 | C1707: 0 | D1707: 3.2822577 | E1707: 11.816128 | F1707: 0 | G1707: 31.511656 | H1707: 1356.1344 | I1707: 1387.6461 | J1707: 0.018 | L1707: 0.52458175 | M1707: -0.17207912 | O1707: Chuyển 1→2 | P1707: coast | Q1707: 1 | S1707: 0.01 | T1707: 0.032831181 | U1707: 3.3854873 | V1707: 8.7877685
A1708: 1259.5345 | B1708: 56.071901 | C1708: 425.11517 | D1708: 3.2822577 | E1708: 11.816128 | F1708: 14520.833 | G1708: 31.511656 | H1708: 1356.1344 | I1708: 1387.6461 | J1708: 0.018 | K1708: 0.19231706 | L1708: 0.52458175 | M1708: 0.9455768 | N1708: 1.0575556 | O1708: Kéo 2 | P1708: drive | Q1708: 2 | R1708: low | S1708: 0 | T1708: 0 | U1708: 3.3854873 | V1708: 8.7877685
A1709: 1260.2098 | B1709: 56.110505 | C1709: 425.17989 | D1709: 3.2840175 | E1709: 11.822463 | F1709: 14523.044 | G1709: 31.545454 | H1709: 1356.1344 | I1709: 1387.6799 | J1709: 0.018 | K1709: 0.19234596 | L1709: 0.5245813 | M1709: 0.94573354 | N1709: 1.0573803 | O1709: Kéo 2 | P1709: drive | Q1709: 2 | R1709: low | S1709: 0.0018608902 | T1709: 0.0061095584 | U1709: 3.3873482 | V1709: 8.7938781
A1710: 1260.8851 | B1710: 56.149111 | C1710: 425.24456 | D1710: 3.2857772 | E1710: 11.828798 | F1710: 14525.253 | G1710: 31.579271 | H1710: 1356.1344 | I1710: 1387.7137 | J1710: 0.018 | K1710: 0.19237483 | L1710: 0.52458085 | M1710: 0.94589015 | N1710: 1.0572052 | O1710: Kéo 2 | P1710: drive | Q1710: 2 | R1710: low | S1710: 0.0018605819 | T1710: 0.0061118206 | U1710: 3.3892088 | V1710: 8.7999899
A1711: 1261.5604 | B1711: 56.18772 | C1711: 425.30919 | D1711: 3.287537 | E1711: 11.835133 | F1711: 14527.46 | G1711: 31.613106 | H1711: 1356.1344 | I1711: 1387.7475 | J1711: 0.018 | K1711: 0.19240368 | L1711: 0.5245804 | M1711: 0.94604664 | N1711: 1.0570303 | O1711: Kéo 2 | P1711: drive | Q1711: 2 | R1711: low | S1711: 0.001860274 | T1711: 0.0061140827 | U1711: 3.391069 | V1711: 8.806104
A1712: 1262.2356 | B1712: 56.226332 | C1712: 425.37376 | D1712: 3.2892968 | E1712: 11.841468 | F1712: 14529.666 | G1712: 31.646959 | H1712: 1356.1344 | I1712: 1387.7814 | J1712: 0.018 | K1712: 0.1924325 | L1712: 0.52457995 | M1712: 0.94620302 | N1712: 1.0568556 | O1712: Kéo 2 | P1712: drive | Q1712: 2 | R1712: low | S1712: 0.0018599664 | T1712: 0.0061163449 | U1712: 3.392929 | V1712: 8.8122203
A1713: 1262.9109 | B1713: 56.264947 | C1713: 425.43829 | D1713: 3.2910565 | E1713: 11.847803 | F1713: 14531.87 | G1713: 31.68083 | H1713: 1356.1344 | I1713: 1387.8152 | J1713: 0.018 | K1713: 0.19246131 | L1713: 0.5245795 | M1713: 0.94635927 | N1713: 1.0566811 | O1713: Kéo 2 | P1713: drive | Q1713: 2 | R1713: low | S1713: 0.0018596592 | T1713: 0.0061186071 | U1713: 3.3947887 | V1713: 8.8183389
A1714: 1263.5862 | B1714: 56.303565 | C1714: 425.50277 | D1714: 3.2928163 | E1714: 11.854139 | F1714: 14534.072 | G1714: 31.714719 | H1714: 1356.1344 | I1714: 1387.8491 | J1714: 0.018 | K1714: 0.19249009 | L1714: 0.52457905 | M1714: 0.94651541 | N1714: 1.0565068 | O1714: Kéo 2 | P1714: drive | Q1714: 2 | R1714: low | S1714: 0.0018593523 | T1714: 0.0061208693 | U1714: 3.396648 | V1714: 8.8244598
A1715: 1264.2615 | B1715: 56.342185 | C1715: 425.5672 | D1715: 3.294576 | E1715: 11.860474 | F1715: 14536.273 | G1715: 31.748626 | H1715: 1356.1344 | I1715: 1387.883 | J1715: 0.018 | K1715: 0.19251886 | L1715: 0.5245786 | M1715: 0.94667142 | N1715: 1.0563327 | O1715: Kéo 2 | P1715: drive | Q1715: 2 | R1715: low | S1715: 0.0018590457 | T1715: 0.0061231316 | U1715: 3.3985071 | V1715: 8.8305829
A1716: 1264.9368 | B1716: 56.380808 | C1716: 425.63159 | D1716: 3.2963358 | E1716: 11.866809 | F1716: 14538.472 | G1716: 31.782552 | H1716: 1356.1344 | I1716: 1387.917 | J1716: 0.018 | K1716: 0.19254759 | L1716: 0.52457815 | M1716: 0.94682732 | N1716: 1.0561588 | O1716: Kéo 2 | P1716: drive | Q1716: 2 | R1716: low | S1716: 0.0018587395 | T1716: 0.0061253939 | U1716: 3.4003658 | V1716: 8.8367083
A1717: 1265.6121 | B1717: 56.419434 | C1717: 425.69592 | D1717: 3.2980956 | E1717: 11.873144 | F1717: 14540.67 | G1717: 31.816495 | H1717: 1356.1344 | I1717: 1387.9509 | J1717: 0.018 | K1717: 0.19257631 | L1717: 0.5245777 | M1717: 0.9469831 | N1717: 1.0559851 | O1717: Kéo 2 | P1717: drive | Q1717: 2 | R1717: low | S1717: 0.0018584336 | T1717: 0.0061276562 | U1717: 3.4022242 | V1717: 8.842836
A1718: 1266.2874 | B1718: 56.458062 | C1718: 425.76021 | D1718: 3.2998553 | E1718: 11.879479 | F1718: 14542.866 | G1718: 31.850457 | H1718: 1356.1344 | I1718: 1387.9849 | J1718: 0.018 | K1718: 0.19260501 | L1718: 0.52457725 | M1718: 0.94713875 | N1718: 1.0558115 | O1718: Kéo 2 | P1718: drive | Q1718: 2 | R1718: low | S1718: 0.001858128 | T1718: 0.0061299186 | U1718: 3.4040824 | V1718: 8.8489659
...

Sheet Tong_hop
A1: TỔNG HỢP 9 PHA VÀ KIỂM TRA KẾT QUẢ
A2: Công thức SUMIF cộng dữ liệu chi tiết đã lưu; chúng không chạy lại mô phỏng khi đầu vào thay đổi. Kết quả là từ 4,251748 đến 90,25 km/h, gồm 4 lần chuyển số; chưa mô phỏng xuất phát bằng ly hợp trượt.
A5: Giai đoạn | B5: Loại | C5: Tay số | D5: v đầu, m/s | E5: v cuối, m/s | F5: Δt, s | G5: ΔS, m | H5: t tích lũy, s | I5: S tích lũy, m
A6: Kéo 1 | B6: drive | C6: 1 | D6: 1.1810412 | E6: 3.4545455 | F6: =SUMIF('Tang_toc_chi_tiet'!$O$6:$O$10015,A6,'Tang_toc_chi_tiet'!$S$6:$S$10015) -> 2.3854873 | G6: =SUMIF('Tang_toc_chi_tiet'!$O$6:$O$10015,A6,'Tang_toc_chi_tiet'!$T$6:$T$10015) -> 5.419402 | H6: =SUM($F$6:F6) -> 2.3854873 | I6: =SUM($G$6:G6) -> 5.419402
A7: Chuyển 1→2 | B7: coast | C7: 1 | D7: 3.4545455 | E7: 3.2822577 | F7: =SUMIF('Tang_toc_chi_tiet'!$O$6:$O$10015,A7,'Tang_toc_chi_tiet'!$S$6:$S$10015) -> 1 | G7: =SUMIF('Tang_toc_chi_tiet'!$O$6:$O$10015,A7,'Tang_toc_chi_tiet'!$T$6:$T$10015) -> 3.3683665 | H7: =SUM($F$6:F7) -> 3.3854873 | I7: =SUM($G$6:G7) -> 8.7877685
A8: Kéo 2 | B8: drive | C8: 2 | D8: 3.2822577 | E8: 6.0978744 | F8: =SUMIF('Tang_toc_chi_tiet'!$O$6:$O$10015,A8,'Tang_toc_chi_tiet'!$S$6:$S$10015) -> 2.7632487 | G8: =SUMIF('Tang_toc_chi_tiet'!$O$6:$O$10015,A8,'Tang_toc_chi_tiet'!$T$6:$T$10015) -> 12.896537 | H8: =SUM($F$6:F8) -> 6.148736 | I8: =SUM($G$6:G8) -> 21.684306
A9: Chuyển 2→3 | B9: coast | C9: 2 | D9: 6.0978744 | E9: 5.9166127 | F9: =SUMIF('Tang_toc_chi_tiet'!$O$6:$O$10015,A9,'Tang_toc_chi_tiet'!$S$6:$S$10015) -> 1 | G9: =SUMIF('Tang_toc_chi_tiet'!$O$6:$O$10015,A9,'Tang_toc_chi_tiet'!$T$6:$T$10015) -> 6.0071777 | H9: =SUM($F$6:F9) -> 7.148736 | I9: =SUM($G$6:G9) -> 27.691483
A10: Kéo 3 | B10: drive | C10: 3 | D10: 5.9166127 | E10: 10.76381 | F10: =SUMIF('Tang_toc_chi_tiet'!$O$6:$O$10015,A10,'Tang_toc_chi_tiet'!$S$6:$S$10015) -> 6.6179361 | G10: =SUMIF('Tang_toc_chi_tiet'!$O$6:$O$10015,A10,'Tang_toc_chi_tiet'!$T$6:$T$10015) -> 54.997602 | H10: =SUM($F$6:F10) -> 13.766672 | I10: =SUM($G$6:G10) -> 82.689085
A11: Chuyển 3→4 | B11: coast | C11: 3 | D11: 10.76381 | E11: 10.554427 | F11: =SUMIF('Tang_toc_chi_tiet'!$O$6:$O$10015,A11,'Tang_toc_chi_tiet'!$S$6:$S$10015) -> 1 | G11: =SUMIF('Tang_toc_chi_tiet'!$O$6:$O$10015,A11,'Tang_toc_chi_tiet'!$T$6:$T$10015) -> 10.658984 | H11: =SUM($F$6:F11) -> 14.766672 | I11: =SUM($G$6:G11) -> 93.348069
A12: Kéo 4 | B12: drive | C12: 4 | D12: 10.554427 | E12: 19 | F12: =SUMIF('Tang_toc_chi_tiet'!$O$6:$O$10015,A12,'Tang_toc_chi_tiet'!$S$6:$S$10015) -> 24.40098 | G12: =SUMIF('Tang_toc_chi_tiet'!$O$6:$O$10015,A12,'Tang_toc_chi_tiet'!$T$6:$T$10015) -> 362.43471 | H12: =SUM($F$6:F12) -> 39.167652 | I12: =SUM($G$6:G12) -> 455.78278
A13: Chuyển 4→5 | B13: coast | C13: 4 | D13: 19 | E13: 18.702927 | F13: =SUMIF('Tang_toc_chi_tiet'!$O$6:$O$10015,A13,'Tang_toc_chi_tiet'!$S$6:$S$10015) -> 1 | G13: =SUMIF('Tang_toc_chi_tiet'!$O$6:$O$10015,A13,'Tang_toc_chi_tiet'!$T$6:$T$10015) -> 18.851125 | H13: =SUM($F$6:F13) -> 40.167652 | I13: =SUM($G$6:G13) -> 474.63391
A14: Kéo 5 | B14: drive | C14: 5 | D14: 18.702927 | E14: 25.069444 | F14: =SUMIF('Tang_toc_chi_tiet'!$O$6:$O$10015,A14,'Tang_toc_chi_tiet'!$S$6:$S$10015) -> 63.847727 | G14: =SUMIF('Tang_toc_chi_tiet'!$O$6:$O$10015,A14,'Tang_toc_chi_tiet'!$T$6:$T$10015) -> 1458.7337 | H14: =SUM($F$6:F14) -> 104.01538 | I14: =SUM($G$6:G14) -> 1933.3676
A16: TỔNG | F16: =SUM(F6:F14) -> 104.01538 | G16: =SUM(G6:G14) -> 1933.3676
A19: THÔNG SỐ BỐN LẦN CHUYỂN SỐ — DỮ LIỆU TÍCH PHÂN ĐÃ LƯU
A20: Từ số | B20: Sang số | C20: v trước, m/s | D20: v sau, m/s | E20: Mất tốc độ, m/s | F20: Δt, s | G20: ΔS, m | H20: n sau nối, v/ph | I20: Ghi chú
A21: 1 | B21: 2 | C21: 3.4545455 | D21: 3.2822577 | E21: 0.17228774 | F21: 1 | G21: 3.3683665 | H21: 1259.5345 | I21: Ngắt lực kéo; δcoast=1,05
A22: 2 | B22: 3 | C22: 6.0978744 | D22: 5.9166127 | E22: 0.18126172 | F22: 1 | G22: 6.0071777 | H22: 1286.2428 | I22: Ngắt lực kéo; δcoast=1,05
A23: 3 | B23: 4 | C23: 10.76381 | D23: 10.554427 | E23: 0.20938317 | F23: 1 | G23: 10.658984 | H23: 1299.861 | I23: Ngắt lực kéo; δcoast=1,05
A24: 4 | B24: 5 | C24: 19 | D24: 18.702927 | E24: 0.2970732 | F24: 1 | G24: 18.851125 | H24: 1842.7305 | I24: Ngắt lực kéo; δcoast=1,05
A27: KIỂM TRA VÀ SAI KHÁC DO CHUẨN HÓA
A28: Thời gian cuối CSV, s | F28: 104.01538
A29: Quãng đường cuối CSV, m | F29: 1933.3676
A30: Sai số thời gian khi gấp đôi lưới, s | F30: -4.2716036e-06
A31: Sai số quãng đường khi gấp đôi lưới, m | F31: -0.00010674652
A32: Dư công suất ở 95 km/h, kW | F32: -1.4210855e-14
A33: Dư lực ở 95 km/h, N | F33: 0
A34: Mômen nguồn cao hơn công thức chuẩn, % | F34: 0.018868309
A37: VÍ DỤ MỘT KHOẢNG HÌNH THANG (SỐ I) — KHÔNG THAY TOÀN BỘ TÍCH PHÂN
A38: vA, m/s | B38: vB, m/s | C38: jA, m/s² | D38: jB, m/s² | E38: Δt, s | F38: ΔS, m | G38: Ý nghĩa
A39: 2 | B39: 2.01 | C39: 0.94550353 | D39: 0.94683046 | E39: =0.5*(1/C39+1/D39)*(B39-A39) -> 0.010568964 | F39: =0.5*(A39/C39+B39/D39)*(B39-A39) -> 0.021190736 | G39: Cộng từng khoảng nhỏ trên từng miền trơn; chuyển số tích phân theo thời gian riêng.

Sheet Do_thi
A1: ĐỒ THỊ XY THAM KHẢO — KHÔNG CHÈN VÀO WORD
A2: Pk và D có trục v riêng cho từng tay số. t(v), S(v) dùng nguyên thứ tự 10.010 dòng, giữ các đoạn vận tốc giảm khi chuyển số. Các đường từ bảng 8 điểm là đường tham khảo; mô phỏng tăng tốc dùng lưới dày đã lưu.
