Workbook

Sheet Huong_dan
A1: BÀI TẬP LỚN LÝ THUYẾT Ô TÔ – NHÓM 2
A2: Ô vàng trong Dau_vao là dữ liệu có thể sửa. Thiet_ke, Dong_co và Luc_keo dùng công thức Excel và có giá trị lưu sẵn.
A3: Tang_toc và Hinh_anh là kết quả tích phân/đồ thị của bộ tham số gốc, KHÔNG tự tính lại khi sửa ô Excel.
A4: Để tái tạo toàn bộ kết quả, sửa nhom2.json và chạy: python build_model.py nhom2.json ket_qua_moi
A5: Cài các thư viện theo requirements.txt. CSV chi tiết và kiem_tra.json phục vụ kiểm tra độc lập.
A6: Đề cho KG được hiểu là kg khối lượng; trọng lực tính với g=9,81 m/s². 70 kg/người là giả thiết.
A7: Công suất cực đại thiết kế là giá trị lý thuyết tối thiểu. Chưa chọn một động cơ thương mại cụ thể.
A8: Phép tăng tốc: đường bằng, đủ tải, không gió, 4 lần chuyển số 1 s; không mô phỏng trượt ly hợp từ đứng yên.
A9: Hệ số cản lăn ghép theo ngưỡng 22,2 m/s có bước nhảy thực nghiệm; không phải lực thực tế đột ngột thay đổi.
A10: Trang nguồn là số in trong tài liệu. PDF sách = trang in +1; PDF bài mẫu = trang in +7.
A11: Các giá trị và công thức đã kiểm tra bằng Python; chưa chạy ứng dụng Microsoft Excel/LibreOffice.

Sheet Dau_vao
A1: Tham số | B1: Giá trị | C1: Đơn vị | D1: Nguồn / giải thích
A2: m0 | B2: 3450 | C2: kg | D2: ĐỀ BÀI
A3: payload | B3: 4100 | C3: kg | D3: ĐỀ BÀI
A4: people | B4: 2 | C4: người | D4: ĐỀ BÀI
A5: person_mass | B5: 70 | C5: kg/người | D5: TỰ CHỌN / quy ước mô hình
A6: g | B6: 9.81 | C6: m/s² | D6: TỰ CHỌN / quy ước mô hình
A7: front_share | B7: 0.3 | C7: – | D7: ĐỀ BÀI
A8: vmax_kmh | B8: 95 | C8: km/h | D8: ĐỀ BÀI
A9: psi_max | B9: 0.31 | C9: – | D9: ĐỀ BÀI
A10: eta | B10: 0.89 | C10: – | D10: Tự chọn hiệu suất tổng, giữ nhất quán cho mọi công thức.
A11: K | B11: 0.65 | C11: N·s²/m⁴ | D11: K đã gộp hệ số khí động theo dạng Pw=KAv²; không nhân thêm ρ/2.
A12: area | B12: 4.5 | C12: m² | D12: Diện tích cản chính diện giả định; chưa có kích thước xe.
A13: f0 | B13: 0.015 | C13: – | D13: TỰ CHỌN / quy ước mô hình
... A33: drive_points | B33: 400 | C33: – | D33: Số điểm cho mỗi pha kéo, tích phân tách ở ngưỡng f.

Sheet Thiet_ke
A1: Đại lượng | B1: Giá trị | C1: Đơn vị / ý nghĩa
A2: m | B2: =Dau_vao!$B$2+Dau_vao!$B$3+Dau_vao!$B$4*Dau_vao!$B$5 -> 7690 | C2: kg
A3: G | B3: =Thiet_ke!$B$2*Dau_vao!$B$6 -> 75438.9 | C3: N
A4: G1 | B4: =Thiet_ke!$B$3*Dau_vao!$B$7 -> 22631.67 | C4: N; tải tĩnh cầu trước
A5: G2 | B5: =Thiet_ke!$B$3-Thiet_ke!$B$4 -> 52807.23 | C5: N; tải tĩnh cầu sau
A6: vmax | B6: =Dau_vao!$B$8/3.6 -> 26.388889 | C6: m/s
A7: rb | B7: =(Dau_vao!$B$16+Dau_vao!$B$17/2)*0.0254*Dau_vao!$B$18 -> 0.38592125 | C7: m
A8: W | B8: =Dau_vao!$B$11*Dau_vao!$B$12 -> 2.925 | C8: N·s²/m²
A9: f_vmax | B9: =IF(Thiet_ke!$B$6<=Dau_vao!$B$14,Dau_vao!$B$13,Dau_vao!$B$13*(1+Thiet_ke!$B$6^2/1500)) -> 0.021963735 | C9: –
A10: nv | B10: =Dau_vao!$B$20*Dau_vao!$B$19 -> 2340 | C10: rpm; điểm thiết kế tốc độ cực đại và chuyển số
A11: Nv | B11: =(Thiet_ke!$B$3*Thiet_ke!$B$9*Thiet_ke!$B$6+Thiet_ke!$B$8*Thiet_ke!$B$6^3)/(1000*Dau_vao!$B$10) -> 109.52315 | C11: kW; công suất cần ở động cơ tại vmax
A12: Nmax | B12: =Thiet_ke!$B$11/(Dau_vao!$B$22*Dau_vao!$B$20+Dau_vao!$B$23*Dau_vao!$B$20^2-Dau_vao!$B$24*Dau_vao!$B$20^3)*Dau_vao!$B$25 -> 117.01191 | C12: kW; đỉnh đặc tính thiết kế
A13: nM | B13: =Dau_vao!$B$19*Dau_vao!$B$23/(2*Dau_vao!$B$24) -> 1950 | C13: rpm; đỉnh mômen của đa thức
A14: Mmax | B14: =60000/(2*PI())*Thiet_ke!$B$12/Dau_vao!$B$19*(Dau_vao!$B$22+Dau_vao!$B$23*Thiet_ke!$B$13/Dau_vao!$B$19-Dau_vao!$B$24*(Thiet_ke!$B$13/Dau_vao!$B$19)^2) -> 456.62223 | C14: N·m
A15: i0 | B15: =2*PI()*Thiet_ke!$B$7*Thiet_ke!$B$10/(60*Dau_vao!$B$28*Thiet_ke!$B$6) -> 3.5836209 | C15: –
A16: Pphi | B16: =Dau_vao!$B$15*Thiet_ke!$B$5 -> 42245.784 | C16: N; bám theo tải tĩnh cầu sau
A17: ih1_min | B17: =Dau_vao!$B$9*Thiet_ke!$B$3*Thiet_ke!$B$7/(Thiet_ke!$B$14*Thiet_ke!$B$15*Dau_vao!$B$10) -> 6.197073 | C17: –; chưa kể Pw, kiểm tra lại sau khi chọn
A18: ih1_max | B18: =Thiet_ke!$B$16*Thiet_ke!$B$7/(Thiet_ke!$B$14*Thiet_ke!$B$15*Dau_vao!$B$10) -> 11.194713 | C18: –; giới hạn bám
A19: q | B19: =(Dau_vao!$B$27/Dau_vao!$B$28)^(1/(Dau_vao!$B$26-1)) -> 1.6265766 | C19: –; workbook cố định 5 trang số, đổi số cấp cần chạy Python
A20: ih1 | B20: =Dau_vao!$B$27/Thiet_ke!$B$19^0 -> 7 | C20: –
A21: ih2 | B21: =Dau_vao!$B$27/Thiet_ke!$B$19^1 -> 4.3035171 | C21: –
A22: ih3 | B22: =Dau_vao!$B$27/Thiet_ke!$B$19^2 -> 2.6457513 | C22: –
A23: ih4 | B23: =Dau_vao!$B$27/Thiet_ke!$B$19^3 -> 1.6265766 | C23: –
A24: ih5 | B24: =Dau_vao!$B$27/Thiet_ke!$B$19^4 -> 1 | C24: –
A25: iR | B25: =Dau_vao!$B$29*Dau_vao!$B$27 -> 8.4 | C25: –; số lùi

Sheet Dong_co
A1: n (rpm) | B1: x=n/nN | C1: Ne (kW) | D1: Me (N·m) | E1: Nk (kW)
A2: =Dau_vao!$B$21+(Dau_vao!$B$19*1.1-Dau_vao!$B$21)*0/100 -> 800 | B2: =A2/Dau_vao!$B$19 -> 0.30769231 | C2: =Thiet_ke!$B$12*(Dau_vao!$B$22*B2+Dau_vao!$B$23*B2^2-Dau_vao!$B$24*B2^3) -> 31.210278 | D2: =60000*C2/(2*PI()*A2) -> 372.54525 | E2: =C2*Dau_vao!$B$10 -> 27.777147
A3: =Dau_vao!$B$21+(Dau_vao!$B$19*1.1-Dau_vao!$B$21)*1/100 -> 820.6 | B3: =A3/Dau_vao!$B$19 -> 0.31561538 | C3: =Thiet_ke!$B$12*(Dau_vao!$B$22*B3+Dau_vao!$B$23*B3^2-Dau_vao!$B$24*B3^3) -> 32.270467 | D3: =60000*C3/(2*PI()*A3) -> 375.53042 | E3: =C3*Dau_vao!$B$10 -> 28.720716
A4: =Dau_vao!$B$21+(Dau_vao!$B$19*1.1-Dau_vao!$B$21)*2/100 -> 841.2 | B4: =A4/Dau_vao!$B$19 -> 0.32353846 | C4: =Thiet_ke!$B$12*(Dau_vao!$B$22*B4+Dau_vao!$B$23*B4^2-Dau_vao!$B$24*B4^3) -> 33.338783 | D4: =60000*C4/(2*PI()*A4) -> 378.46163 | E4: =C4*Dau_vao!$B$10 -> 29.671517
A5: =Dau_vao!$B$21+(Dau_vao!$B$19*1.1-Dau_vao!$B$21)*3/100 -> 861.8 | B5: =A5/Dau_vao!$B$19 -> 0.33146154 | C5: =Thiet_ke!$B$12*(Dau_vao!$B$22*B5+Dau_vao!$B$23*B5^2-Dau_vao!$B$24*B5^3) -> 34.414876 | D5: =60000*C5/(2*PI()*A5) -> 381.33889 | E5: =C5*Dau_vao!$B$10 -> 30.62924
A6: =Dau_vao!$B$21+(Dau_vao!$B$19*1.1-Dau_vao!$B$21)*4/100 -> 882.4 | B6: =A6/Dau_vao!$B$19 -> 0.33938462 | C6: =Thiet_ke!$B$12*(Dau_vao!$B$22*B6+Dau_vao!$B$23*B6^2-Dau_vao!$B$24*B6^3) -> 35.498397 | D6: =60000*C6/(2*PI()*A6) -> 384.16219 | E6: =C6*Dau_vao!$B$10 -> 31.593573
A7: =Dau_vao!$B$21+(Dau_vao!$B$19*1.1-Dau_vao!$B$21)*5/100 -> 903 | B7: =A7/Dau_vao!$B$19 -> 0.34730769 | C7: =Thiet_ke!$B$12*(Dau_vao!$B$22*B7+Dau_vao!$B$23*B7^2-Dau_vao!$B$24*B7^3) -> 36.588996 | D7: =60000*C7/(2*PI()*A7) -> 386.93154 | E7: =C7*Dau_vao!$B$10 -> 32.564207
A8: =Dau_vao!$B$21+(Dau_vao!$B$19*1.1-Dau_vao!$B$21)*6/100 -> 923.6 | B8: =A8/Dau_vao!$B$19 -> 0.35523077 | C8: =Thiet_ke!$B$12*(Dau_vao!$B$22*B8+Dau_vao!$B$23*B8^2-Dau_vao!$B$24*B8^3) -> 37.686325 | D8: =60000*C8/(2*PI()*A8) -> 389.64692 | E8: =C8*Dau_vao!$B$10 -> 33.54083
A9: =Dau_vao!$B$21+(Dau_vao!$B$19*1.1-Dau_vao!$B$21)*7/100 -> 944.2 | B9: =A9/Dau_vao!$B$19 -> 0.36315385 | C9: =Thiet_ke!$B$12*(Dau_vao!$B$22*B9+Dau_vao!$B$23*B9^2-Dau_vao!$B$24*B9^3) -> 38.790035 | D9: =60000*C9/(2*PI()*A9) -> 392.30835 | E9: =C9*Dau_vao!$B$10 -> 34.523131
A10: =Dau_vao!$B$21+(Dau_vao!$B$19*1.1-Dau_vao!$B$21)*8/100 -> 964.8 | B10: =A10/Dau_vao!$B$19 -> 0.37107692 | C10: =Thiet_ke!$B$12*(Dau_vao!$B$22*B10+Dau_vao!$B$23*B10^2-Dau_vao!$B$24*B10^3) -> 39.899776 | D10: =60000*C10/(2*PI()*A10) -> 394.91583 | E10: =C10*Dau_vao!$B$10 -> 35.5108
A11: =Dau_vao!$B$21+(Dau_vao!$B$19*1.1-Dau_vao!$B$21)*9/100 -> 985.4 | B11: =A11/Dau_vao!$B$19 -> 0.379 | C11: =Thiet_ke!$B$12*(Dau_vao!$B$22*B11+Dau_vao!$B$23*B11^2-Dau_vao!$B$24*B11^3) -> 41.015198 | D11: =60000*C11/(2*PI()*A11) -> 397.46934 | E11: =C11*Dau_vao!$B$10 -> 36.503526
A12: =Dau_vao!$B$21+(Dau_vao!$B$19*1.1-Dau_vao!$B$21)*10/100 -> 1006 | B12: =A12/Dau_vao!$B$19 -> 0.38692308 | C12: =Thiet_ke!$B$12*(Dau_vao!$B$22*B12+Dau_vao!$B$23*B12^2-Dau_vao!$B$24*B12^3) -> 42.135954 | D12: =60000*C12/(2*PI()*A12) -> 399.9689 | E12: =C12*Dau_vao!$B$10 -> 37.500999
A13: =Dau_vao!$B$21+(Dau_vao!$B$19*1.1-Dau_vao!$B$21)*11/100 -> 1026.6 | B13: =A13/Dau_vao!$B$19 -> 0.39484615 | C13: =Thiet_ke!$B$12*(Dau_vao!$B$22*B13+Dau_vao!$B$23*B13^2-Dau_vao!$B$24*B13^3) -> 43.261693 | D13: =60000*C13/(2*PI()*A13) -> 402.41451 | E13: =C13*Dau_vao!$B$10 -> 38.502906
A14: =Dau_vao!$B$21+(Dau_vao!$B$19*1.1-Dau_vao!$B$21)*12/100 -> 1047.2 | B14: =A14/Dau_vao!$B$19 -> 0.40276923 | C14: =Thiet_ke!$B$12*(Dau_vao!$B$22*B14+Dau_vao!$B$23*B14^2-Dau_vao!$B$24*B14^3) -> 44.392066 | D14: =60000*C14/(2*PI()*A14) -> 404.80615 | E14: =C14*Dau_vao!$B$10 -> 39.508939
A15: =Dau_vao!$B$21+(Dau_vao!$B$19*1.1-Dau_vao!$B$21)*13/100 -> 1067.8 | B15: =A15/Dau_vao!$B$19 -> 0.41069231 | C15: =Thiet_ke!$B$12*(Dau_vao!$B$22*B15+Dau_vao!$B$23*B15^2-Dau_vao!$B$24*B15^3) -> 45.526725 | D15: =60000*C15/(2*PI()*A15) -> 407.14384 | E15: =C15*Dau_vao!$B$10 -> 40.518785
A16: =Dau_vao!$B$21+(Dau_vao!$B$19*1.1-Dau_vao!$B$21)*14/100 -> 1088.4 | B16: =A16/Dau_vao!$B$19 -> 0.41861538 | C16: =Thiet_ke!$B$12*(Dau_vao!$B$22*B16+Dau_vao!$B$23*B16^2-Dau_vao!$B$24*B16^3) -> 46.665319 | D16: =60000*C16/(2*PI()*A16) -> 409.42758 | E16: =C16*Dau_vao!$B$10 -> 41.532134
A17: =Dau_vao!$B$21+(Dau_vao!$B$19*1.1-Dau_vao!$B$21)*15/100 -> 1109 | B17: =A17/Dau_vao!$B$19 -> 0.42653846 | C17: =Thiet_ke!$B$12*(Dau_vao!$B$22*B17+Dau_vao!$B$23*B17^2-Dau_vao!$B$24*B17^3) -> 47.807501 | D17: =60000*C17/(2*PI()*A17) -> 411.65735 | E17: =C17*Dau_vao!$B$10 -> 42.548676
A18: =Dau_vao!$B$21+(Dau_vao!$B$19*1.1-Dau_vao!$B$21)*16/100 -> 1129.6 | B18: =A18/Dau_vao!$B$19 -> 0.43446154 | C18: =Thiet_ke!$B$12*(Dau_vao!$B$22*B18+Dau_vao!$B$23*B18^2-Dau_vao!$B$24*B18^3) -> 48.95292 | D18: =60000*C18/(2*PI()*A18) -> 413.83317 | E18: =C18*Dau_vao!$B$10 -> 43.568099
A19: =Dau_vao!$B$21+(Dau_vao!$B$19*1.1-Dau_vao!$B$21)*17/100 -> 1150.2 | B19: =A19/Dau_vao!$B$19 -> 0.44238462 | C19: =Thiet_ke!$B$12*(Dau_vao!$B$22*B19+Dau_vao!$B$23*B19^2-Dau_vao!$B$24*B19^3) -> 50.101227 | D19: =60000*C19/(2*PI()*A19) -> 415.95503 | E19: =C19*Dau_vao!$B$10 -> 44.590092
A20: =Dau_vao!$B$21+(Dau_vao!$B$19*1.1-Dau_vao!$B$21)*18/100 -> 1170.8 | B20: =A20/Dau_vao!$B$19 -> 0.45030769 | C20: =Thiet_ke!$B$12*(Dau_vao!$B$22*B20+Dau_vao!$B$23*B20^2-Dau_vao!$B$24*B20^3) -> 51.252074 | D20: =60000*C20/(2*PI()*A20) -> 418.02294 | E20: =C20*Dau_vao!$B$10 -> 45.614346
A21: =Dau_vao!$B$21+(Dau_vao!$B$19*1.1-Dau_vao!$B$21)*19/100 -> 1191.4 | B21: =A21/Dau_vao!$B$19 -> 0.45823077 | C21: =Thiet_ke!$B$12*(Dau_vao!$B$22*B21+Dau_vao!$B$23*B21^2-Dau_vao!$B$24*B21^3) -> 52.405111 | D21: =60000*C21/(2*PI()*A21) -> 420.03689 | E21: =C21*Dau_vao!$B$10 -> 46.640549
A22: =Dau_vao!$B$21+(Dau_vao!$B$19*1.1-Dau_vao!$B$21)*20/100 -> 1212 | B22: =A22/Dau_vao!$B$19 -> 0.46615385 | C22: =Thiet_ke!$B$12*(Dau_vao!$B$22*B22+Dau_vao!$B$23*B22^2-Dau_vao!$B$24*B22^3) -> 53.559989 | D22: =60000*C22/(2*PI()*A22) -> 421.99688 | E22: =C22*Dau_vao!$B$10 -> 47.66839
A23: =Dau_vao!$B$21+(Dau_vao!$B$19*1.1-Dau_vao!$B$21)*21/100 -> 1232.6 | B23: =A23/Dau_vao!$B$19 -> 0.47407692 | C23: =Thiet_ke!$B$12*(Dau_vao!$B$22*B23+Dau_vao!$B$23*B23^2-Dau_vao!$B$24*B23^3) -> 54.716358 | D23: =60000*C23/(2*PI()*A23) -> 423.90292 | E23: =C23*Dau_vao!$B$10 -> 48.697559
A24: =Dau_vao!$B$21+(Dau_vao!$B$19*1.1-Dau_vao!$B$21)*22/100 -> 1253.2 | B24: =A24/Dau_vao!$B$19 -> 0.482 | C24: =Thiet_ke!$B$12*(Dau_vao!$B$22*B24+Dau_vao!$B$23*B24^2-Dau_vao!$B$24*B24^3) -> 55.87387 | D24: =60000*C24/(2*PI()*A24) -> 425.755 | E24: =C24*Dau_vao!$B$10 -> 49.727745
A25: =Dau_vao!$B$21+(Dau_vao!$B$19*1.1-Dau_vao!$B$21)*23/100 -> 1273.8 | B25: =A25/Dau_vao!$B$19 -> 0.48992308 | C25: =Thiet_ke!$B$12*(Dau_vao!$B$22*B25+Dau_vao!$B$23*B25^2-Dau_vao!$B$24*B25^3) -> 57.032176 | D25: =60000*C25/(2*PI()*A25) -> 427.55312 | E25: =C25*Dau_vao!$B$10 -> 50.758636
A26: =Dau_vao!$B$21+(Dau_vao!$B$19*1.1-Dau_vao!$B$21)*24/100 -> 1294.4 | B26: =A26/Dau_vao!$B$19 -> 0.49784615 | C26: =Thiet_ke!$B$12*(Dau_vao!$B$22*B26+Dau_vao!$B$23*B26^2-Dau_vao!$B$24*B26^3) -> 58.190925 | D26: =60000*C26/(2*PI()*A26) -> 429.29728 | E26: =C26*Dau_vao!$B$10 -> 51.789923
A27: =Dau_vao!$B$21+(Dau_vao!$B$19*1.1-Dau_vao!$B$21)*25/100 -> 1315 | B27: =A27/Dau_vao!$B$19 -> 0.50576923 | C27: =Thiet_ke!$B$12*(Dau_vao!$B$22*B27+Dau_vao!$B$23*B27^2-Dau_vao!$B$24*B27^3) -> 59.34977 | D27: =60000*C27/(2*PI()*A27) -> 430.98749 | E27: =C27*Dau_vao!$B$10 -> 52.821295
A28: =Dau_vao!$B$21+(Dau_vao!$B$19*1.1-Dau_vao!$B$21)*26/100 -> 1335.6 | B28: =A28/Dau_vao!$B$19 -> 0.51369231 | C28: =Thiet_ke!$B$12*(Dau_vao!$B$22*B28+Dau_vao!$B$23*B28^2-Dau_vao!$B$24*B28^3) -> 60.50836 | D28: =60000*C28/(2*PI()*A28) -> 432.62374 | E28: =C28*Dau_vao!$B$10 -> 53.85244
A29: =Dau_vao!$B$21+(Dau_vao!$B$19*1.1-Dau_vao!$B$21)*27/100 -> 1356.2 | B29: =A29/Dau_vao!$B$19 -> 0.52161538 | C29: =Thiet_ke!$B$12*(Dau_vao!$B$22*B29+Dau_vao!$B$23*B29^2-Dau_vao!$B$24*B29^3) -> 61.666346 | D29: =60000*C29/(2*PI()*A29) -> 434.20604 | E29: =C29*Dau_vao!$B$10 -> 54.883048
A30: =Dau_vao!$B$21+(Dau_vao!$B$19*1.1-Dau_vao!$B$21)*28/100 -> 1376.8 | B30: =A30/Dau_vao!$B$19 -> 0.52953846 | C30: =Thiet_ke!$B$12*(Dau_vao!$B$22*B30+Dau_vao!$B$23*B30^2-Dau_vao!$B$24*B30^3) -> 62.82338 | D30: =60000*C30/(2*PI()*A30) -> 435.73438 | E30: =C30*Dau_vao!$B$10 -> 55.912808
A31: =Dau_vao!$B$21+(Dau_vao!$B$19*1.1-Dau_vao!$B$21)*29/100 -> 1397.4 | B31: =A31/Dau_vao!$B$19 -> 0.53746154 | C31: =Thiet_ke!$B$12*(Dau_vao!$B$22*B31+Dau_vao!$B$23*B31^2-Dau_vao!$B$24*B31^3) -> 63.979112 | D31: =60000*C31/(2*PI()*A31) -> 437.20876 | E31: =C31*Dau_vao!$B$10 -> 56.94141
A32: =Dau_vao!$B$21+(Dau_vao!$B$19*1.1-Dau_vao!$B$21)*30/100 -> 1418 | B32: =A32/Dau_vao!$B$19 -> 0.54538462 | C32: =Thiet_ke!$B$12*(Dau_vao!$B$22*B32+Dau_vao!$B$23*B32^2-Dau_vao!$B$24*B32^3) -> 65.133193 | D32: =60000*C32/(2*PI()*A32) -> 438.62918 | E32: =C32*Dau_vao!$B$10 -> 57.968542
A33: =Dau_vao!$B$21+(Dau_vao!$B$19*1.1-Dau_vao!$B$21)*31/100 -> 1438.6 | B33: =A33/Dau_vao!$B$19 -> 0.55330769 | C33: =Thiet_ke!$B$12*(Dau_vao!$B$22*B33+Dau_vao!$B$23*B33^2-Dau_vao!$B$24*B33^3) -> 66.285274 | D33: =60000*C33/(2*PI()*A33) -> 439.99565 | E33: =C33*Dau_vao!$B$10 -> 58.993894
A34: =Dau_vao!$B$21+(Dau_vao!$B$19*1.1-Dau_vao!$B$21)*32/100 -> 1459.2 | B34: =A34/Dau_vao!$B$19 -> 0.56123077 | C34: =Thiet_ke!$B$12*(Dau_vao!$B$22*B34+Dau_vao!$B$23*B34^2-Dau_vao!$B$24*B34^3) -> 67.435006 | D34: =60000*C34/(2*PI()*A34) -> 441.30816 | E34: =C34*Dau_vao!$B$10 -> 60.017155
A35: =Dau_vao!$B$21+(Dau_vao!$B$19*1.1-Dau_vao!$B$21)*33/100 -> 1479.8 | B35: =A35/Dau_vao!$B$19 -> 0.56915385 | C35: =Thiet_ke!$B$12*(Dau_vao!$B$22*B35+Dau_vao!$B$23*B35^2-Dau_vao!$B$24*B35^3) -> 68.582039 | D35: =60000*C35/(2*PI()*A35) -> 442.56672 | E35: =C35*Dau_vao!$B$10 -> 61.038014
A36: =Dau_vao!$B$21+(Dau_vao!$B$19*1.1-Dau_vao!$B$21)*34/100 -> 1500.4 | B36: =A36/Dau_vao!$B$19 -> 0.57707692 | C36: =Thiet_ke!$B$12*(Dau_vao!$B$22*B36+Dau_vao!$B$23*B36^2-Dau_vao!$B$24*B36^3) -> 69.726024 | D36: =60000*C36/(2*PI()*A36) -> 443.77131 | E36: =C36*Dau_vao!$B$10 -> 62.056161
A37: =Dau_vao!$B$21+(Dau_vao!$B$19*1.1-Dau_vao!$B$21)*35/100 -> 1521 | B37: =A37/Dau_vao!$B$19 -> 0.585 | C37: =Thiet_ke!$B$12*(Dau_vao!$B$22*B37+Dau_vao!$B$23*B37^2-Dau_vao!$B$24*B37^3) -> 70.866612 | D37: =60000*C37/(2*PI()*A37) -> 444.92196 | E37: =C37*Dau_vao!$B$10 -> 63.071285
A38: =Dau_vao!$B$21+(Dau_vao!$B$19*1.1-Dau_vao!$B$21)*36/100 -> 1541.6 | B38: =A38/Dau_vao!$B$19 -> 0.59292308 | C38: =Thiet_ke!$B$12*(Dau_vao!$B$22*B38+Dau_vao!$B$23*B38^2-Dau_vao!$B$24*B38^3) -> 72.003454 | D38: =60000*C38/(2*PI()*A38) -> 446.01864 | E38: =C38*Dau_vao!$B$10 -> 64.083074
A39: =Dau_vao!$B$21+(Dau_vao!$B$19*1.1-Dau_vao!$B$21)*37/100 -> 1562.2 | B39: =A39/Dau_vao!$B$19 -> 0.60084615 | C39: =Thiet_ke!$B$12*(Dau_vao!$B$22*B39+Dau_vao!$B$23*B39^2-Dau_vao!$B$24*B39^3) -> 73.1362 | D39: =60000*C39/(2*PI()*A39) -> 447.06137 | E39: =C39*Dau_vao!$B$10 -> 65.091218
A40: =Dau_vao!$B$21+(Dau_vao!$B$19*1.1-Dau_vao!$B$21)*38/100 -> 1582.8 | B40: =A40/Dau_vao!$B$19 -> 0.60876923 | C40: =Thiet_ke!$B$12*(Dau_vao!$B$22*B40+Dau_vao!$B$23*B40^2-Dau_vao!$B$24*B40^3) -> 74.264502 | D40: =60000*C40/(2*PI()*A40) -> 448.05014 | E40: =C40*Dau_vao!$B$10 -> 66.095407
...

Sheet Luc_keo
A1: Số | B1: ih | C1: n rpm | D1: v m/s | E1: v km/h | F1: Ne kW | G1: Me Nm | H1: Pk N | I1: f | J1: Pw N | K1: Pc N | L1: D | M1: delta | N1: j m/s2 | O1: 1/j s2/m
A2: 1 | B2: =Thiet_ke!$B$20 -> 7 | C2: =Dau_vao!$B$21+(Dau_vao!$B$19-Dau_vao!$B$21)*0/200 -> 800 | D2: =2*PI()*C2*Thiet_ke!$B$7/(60*Thiet_ke!$B$15*B2) -> 1.2888346 | E2: =D2*3.6 -> 4.6398046 | F2: =Thiet_ke!$B$12*(Dau_vao!$B$22*(C2/Dau_vao!$B$19)+Dau_vao!$B$23*(C2/Dau_vao!$B$19)^2-Dau_vao!$B$24*(C2/Dau_vao!$B$19)^3) -> 31.210278 | G2: =60000*F2/(2*PI()*C2) -> 372.54525 | H2: =G2*Thiet_ke!$B$15*B2*Dau_vao!$B$10/Thiet_ke!$B$7 -> 21552.142 | I2: =IF(D2<=Dau_vao!$B$14,Dau_vao!$B$13,Dau_vao!$B$13*(1+D2^2/1500)) -> 0.015 | J2: =Thiet_ke!$B$8*D2^2 -> 4.8587019 | K2: =Thiet_ke!$B$3*I2+J2 -> 1136.4422 | L2: =(H2-J2)/Thiet_ke!$B$3 -> 0.28562563 | M2: =1.05+0.05*B2^2 -> 3.5 | N2: =(MIN(H2,Thiet_ke!$B$16)-K2)/(Thiet_ke!$B$2*M2) -> 0.75852499 | O2: =IF(N2>0,1/N2,"") -> 1.3183481
A3: 1 | B3: =Thiet_ke!$B$20 -> 7 | C3: =Dau_vao!$B$21+(Dau_vao!$B$19-Dau_vao!$B$21)*1/200 -> 809 | D3: =2*PI()*C3*Thiet_ke!$B$7/(60*Thiet_ke!$B$15*B3) -> 1.303334 | E3: =D3*3.6 -> 4.6920024 | F3: =Thiet_ke!$B$12*(Dau_vao!$B$22*(C3/Dau_vao!$B$19)+Dau_vao!$B$23*(C3/Dau_vao!$B$19)^2-Dau_vao!$B$24*(C3/Dau_vao!$B$19)^3) -> 31.672445 | G3: =60000*F3/(2*PI()*C3) -> 373.85609 | H3: =G3*Thiet_ke!$B$15*B3*Dau_vao!$B$10/Thiet_ke!$B$7 -> 21627.976 | I3: =IF(D3<=Dau_vao!$B$14,Dau_vao!$B$13,Dau_vao!$B$13*(1+D3^2/1500)) -> 0.015 | J3: =Thiet_ke!$B$8*D3^2 -> 4.9686377 | K3: =Thiet_ke!$B$3*I3+J3 -> 1136.5521 | L3: =(H3-J3)/Thiet_ke!$B$3 -> 0.28662941 | M3: =1.05+0.05*B3^2 -> 3.5 | N3: =(MIN(H3,Thiet_ke!$B$16)-K3)/(Thiet_ke!$B$2*M3) -> 0.76133842 | O3: =IF(N3>0,1/N3,"") -> 1.3134763
A4: 1 | B4: =Thiet_ke!$B$20 -> 7 | C4: =Dau_vao!$B$21+(Dau_vao!$B$19-Dau_vao!$B$21)*2/200 -> 818 | D4: =2*PI()*C4*Thiet_ke!$B$7/(60*Thiet_ke!$B$15*B4) -> 1.3178334 | E4: =D4*3.6 -> 4.7442002 | F4: =Thiet_ke!$B$12*(Dau_vao!$B$22*(C4/Dau_vao!$B$19)+Dau_vao!$B$23*(C4/Dau_vao!$B$19)^2-Dau_vao!$B$24*(C4/Dau_vao!$B$19)^3) -> 32.136202 | G4: =60000*F4/(2*PI()*C4) -> 375.15663 | H4: =G4*Thiet_ke!$B$15*B4*Dau_vao!$B$10/Thiet_ke!$B$7 -> 21703.213 | I4: =IF(D4<=Dau_vao!$B$14,Dau_vao!$B$13,Dau_vao!$B$13*(1+D4^2/1500)) -> 0.015 | J4: =Thiet_ke!$B$8*D4^2 -> 5.0798033 | K4: =Thiet_ke!$B$3*I4+J4 -> 1136.6633 | L4: =(H4-J4)/Thiet_ke!$B$3 -> 0.28762526 | M4: =1.05+0.05*B4^2 -> 3.5 | N4: =(MIN(H4,Thiet_ke!$B$16)-K4)/(Thiet_ke!$B$2*M4) -> 0.76412967 | O4: =IF(N4>0,1/N4,"") -> 1.3086784
A5: 1 | B5: =Thiet_ke!$B$20 -> 7 | C5: =Dau_vao!$B$21+(Dau_vao!$B$19-Dau_vao!$B$21)*3/200 -> 827 | D5: =2*PI()*C5*Thiet_ke!$B$7/(60*Thiet_ke!$B$15*B5) -> 1.3323328 | E5: =D5*3.6 -> 4.796398 | F5: =Thiet_ke!$B$12*(Dau_vao!$B$22*(C5/Dau_vao!$B$19)+Dau_vao!$B$23*(C5/Dau_vao!$B$19)^2-Dau_vao!$B$24*(C5/Dau_vao!$B$19)^3) -> 32.601517 | G5: =60000*F5/(2*PI()*C5) -> 376.44687 | H5: =G5*Thiet_ke!$B$15*B5*Dau_vao!$B$10/Thiet_ke!$B$7 -> 21777.855 | I5: =IF(D5<=Dau_vao!$B$14,Dau_vao!$B$13,Dau_vao!$B$13*(1+D5^2/1500)) -> 0.015 | J5: =Thiet_ke!$B$8*D5^2 -> 5.1921987 | K5: =Thiet_ke!$B$3*I5+J5 -> 1136.7757 | L5: =(H5-J5)/Thiet_ke!$B$3 -> 0.28861321 | M5: =1.05+0.05*B5^2 -> 3.5 | N5: =(MIN(H5,Thiet_ke!$B$16)-K5)/(Thiet_ke!$B$2*M5) -> 0.76689873 | O5: =IF(N5>0,1/N5,"") -> 1.3039531
A6: 1 | B6: =Thiet_ke!$B$20 -> 7 | C6: =Dau_vao!$B$21+(Dau_vao!$B$19-Dau_vao!$B$21)*4/200 -> 836 | D6: =2*PI()*C6*Thiet_ke!$B$7/(60*Thiet_ke!$B$15*B6) -> 1.3468322 | E6: =D6*3.6 -> 4.8485958 | F6: =Thiet_ke!$B$12*(Dau_vao!$B$22*(C6/Dau_vao!$B$19)+Dau_vao!$B$23*(C6/Dau_vao!$B$19)^2-Dau_vao!$B$24*(C6/Dau_vao!$B$19)^3) -> 33.068364 | G6: =60000*F6/(2*PI()*C6) -> 377.72681 | H6: =G6*Thiet_ke!$B$15*B6*Dau_vao!$B$10/Thiet_ke!$B$7 -> 21851.901 | I6: =IF(D6<=Dau_vao!$B$14,Dau_vao!$B$13,Dau_vao!$B$13*(1+D6^2/1500)) -> 0.015 | J6: =Thiet_ke!$B$8*D6^2 -> 5.305824 | K6: =Thiet_ke!$B$3*I6+J6 -> 1136.8893 | L6: =(H6-J6)/Thiet_ke!$B$3 -> 0.28959324 | M6: =1.05+0.05*B6^2 -> 3.5 | N6: =(MIN(H6,Thiet_ke!$B$16)-K6)/(Thiet_ke!$B$2*M6) -> 0.76964562 | O6: =IF(N6>0,1/N6,"") -> 1.2992993
A7: 1 | B7: =Thiet_ke!$B$20 -> 7 | C7: =Dau_vao!$B$21+(Dau_vao!$B$19-Dau_vao!$B$21)*5/200 -> 845 | D7: =2*PI()*C7*Thiet_ke!$B$7/(60*Thiet_ke!$B$15*B7) -> 1.3613316 | E7: =D7*3.6 -> 4.9007937 | F7: =Thiet_ke!$B$12*(Dau_vao!$B$22*(C7/Dau_vao!$B$19)+Dau_vao!$B$23*(C7/Dau_vao!$B$19)^2-Dau_vao!$B$24*(C7/Dau_vao!$B$19)^3) -> 33.536711 | G7: =60000*F7/(2*PI()*C7) -> 378.99645 | H7: =G7*Thiet_ke!$B$15*B7*Dau_vao!$B$10/Thiet_ke!$B$7 -> 21925.351 | I7: =IF(D7<=Dau_vao!$B$14,Dau_vao!$B$13,Dau_vao!$B$13*(1+D7^2/1500)) -> 0.015 | J7: =Thiet_ke!$B$8*D7^2 -> 5.4206792 | K7: =Thiet_ke!$B$3*I7+J7 -> 1137.0042 | L7: =(H7-J7)/Thiet_ke!$B$3 -> 0.29056535 | M7: =1.05+0.05*B7^2 -> 3.5 | N7: =(MIN(H7,Thiet_ke!$B$16)-K7)/(Thiet_ke!$B$2*M7) -> 0.77237032 | O7: =IF(N7>0,1/N7,"") -> 1.2947157
A8: 1 | B8: =Thiet_ke!$B$20 -> 7 | C8: =Dau_vao!$B$21+(Dau_vao!$B$19-Dau_vao!$B$21)*6/200 -> 854 | D8: =2*PI()*C8*Thiet_ke!$B$7/(60*Thiet_ke!$B$15*B8) -> 1.375831 | E8: =D8*3.6 -> 4.9529915 | F8: =Thiet_ke!$B$12*(Dau_vao!$B$22*(C8/Dau_vao!$B$19)+Dau_vao!$B$23*(C8/Dau_vao!$B$19)^2-Dau_vao!$B$24*(C8/Dau_vao!$B$19)^3) -> 34.006531 | G8: =60000*F8/(2*PI()*C8) -> 380.25579 | H8: =G8*Thiet_ke!$B$15*B8*Dau_vao!$B$10/Thiet_ke!$B$7 -> 21998.206 | I8: =IF(D8<=Dau_vao!$B$14,Dau_vao!$B$13,Dau_vao!$B$13*(1+D8^2/1500)) -> 0.015 | J8: =Thiet_ke!$B$8*D8^2 -> 5.5367642 | K8: =Thiet_ke!$B$3*I8+J8 -> 1137.1203 | L8: =(H8-J8)/Thiet_ke!$B$3 -> 0.29152955 | M8: =1.05+0.05*B8^2 -> 3.5 | N8: =(MIN(H8,Thiet_ke!$B$16)-K8)/(Thiet_ke!$B$2*M8) -> 0.77507283 | O8: =IF(N8>0,1/N8,"") -> 1.2902013
A9: 1 | B9: =Thiet_ke!$B$20 -> 7 | C9: =Dau_vao!$B$21+(Dau_vao!$B$19-Dau_vao!$B$21)*7/200 -> 863 | D9: =2*PI()*C9*Thiet_ke!$B$7/(60*Thiet_ke!$B$15*B9) -> 1.3903303 | E9: =D9*3.6 -> 5.0051893 | F9: =Thiet_ke!$B$12*(Dau_vao!$B$22*(C9/Dau_vao!$B$19)+Dau_vao!$B$23*(C9/Dau_vao!$B$19)^2-Dau_vao!$B$24*(C9/Dau_vao!$B$19)^3) -> 34.477793 | G9: =60000*F9/(2*PI()*C9) -> 381.50484 | H9: =G9*Thiet_ke!$B$15*B9*Dau_vao!$B$10/Thiet_ke!$B$7 -> 22070.464 | I9: =IF(D9<=Dau_vao!$B$14,Dau_vao!$B$13,Dau_vao!$B$13*(1+D9^2/1500)) -> 0.015 | J9: =Thiet_ke!$B$8*D9^2 -> 5.654079 | K9: =Thiet_ke!$B$3*I9+J9 -> 1137.2376 | L9: =(H9-J9)/Thiet_ke!$B$3 -> 0.29248584 | M9: =1.05+0.05*B9^2 -> 3.5 | N9: =(MIN(H9,Thiet_ke!$B$16)-K9)/(Thiet_ke!$B$2*M9) -> 0.77775317 | O9: =IF(N9>0,1/N9,"") -> 1.285755
A10: 1 | B10: =Thiet_ke!$B$20 -> 7 | C10: =Dau_vao!$B$21+(Dau_vao!$B$19-Dau_vao!$B$21)*8/200 -> 872 | D10: =2*PI()*C10*Thiet_ke!$B$7/(60*Thiet_ke!$B$15*B10) -> 1.4048297 | E10: =D10*3.6 -> 5.0573871 | F10: =Thiet_ke!$B$12*(Dau_vao!$B$22*(C10/Dau_vao!$B$19)+Dau_vao!$B$23*(C10/Dau_vao!$B$19)^2-Dau_vao!$B$24*(C10/Dau_vao!$B$19)^3) -> 34.95047 | G10: =60000*F10/(2*PI()*C10) -> 382.74358 | H10: =G10*Thiet_ke!$B$15*B10*Dau_vao!$B$10/Thiet_ke!$B$7 -> 22142.127 | I10: =IF(D10<=Dau_vao!$B$14,Dau_vao!$B$13,Dau_vao!$B$13*(1+D10^2/1500)) -> 0.015 | J10: =Thiet_ke!$B$8*D10^2 -> 5.7726238 | K10: =Thiet_ke!$B$3*I10+J10 -> 1137.3561 | L10: =(H10-J10)/Thiet_ke!$B$3 -> 0.29343421 | M10: =1.05+0.05*B10^2 -> 3.5 | N10: =(MIN(H10,Thiet_ke!$B$16)-K10)/(Thiet_ke!$B$2*M10) -> 0.78041132 | O10: =IF(N10>0,1/N10,"") -> 1.2813756
A11: 1 | B11: =Thiet_ke!$B$20 -> 7 | C11: =Dau_vao!$B$21+(Dau_vao!$B$19-Dau_vao!$B$21)*9/200 -> 881 | D11: =2*PI()*C11*Thiet_ke!$B$7/(60*Thiet_ke!$B$15*B11) -> 1.4193291 | E11: =D11*3.6 -> 5.1095849 | F11: =Thiet_ke!$B$12*(Dau_vao!$B$22*(C11/Dau_vao!$B$19)+Dau_vao!$B$23*(C11/Dau_vao!$B$19)^2-Dau_vao!$B$24*(C11/Dau_vao!$B$19)^3) -> 35.424531 | G11: =60000*F11/(2*PI()*C11) -> 383.97203 | H11: =G11*Thiet_ke!$B$15*B11*Dau_vao!$B$10/Thiet_ke!$B$7 -> 22213.194 | I11: =IF(D11<=Dau_vao!$B$14,Dau_vao!$B$13,Dau_vao!$B$13*(1+D11^2/1500)) -> 0.015 | J11: =Thiet_ke!$B$8*D11^2 -> 5.8923984 | K11: =Thiet_ke!$B$3*I11+J11 -> 1137.4759 | L11: =(H11-J11)/Thiet_ke!$B$3 -> 0.29437467 | M11: =1.05+0.05*B11^2 -> 3.5 | N11: =(MIN(H11,Thiet_ke!$B$16)-K11)/(Thiet_ke!$B$2*M11) -> 0.78304729 | O11: =IF(N11>0,1/N11,"") -> 1.2770621
A12: 1 | B12: =Thiet_ke!$B$20 -> 7 | C12: =Dau_vao!$B$21+(Dau_vao!$B$19-Dau_vao!$B$21)*10/200 -> 890 | D12: =2*PI()*C12*Thiet_ke!$B$7/(60*Thiet_ke!$B$15*B12) -> 1.4338285 | E12: =D12*3.6 -> 5.1617827 | F12: =Thiet_ke!$B$12*(Dau_vao!$B$22*(C12/Dau_vao!$B$19)+Dau_vao!$B$23*(C12/Dau_vao!$B$19)^2-Dau_vao!$B$24*(C12/Dau_vao!$B$19)^3) -> 35.899948 | G12: =60000*F12/(2*PI()*C12) -> 385.19017 | H12: =G12*Thiet_ke!$B$15*B12*Dau_vao!$B$10/Thiet_ke!$B$7 -> 22283.665 | I12: =IF(D12<=Dau_vao!$B$14,Dau_vao!$B$13,Dau_vao!$B$13*(1+D12^2/1500)) -> 0.015 | J12: =Thiet_ke!$B$8*D12^2 -> 6.0134028 | K12: =Thiet_ke!$B$3*I12+J12 -> 1137.5969 | L12: =(H12-J12)/Thiet_ke!$B$3 -> 0.29530721 | M12: =1.05+0.05*B12^2 -> 3.5 | N12: =(MIN(H12,Thiet_ke!$B$16)-K12)/(Thiet_ke!$B$2*M12) -> 0.78566108 | O12: =IF(N12>0,1/N12,"") -> 1.2728135
A13: 1 | B13: =Thiet_ke!$B$20 -> 7 | C13: =Dau_vao!$B$21+(Dau_vao!$B$19-Dau_vao!$B$21)*11/200 -> 899 | D13: =2*PI()*C13*Thiet_ke!$B$7/(60*Thiet_ke!$B$15*B13) -> 1.4483279 | E13: =D13*3.6 -> 5.2139805 | F13: =Thiet_ke!$B$12*(Dau_vao!$B$22*(C13/Dau_vao!$B$19)+Dau_vao!$B$23*(C13/Dau_vao!$B$19)^2-Dau_vao!$B$24*(C13/Dau_vao!$B$19)^3) -> 36.376692 | G13: =60000*F13/(2*PI()*C13) -> 386.39802 | H13: =G13*Thiet_ke!$B$15*B13*Dau_vao!$B$10/Thiet_ke!$B$7 -> 22353.54 | I13: =IF(D13<=Dau_vao!$B$14,Dau_vao!$B$13,Dau_vao!$B$13*(1+D13^2/1500)) -> 0.015 | J13: =Thiet_ke!$B$8*D13^2 -> 6.1356371 | K13: =Thiet_ke!$B$3*I13+J13 -> 1137.7191 | L13: =(H13-J13)/Thiet_ke!$B$3 -> 0.29623184 | M13: =1.05+0.05*B13^2 -> 3.5 | N13: =(MIN(H13,Thiet_ke!$B$16)-K13)/(Thiet_ke!$B$2*M13) -> 0.78825268 | O13: =IF(N13>0,1/N13,"") -> 1.2686287
A14: 1 | B14: =Thiet_ke!$B$20 -> 7 | C14: =Dau_vao!$B$21+(Dau_vao!$B$19-Dau_vao!$B$21)*12/200 -> 908 | D14: =2*PI()*C14*Thiet_ke!$B$7/(60*Thiet_ke!$B$15*B14) -> 1.4628273 | E14: =D14*3.6 -> 5.2661783 | F14: =Thiet_ke!$B$12*(Dau_vao!$B$22*(C14/Dau_vao!$B$19)+Dau_vao!$B$23*(C14/Dau_vao!$B$19)^2-Dau_vao!$B$24*(C14/Dau_vao!$B$19)^3) -> 36.854733 | G14: =60000*F14/(2*PI()*C14) -> 387.59557 | H14: =G14*Thiet_ke!$B$15*B14*Dau_vao!$B$10/Thiet_ke!$B$7 -> 22422.82 | I14: =IF(D14<=Dau_vao!$B$14,Dau_vao!$B$13,Dau_vao!$B$13*(1+D14^2/1500)) -> 0.015 | J14: =Thiet_ke!$B$8*D14^2 -> 6.2591013 | K14: =Thiet_ke!$B$3*I14+J14 -> 1137.8426 | L14: =(H14-J14)/Thiet_ke!$B$3 -> 0.29714856 | M14: =1.05+0.05*B14^2 -> 3.5 | N14: =(MIN(H14,Thiet_ke!$B$16)-K14)/(Thiet_ke!$B$2*M14) -> 0.7908221 | O14: =IF(N14>0,1/N14,"") -> 1.2645069
A15: 1 | B15: =Thiet_ke!$B$20 -> 7 | C15: =Dau_vao!$B$21+(Dau_vao!$B$19-Dau_vao!$B$21)*13/200 -> 917 | D15: =2*PI()*C15*Thiet_ke!$B$7/(60*Thiet_ke!$B$15*B15) -> 1.4773267 | E15: =D15*3.6 -> 5.3183761 | F15: =Thiet_ke!$B$12*(Dau_vao!$B$22*(C15/Dau_vao!$B$19)+Dau_vao!$B$23*(C15/Dau_vao!$B$19)^2-Dau_vao!$B$24*(C15/Dau_vao!$B$19)^3) -> 37.334043 | G15: =60000*F15/(2*PI()*C15) -> 388.78282 | H15: =G15*Thiet_ke!$B$15*B15*Dau_vao!$B$10/Thiet_ke!$B$7 -> 22491.503 | I15: =IF(D15<=Dau_vao!$B$14,Dau_vao!$B$13,Dau_vao!$B$13*(1+D15^2/1500)) -> 0.015 | J15: =Thiet_ke!$B$8*D15^2 -> 6.3837953 | K15: =Thiet_ke!$B$3*I15+J15 -> 1137.9673 | L15: =(H15-J15)/Thiet_ke!$B$3 -> 0.29805736 | M15: =1.05+0.05*B15^2 -> 3.5 | N15: =(MIN(H15,Thiet_ke!$B$16)-K15)/(Thiet_ke!$B$2*M15) -> 0.79336934 | O15: =IF(N15>0,1/N15,"") -> 1.260447
A16: 1 | B16: =Thiet_ke!$B$20 -> 7 | C16: =Dau_vao!$B$21+(Dau_vao!$B$19-Dau_vao!$B$21)*14/200 -> 926 | D16: =2*PI()*C16*Thiet_ke!$B$7/(60*Thiet_ke!$B$15*B16) -> 1.4918261 | E16: =D16*3.6 -> 5.3705739 | F16: =Thiet_ke!$B$12*(Dau_vao!$B$22*(C16/Dau_vao!$B$19)+Dau_vao!$B$23*(C16/Dau_vao!$B$19)^2-Dau_vao!$B$24*(C16/Dau_vao!$B$19)^3) -> 37.814591 | G16: =60000*F16/(2*PI()*C16) -> 389.95977 | H16: =G16*Thiet_ke!$B$15*B16*Dau_vao!$B$10/Thiet_ke!$B$7 -> 22559.591 | I16: =IF(D16<=Dau_vao!$B$14,Dau_vao!$B$13,Dau_vao!$B$13*(1+D16^2/1500)) -> 0.015 | J16: =Thiet_ke!$B$8*D16^2 -> 6.5097192 | K16: =Thiet_ke!$B$3*I16+J16 -> 1138.0932 | L16: =(H16-J16)/Thiet_ke!$B$3 -> 0.29895825 | M16: =1.05+0.05*B16^2 -> 3.5 | N16: =(MIN(H16,Thiet_ke!$B$16)-K16)/(Thiet_ke!$B$2*M16) -> 0.7958944 | O16: =IF(N16>0,1/N16,"") -> 1.2564481
A17: 1 | B17: =Thiet_ke!$B$20 -> 7 | C17: =Dau_vao!$B$21+(Dau_vao!$B$19-Dau_vao!$B$21)*15/200 -> 935 | D17: =2*PI()*C17*Thiet_ke!$B$7/(60*Thiet_ke!$B$15*B17) -> 1.5063255 | E17: =D17*3.6 -> 5.4227717 | F17: =Thiet_ke!$B$12*(Dau_vao!$B$22*(C17/Dau_vao!$B$19)+Dau_vao!$B$23*(C17/Dau_vao!$B$19)^2-Dau_vao!$B$24*(C17/Dau_vao!$B$19)^3) -> 38.29635 | G17: =60000*F17/(2*PI()*C17) -> 391.12642 | H17: =G17*Thiet_ke!$B$15*B17*Dau_vao!$B$10/Thiet_ke!$B$7 -> 22627.083 | I17: =IF(D17<=Dau_vao!$B$14,Dau_vao!$B$13,Dau_vao!$B$13*(1+D17^2/1500)) -> 0.015 | J17: =Thiet_ke!$B$8*D17^2 -> 6.636873 | K17: =Thiet_ke!$B$3*I17+J17 -> 1138.2204 | L17: =(H17-J17)/Thiet_ke!$B$3 -> 0.29985122 | M17: =1.05+0.05*B17^2 -> 3.5 | N17: =(MIN(H17,Thiet_ke!$B$16)-K17)/(Thiet_ke!$B$2*M17) -> 0.79839728 | O17: =IF(N17>0,1/N17,"") -> 1.2525093
A18: 1 | B18: =Thiet_ke!$B$20 -> 7 | C18: =Dau_vao!$B$21+(Dau_vao!$B$19-Dau_vao!$B$21)*16/200 -> 944 | D18: =2*PI()*C18*Thiet_ke!$B$7/(60*Thiet_ke!$B$15*B18) -> 1.5208249 | E18: =D18*3.6 -> 5.4749695 | F18: =Thiet_ke!$B$12*(Dau_vao!$B$22*(C18/Dau_vao!$B$19)+Dau_vao!$B$23*(C18/Dau_vao!$B$19)^2-Dau_vao!$B$24*(C18/Dau_vao!$B$19)^3) -> 38.77929 | G18: =60000*F18/(2*PI()*C18) -> 392.28277 | H18: =G18*Thiet_ke!$B$15*B18*Dau_vao!$B$10/Thiet_ke!$B$7 -> 22693.979 | I18: =IF(D18<=Dau_vao!$B$14,Dau_vao!$B$13,Dau_vao!$B$13*(1+D18^2/1500)) -> 0.015 | J18: =Thiet_ke!$B$8*D18^2 -> 6.7652566 | K18: =Thiet_ke!$B$3*I18+J18 -> 1138.3488 | L18: =(H18-J18)/Thiet_ke!$B$3 -> 0.30073628 | M18: =1.05+0.05*B18^2 -> 3.5 | N18: =(MIN(H18,Thiet_ke!$B$16)-K18)/(Thiet_ke!$B$2*M18) -> 0.80087797 | O18: =IF(N18>0,1/N18,"") -> 1.2486297
A19: 1 | B19: =Thiet_ke!$B$20 -> 7 | C19: =Dau_vao!$B$21+(Dau_vao!$B$19-Dau_vao!$B$21)*17/200 -> 953 | D19: =2*PI()*C19*Thiet_ke!$B$7/(60*Thiet_ke!$B$15*B19) -> 1.5353242 | E19: =D19*3.6 -> 5.5271673 | F19: =Thiet_ke!$B$12*(Dau_vao!$B$22*(C19/Dau_vao!$B$19)+Dau_vao!$B$23*(C19/Dau_vao!$B$19)^2-Dau_vao!$B$24*(C19/Dau_vao!$B$19)^3) -> 39.263381 | G19: =60000*F19/(2*PI()*C19) -> 393.42883 | H19: =G19*Thiet_ke!$B$15*B19*Dau_vao!$B$10/Thiet_ke!$B$7 -> 22760.28 | I19: =IF(D19<=Dau_vao!$B$14,Dau_vao!$B$13,Dau_vao!$B$13*(1+D19^2/1500)) -> 0.015 | J19: =Thiet_ke!$B$8*D19^2 -> 6.8948701 | K19: =Thiet_ke!$B$3*I19+J19 -> 1138.4784 | L19: =(H19-J19)/Thiet_ke!$B$3 -> 0.30161342 | M19: =1.05+0.05*B19^2 -> 3.5 | N19: =(MIN(H19,Thiet_ke!$B$16)-K19)/(Thiet_ke!$B$2*M19) -> 0.80333648 | O19: =IF(N19>0,1/N19,"") -> 1.2448084
A20: 1 | B20: =Thiet_ke!$B$20 -> 7 | C20: =Dau_vao!$B$21+(Dau_vao!$B$19-Dau_vao!$B$21)*18/200 -> 962 | D20: =2*PI()*C20*Thiet_ke!$B$7/(60*Thiet_ke!$B$15*B20) -> 1.5498236 | E20: =D20*3.6 -> 5.5793651 | F20: =Thiet_ke!$B$12*(Dau_vao!$B$22*(C20/Dau_vao!$B$19)+Dau_vao!$B$23*(C20/Dau_vao!$B$19)^2-Dau_vao!$B$24*(C20/Dau_vao!$B$19)^3) -> 39.748596 | G20: =60000*F20/(2*PI()*C20) -> 394.56458 | H20: =G20*Thiet_ke!$B$15*B20*Dau_vao!$B$10/Thiet_ke!$B$7 -> 22825.984 | I20: =IF(D20<=Dau_vao!$B$14,Dau_vao!$B$13,Dau_vao!$B$13*(1+D20^2/1500)) -> 0.015 | J20: =Thiet_ke!$B$8*D20^2 -> 7.0257134 | K20: =Thiet_ke!$B$3*I20+J20 -> 1138.6092 | L20: =(H20-J20)/Thiet_ke!$B$3 -> 0.30248265 | M20: =1.05+0.05*B20^2 -> 3.5 | N20: =(MIN(H20,Thiet_ke!$B$16)-K20)/(Thiet_ke!$B$2*M20) -> 0.80577281 | O20: =IF(N20>0,1/N20,"") -> 1.2410446
A21: 1 | B21: =Thiet_ke!$B$20 -> 7 | C21: =Dau_vao!$B$21+(Dau_vao!$B$19-Dau_vao!$B$21)*19/200 -> 971 | D21: =2*PI()*C21*Thiet_ke!$B$7/(60*Thiet_ke!$B$15*B21) -> 1.564323 | E21: =D21*3.6 -> 5.6315629 | F21: =Thiet_ke!$B$12*(Dau_vao!$B$22*(C21/Dau_vao!$B$19)+Dau_vao!$B$23*(C21/Dau_vao!$B$19)^2-Dau_vao!$B$24*(C21/Dau_vao!$B$19)^3) -> 40.234903 | G21: =60000*F21/(2*PI()*C21) -> 395.69004 | H21: =G21*Thiet_ke!$B$15*B21*Dau_vao!$B$10/Thiet_ke!$B$7 -> 22891.093 | I21: =IF(D21<=Dau_vao!$B$14,Dau_vao!$B$13,Dau_vao!$B$13*(1+D21^2/1500)) -> 0.015 | J21: =Thiet_ke!$B$8*D21^2 -> 7.1577866 | K21: =Thiet_ke!$B$3*I21+J21 -> 1138.7413 | L21: =(H21-J21)/Thiet_ke!$B$3 -> 0.30334397 | M21: =1.05+0.05*B21^2 -> 3.5 | N21: =(MIN(H21,Thiet_ke!$B$16)-K21)/(Thiet_ke!$B$2*M21) -> 0.80818695 | O21: =IF(N21>0,1/N21,"") -> 1.2373375
A22: 1 | B22: =Thiet_ke!$B$20 -> 7 | C22: =Dau_vao!$B$21+(Dau_vao!$B$19-Dau_vao!$B$21)*20/200 -> 980 | D22: =2*PI()*C22*Thiet_ke!$B$7/(60*Thiet_ke!$B$15*B22) -> 1.5788224 | E22: =D22*3.6 -> 5.6837607 | F22: =Thiet_ke!$B$12*(Dau_vao!$B$22*(C22/Dau_vao!$B$19)+Dau_vao!$B$23*(C22/Dau_vao!$B$19)^2-Dau_vao!$B$24*(C22/Dau_vao!$B$19)^3) -> 40.722276 | G22: =60000*F22/(2*PI()*C22) -> 396.80519 | H22: =G22*Thiet_ke!$B$15*B22*Dau_vao!$B$10/Thiet_ke!$B$7 -> 22955.606 | I22: =IF(D22<=Dau_vao!$B$14,Dau_vao!$B$13,Dau_vao!$B$13*(1+D22^2/1500)) -> 0.015 | J22: =Thiet_ke!$B$8*D22^2 -> 7.2910896 | K22: =Thiet_ke!$B$3*I22+J22 -> 1138.8746 | L22: =(H22-J22)/Thiet_ke!$B$3 -> 0.30419737 | M22: =1.05+0.05*B22^2 -> 3.5 | N22: =(MIN(H22,Thiet_ke!$B$16)-K22)/(Thiet_ke!$B$2*M22) -> 0.81057892 | O22: =IF(N22>0,1/N22,"") -> 1.2336862
A23: 1 | B23: =Thiet_ke!$B$20 -> 7 | C23: =Dau_vao!$B$21+(Dau_vao!$B$19-Dau_vao!$B$21)*21/200 -> 989 | D23: =2*PI()*C23*Thiet_ke!$B$7/(60*Thiet_ke!$B$15*B23) -> 1.5933218 | E23: =D23*3.6 -> 5.7359585 | F23: =Thiet_ke!$B$12*(Dau_vao!$B$22*(C23/Dau_vao!$B$19)+Dau_vao!$B$23*(C23/Dau_vao!$B$19)^2-Dau_vao!$B$24*(C23/Dau_vao!$B$19)^3) -> 41.210684 | G23: =60000*F23/(2*PI()*C23) -> 397.91005 | H23: =G23*Thiet_ke!$B$15*B23*Dau_vao!$B$10/Thiet_ke!$B$7 -> 23019.523 | I23: =IF(D23<=Dau_vao!$B$14,Dau_vao!$B$13,Dau_vao!$B$13*(1+D23^2/1500)) -> 0.015 | J23: =Thiet_ke!$B$8*D23^2 -> 7.4256225 | K23: =Thiet_ke!$B$3*I23+J23 -> 1139.0091 | L23: =(H23-J23)/Thiet_ke!$B$3 -> 0.30504286 | M23: =1.05+0.05*B23^2 -> 3.5 | N23: =(MIN(H23,Thiet_ke!$B$16)-K23)/(Thiet_ke!$B$2*M23) -> 0.8129487 | O23: =IF(N23>0,1/N23,"") -> 1.2300899
A24: 1 | B24: =Thiet_ke!$B$20 -> 7 | C24: =Dau_vao!$B$21+(Dau_vao!$B$19-Dau_vao!$B$21)*22/200 -> 998 | D24: =2*PI()*C24*Thiet_ke!$B$7/(60*Thiet_ke!$B$15*B24) -> 1.6078212 | E24: =D24*3.6 -> 5.7881563 | F24: =Thiet_ke!$B$12*(Dau_vao!$B$22*(C24/Dau_vao!$B$19)+Dau_vao!$B$23*(C24/Dau_vao!$B$19)^2-Dau_vao!$B$24*(C24/Dau_vao!$B$19)^3) -> 41.700098 | G24: =60000*F24/(2*PI()*C24) -> 399.00461 | H24: =G24*Thiet_ke!$B$15*B24*Dau_vao!$B$10/Thiet_ke!$B$7 -> 23082.845 | I24: =IF(D24<=Dau_vao!$B$14,Dau_vao!$B$13,Dau_vao!$B$13*(1+D24^2/1500)) -> 0.015 | J24: =Thiet_ke!$B$8*D24^2 -> 7.5613853 | K24: =Thiet_ke!$B$3*I24+J24 -> 1139.1449 | L24: =(H24-J24)/Thiet_ke!$B$3 -> 0.30588043 | M24: =1.05+0.05*B24^2 -> 3.5 | N24: =(MIN(H24,Thiet_ke!$B$16)-K24)/(Thiet_ke!$B$2*M24) -> 0.8152963 | O24: =IF(N24>0,1/N24,"") -> 1.2265479
A25: 1 | B25: =Thiet_ke!$B$20 -> 7 | C25: =Dau_vao!$B$21+(Dau_vao!$B$19-Dau_vao!$B$21)*23/200 -> 1007 | D25: =2*PI()*C25*Thiet_ke!$B$7/(60*Thiet_ke!$B$15*B25) -> 1.6223206 | E25: =D25*3.6 -> 5.8403541 | F25: =Thiet_ke!$B$12*(Dau_vao!$B$22*(C25/Dau_vao!$B$19)+Dau_vao!$B$23*(C25/Dau_vao!$B$19)^2-Dau_vao!$B$24*(C25/Dau_vao!$B$19)^3) -> 42.190489 | G25: =60000*F25/(2*PI()*C25) -> 400.08887 | H25: =G25*Thiet_ke!$B$15*B25*Dau_vao!$B$10/Thiet_ke!$B$7 -> 23145.57 | I25: =IF(D25<=Dau_vao!$B$14,Dau_vao!$B$13,Dau_vao!$B$13*(1+D25^2/1500)) -> 0.015 | J25: =Thiet_ke!$B$8*D25^2 -> 7.6983779 | K25: =Thiet_ke!$B$3*I25+J25 -> 1139.2819 | L25: =(H25-J25)/Thiet_ke!$B$3 -> 0.30671009 | M25: =1.05+0.05*B25^2 -> 3.5 | N25: =(MIN(H25,Thiet_ke!$B$16)-K25)/(Thiet_ke!$B$2*M25) -> 0.81762171 | O25: =IF(N25>0,1/N25,"") -> 1.2230595
A26: 1 | B26: =Thiet_ke!$B$20 -> 7 | C26: =Dau_vao!$B$21+(Dau_vao!$B$19-Dau_vao!$B$21)*24/200 -> 1016 | D26: =2*PI()*C26*Thiet_ke!$B$7/(60*Thiet_ke!$B$15*B26) -> 1.63682 | E26: =D26*3.6 -> 5.8925519 | F26: =Thiet_ke!$B$12*(Dau_vao!$B$22*(C26/Dau_vao!$B$19)+Dau_vao!$B$23*(C26/Dau_vao!$B$19)^2-Dau_vao!$B$24*(C26/Dau_vao!$B$19)^3) -> 42.681828 | G26: =60000*F26/(2*PI()*C26) -> 401.16283 | H26: =G26*Thiet_ke!$B$15*B26*Dau_vao!$B$10/Thiet_ke!$B$7 -> 23207.7 | I26: =IF(D26<=Dau_vao!$B$14,Dau_vao!$B$13,Dau_vao!$B$13*(1+D26^2/1500)) -> 0.015 | J26: =Thiet_ke!$B$8*D26^2 -> 7.8366004 | K26: =Thiet_ke!$B$3*I26+J26 -> 1139.4201 | L26: =(H26-J26)/Thiet_ke!$B$3 -> 0.30753184 | M26: =1.05+0.05*B26^2 -> 3.5 | N26: =(MIN(H26,Thiet_ke!$B$16)-K26)/(Thiet_ke!$B$2*M26) -> 0.81992495 | O26: =IF(N26>0,1/N26,"") -> 1.2196238
A27: 1 | B27: =Thiet_ke!$B$20 -> 7 | C27: =Dau_vao!$B$21+(Dau_vao!$B$19-Dau_vao!$B$21)*25/200 -> 1025 | D27: =2*PI()*C27*Thiet_ke!$B$7/(60*Thiet_ke!$B$15*B27) -> 1.6513194 | E27: =D27*3.6 -> 5.9447497 | F27: =Thiet_ke!$B$12*(Dau_vao!$B$22*(C27/Dau_vao!$B$19)+Dau_vao!$B$23*(C27/Dau_vao!$B$19)^2-Dau_vao!$B$24*(C27/Dau_vao!$B$19)^3) -> 43.174086 | G27: =60000*F27/(2*PI()*C27) -> 402.22649 | H27: =G27*Thiet_ke!$B$15*B27*Dau_vao!$B$10/Thiet_ke!$B$7 -> 23269.234 | I27: =IF(D27<=Dau_vao!$B$14,Dau_vao!$B$13,Dau_vao!$B$13*(1+D27^2/1500)) -> 0.015 | J27: =Thiet_ke!$B$8*D27^2 -> 7.9760527 | K27: =Thiet_ke!$B$3*I27+J27 -> 1139.5596 | L27: =(H27-J27)/Thiet_ke!$B$3 -> 0.30834567 | M27: =1.05+0.05*B27^2 -> 3.5 | N27: =(MIN(H27,Thiet_ke!$B$16)-K27)/(Thiet_ke!$B$2*M27) -> 0.822206 | O27: =IF(N27>0,1/N27,"") -> 1.2162402
A28: 1 | B28: =Thiet_ke!$B$20 -> 7 | C28: =Dau_vao!$B$21+(Dau_vao!$B$19-Dau_vao!$B$21)*26/200 -> 1034 | D28: =2*PI()*C28*Thiet_ke!$B$7/(60*Thiet_ke!$B$15*B28) -> 1.6658187 | E28: =D28*3.6 -> 5.9969475 | F28: =Thiet_ke!$B$12*(Dau_vao!$B$22*(C28/Dau_vao!$B$19)+Dau_vao!$B$23*(C28/Dau_vao!$B$19)^2-Dau_vao!$B$24*(C28/Dau_vao!$B$19)^3) -> 43.667234 | G28: =60000*F28/(2*PI()*C28) -> 403.27985 | H28: =G28*Thiet_ke!$B$15*B28*Dau_vao!$B$10/Thiet_ke!$B$7 -> 23330.172 | I28: =IF(D28<=Dau_vao!$B$14,Dau_vao!$B$13,Dau_vao!$B$13*(1+D28^2/1500)) -> 0.015 | J28: =Thiet_ke!$B$8*D28^2 -> 8.1167349 | K28: =Thiet_ke!$B$3*I28+J28 -> 1139.7002 | L28: =(H28-J28)/Thiet_ke!$B$3 -> 0.30915158 | M28: =1.05+0.05*B28^2 -> 3.5 | N28: =(MIN(H28,Thiet_ke!$B$16)-K28)/(Thiet_ke!$B$2*M28) -> 0.82446487 | O28: =IF(N28>0,1/N28,"") -> 1.212908
A29: 1 | B29: =Thiet_ke!$B$20 -> 7 | C29: =Dau_vao!$B$21+(Dau_vao!$B$19-Dau_vao!$B$21)*27/200 -> 1043 | D29: =2*PI()*C29*Thiet_ke!$B$7/(60*Thiet_ke!$B$15*B29) -> 1.6803181 | E29: =D29*3.6 -> 6.0491453 | F29: =Thiet_ke!$B$12*(Dau_vao!$B$22*(C29/Dau_vao!$B$19)+Dau_vao!$B$23*(C29/Dau_vao!$B$19)^2-Dau_vao!$B$24*(C29/Dau_vao!$B$19)^3) -> 44.161242 | G29: =60000*F29/(2*PI()*C29) -> 404.32292 | H29: =G29*Thiet_ke!$B$15*B29*Dau_vao!$B$10/Thiet_ke!$B$7 -> 23390.514 | I29: =IF(D29<=Dau_vao!$B$14,Dau_vao!$B$13,Dau_vao!$B$13*(1+D29^2/1500)) -> 0.015 | J29: =Thiet_ke!$B$8*D29^2 -> 8.258647 | K29: =Thiet_ke!$B$3*I29+J29 -> 1139.8421 | L29: =(H29-J29)/Thiet_ke!$B$3 -> 0.30994959 | M29: =1.05+0.05*B29^2 -> 3.5 | N29: =(MIN(H29,Thiet_ke!$B$16)-K29)/(Thiet_ke!$B$2*M29) -> 0.82670155 | O29: =IF(N29>0,1/N29,"") -> 1.2096264
A30: 1 | B30: =Thiet_ke!$B$20 -> 7 | C30: =Dau_vao!$B$21+(Dau_vao!$B$19-Dau_vao!$B$21)*28/200 -> 1052 | D30: =2*PI()*C30*Thiet_ke!$B$7/(60*Thiet_ke!$B$15*B30) -> 1.6948175 | E30: =D30*3.6 -> 6.1013431 | F30: =Thiet_ke!$B$12*(Dau_vao!$B$22*(C30/Dau_vao!$B$19)+Dau_vao!$B$23*(C30/Dau_vao!$B$19)^2-Dau_vao!$B$24*(C30/Dau_vao!$B$19)^3) -> 44.656082 | G30: =60000*F30/(2*PI()*C30) -> 405.35568 | H30: =G30*Thiet_ke!$B$15*B30*Dau_vao!$B$10/Thiet_ke!$B$7 -> 23450.261 | I30: =IF(D30<=Dau_vao!$B$14,Dau_vao!$B$13,Dau_vao!$B$13*(1+D30^2/1500)) -> 0.015 | J30: =Thiet_ke!$B$8*D30^2 -> 8.4017889 | K30: =Thiet_ke!$B$3*I30+J30 -> 1139.9853 | L30: =(H30-J30)/Thiet_ke!$B$3 -> 0.31073967 | M30: =1.05+0.05*B30^2 -> 3.5 | N30: =(MIN(H30,Thiet_ke!$B$16)-K30)/(Thiet_ke!$B$2*M30) -> 0.82891606 | O30: =IF(N30>0,1/N30,"") -> 1.2063948
A31: 1 | B31: =Thiet_ke!$B$20 -> 7 | C31: =Dau_vao!$B$21+(Dau_vao!$B$19-Dau_vao!$B$21)*29/200 -> 1061 | D31: =2*PI()*C31*Thiet_ke!$B$7/(60*Thiet_ke!$B$15*B31) -> 1.7093169 | E31: =D31*3.6 -> 6.1535409 | F31: =Thiet_ke!$B$12*(Dau_vao!$B$22*(C31/Dau_vao!$B$19)+Dau_vao!$B$23*(C31/Dau_vao!$B$19)^2-Dau_vao!$B$24*(C31/Dau_vao!$B$19)^3) -> 45.151725 | G31: =60000*F31/(2*PI()*C31) -> 406.37814 | H31: =G31*Thiet_ke!$B$15*B31*Dau_vao!$B$10/Thiet_ke!$B$7 -> 23509.412 | I31: =IF(D31<=Dau_vao!$B$14,Dau_vao!$B$13,Dau_vao!$B$13*(1+D31^2/1500)) -> 0.015 | J31: =Thiet_ke!$B$8*D31^2 -> 8.5461607 | K31: =Thiet_ke!$B$3*I31+J31 -> 1140.1297 | L31: =(H31-J31)/Thiet_ke!$B$3 -> 0.31152185 | M31: =1.05+0.05*B31^2 -> 3.5 | N31: =(MIN(H31,Thiet_ke!$B$16)-K31)/(Thiet_ke!$B$2*M31) -> 0.83110838 | O31: =IF(N31>0,1/N31,"") -> 1.2032125
A32: 1 | B32: =Thiet_ke!$B$20 -> 7 | C32: =Dau_vao!$B$21+(Dau_vao!$B$19-Dau_vao!$B$21)*30/200 -> 1070 | D32: =2*PI()*C32*Thiet_ke!$B$7/(60*Thiet_ke!$B$15*B32) -> 1.7238163 | E32: =D32*3.6 -> 6.2057387 | F32: =Thiet_ke!$B$12*(Dau_vao!$B$22*(C32/Dau_vao!$B$19)+Dau_vao!$B$23*(C32/Dau_vao!$B$19)^2-Dau_vao!$B$24*(C32/Dau_vao!$B$19)^3) -> 45.64814 | G32: =60000*F32/(2*PI()*C32) -> 407.39031 | H32: =G32*Thiet_ke!$B$15*B32*Dau_vao!$B$10/Thiet_ke!$B$7 -> 23567.967 | I32: =IF(D32<=Dau_vao!$B$14,Dau_vao!$B$13,Dau_vao!$B$13*(1+D32^2/1500)) -> 0.015 | J32: =Thiet_ke!$B$8*D32^2 -> 8.6917623 | K32: =Thiet_ke!$B$3*I32+J32 -> 1140.2753 | L32: =(H32-J32)/Thiet_ke!$B$3 -> 0.31229611 | M32: =1.05+0.05*B32^2 -> 3.5 | N32: =(MIN(H32,Thiet_ke!$B$16)-K32)/(Thiet_ke!$B$2*M32) -> 0.83327852 | O32: =IF(N32>0,1/N32,"") -> 1.2000789
A33: 1 | B33: =Thiet_ke!$B$20 -> 7 | C33: =Dau_vao!$B$21+(Dau_vao!$B$19-Dau_vao!$B$21)*31/200 -> 1079 | D33: =2*PI()*C33*Thiet_ke!$B$7/(60*Thiet_ke!$B$15*B33) -> 1.7383157 | E33: =D33*3.6 -> 6.2579365 | F33: =Thiet_ke!$B$12*(Dau_vao!$B$22*(C33/Dau_vao!$B$19)+Dau_vao!$B$23*(C33/Dau_vao!$B$19)^2-Dau_vao!$B$24*(C33/Dau_vao!$B$19)^3) -> 46.1453 | G33: =60000*F33/(2*PI()*C33) -> 408.39218 | H33: =G33*Thiet_ke!$B$15*B33*Dau_vao!$B$10/Thiet_ke!$B$7 -> 23625.926 | I33: =IF(D33<=Dau_vao!$B$14,Dau_vao!$B$13,Dau_vao!$B$13*(1+D33^2/1500)) -> 0.015 | J33: =Thiet_ke!$B$8*D33^2 -> 8.8385938 | K33: =Thiet_ke!$B$3*I33+J33 -> 1140.4221 | L33: =(H33-J33)/Thiet_ke!$B$3 -> 0.31306245 | M33: =1.05+0.05*B33^2 -> 3.5 | N33: =(MIN(H33,Thiet_ke!$B$16)-K33)/(Thiet_ke!$B$2*M33) -> 0.83542647 | O33: =IF(N33>0,1/N33,"") -> 1.1969934
A34: 1 | B34: =Thiet_ke!$B$20 -> 7 | C34: =Dau_vao!$B$21+(Dau_vao!$B$19-Dau_vao!$B$21)*32/200 -> 1088 | D34: =2*PI()*C34*Thiet_ke!$B$7/(60*Thiet_ke!$B$15*B34) -> 1.7528151 | E34: =D34*3.6 -> 6.3101343 | F34: =Thiet_ke!$B$12*(Dau_vao!$B$22*(C34/Dau_vao!$B$19)+Dau_vao!$B$23*(C34/Dau_vao!$B$19)^2-Dau_vao!$B$24*(C34/Dau_vao!$B$19)^3) -> 46.643175 | G34: =60000*F34/(2*PI()*C34) -> 409.38375 | H34: =G34*Thiet_ke!$B$15*B34*Dau_vao!$B$10/Thiet_ke!$B$7 -> 23683.289 | I34: =IF(D34<=Dau_vao!$B$14,Dau_vao!$B$13,Dau_vao!$B$13*(1+D34^2/1500)) -> 0.015 | J34: =Thiet_ke!$B$8*D34^2 -> 8.9866551 | K34: =Thiet_ke!$B$3*I34+J34 -> 1140.5702 | L34: =(H34-J34)/Thiet_ke!$B$3 -> 0.31382088 | M34: =1.05+0.05*B34^2 -> 3.5 | N34: =(MIN(H34,Thiet_ke!$B$16)-K34)/(Thiet_ke!$B$2*M34) -> 0.83755225 | O34: =IF(N34>0,1/N34,"") -> 1.1939554
A35: 1 | B35: =Thiet_ke!$B$20 -> 7 | C35: =Dau_vao!$B$21+(Dau_vao!$B$19-Dau_vao!$B$21)*33/200 -> 1097 | D35: =2*PI()*C35*Thiet_ke!$B$7/(60*Thiet_ke!$B$15*B35) -> 1.7673145 | E35: =D35*3.6 -> 6.3623321 | F35: =Thiet_ke!$B$12*(Dau_vao!$B$22*(C35/Dau_vao!$B$19)+Dau_vao!$B$23*(C35/Dau_vao!$B$19)^2-Dau_vao!$B$24*(C35/Dau_vao!$B$19)^3) -> 47.141736 | G35: =60000*F35/(2*PI()*C35) -> 410.36501 | H35: =G35*Thiet_ke!$B$15*B35*Dau_vao!$B$10/Thiet_ke!$B$7 -> 23740.056 | I35: =IF(D35<=Dau_vao!$B$14,Dau_vao!$B$13,Dau_vao!$B$13*(1+D35^2/1500)) -> 0.015 | J35: =Thiet_ke!$B$8*D35^2 -> 9.1359463 | K35: =Thiet_ke!$B$3*I35+J35 -> 1140.7194 | L35: =(H35-J35)/Thiet_ke!$B$3 -> 0.3145714 | M35: =1.05+0.05*B35^2 -> 3.5 | N35: =(MIN(H35,Thiet_ke!$B$16)-K35)/(Thiet_ke!$B$2*M35) -> 0.83965584 | O35: =IF(N35>0,1/N35,"") -> 1.1909641
A36: 1 | B36: =Thiet_ke!$B$20 -> 7 | C36: =Dau_vao!$B$21+(Dau_vao!$B$19-Dau_vao!$B$21)*34/200 -> 1106 | D36: =2*PI()*C36*Thiet_ke!$B$7/(60*Thiet_ke!$B$15*B36) -> 1.7818139 | E36: =D36*3.6 -> 6.4145299 | F36: =Thiet_ke!$B$12*(Dau_vao!$B$22*(C36/Dau_vao!$B$19)+Dau_vao!$B$23*(C36/Dau_vao!$B$19)^2-Dau_vao!$B$24*(C36/Dau_vao!$B$19)^3) -> 47.640954 | G36: =60000*F36/(2*PI()*C36) -> 411.33598 | H36: =G36*Thiet_ke!$B$15*B36*Dau_vao!$B$10/Thiet_ke!$B$7 -> 23796.228 | I36: =IF(D36<=Dau_vao!$B$14,Dau_vao!$B$13,Dau_vao!$B$13*(1+D36^2/1500)) -> 0.015 | J36: =Thiet_ke!$B$8*D36^2 -> 9.2864674 | K36: =Thiet_ke!$B$3*I36+J36 -> 1140.87 | L36: =(H36-J36)/Thiet_ke!$B$3 -> 0.315314 | M36: =1.05+0.05*B36^2 -> 3.5 | N36: =(MIN(H36,Thiet_ke!$B$16)-K36)/(Thiet_ke!$B$2*M36) -> 0.84173725 | O36: =IF(N36>0,1/N36,"") -> 1.1880192
A37: 1 | B37: =Thiet_ke!$B$20 -> 7 | C37: =Dau_vao!$B$21+(Dau_vao!$B$19-Dau_vao!$B$21)*35/200 -> 1115 | D37: =2*PI()*C37*Thiet_ke!$B$7/(60*Thiet_ke!$B$15*B37) -> 1.7963133 | E37: =D37*3.6 -> 6.4667277 | F37: =Thiet_ke!$B$12*(Dau_vao!$B$22*(C37/Dau_vao!$B$19)+Dau_vao!$B$23*(C37/Dau_vao!$B$19)^2-Dau_vao!$B$24*(C37/Dau_vao!$B$19)^3) -> 48.140799 | G37: =60000*F37/(2*PI()*C37) -> 412.29665 | H37: =G37*Thiet_ke!$B$15*B37*Dau_vao!$B$10/Thiet_ke!$B$7 -> 23851.804 | I37: =IF(D37<=Dau_vao!$B$14,Dau_vao!$B$13,Dau_vao!$B$13*(1+D37^2/1500)) -> 0.015 | J37: =Thiet_ke!$B$8*D37^2 -> 9.4382183 | K37: =Thiet_ke!$B$3*I37+J37 -> 1141.0217 | L37: =(H37-J37)/Thiet_ke!$B$3 -> 0.31604869 | M37: =1.05+0.05*B37^2 -> 3.5 | N37: =(MIN(H37,Thiet_ke!$B$16)-K37)/(Thiet_ke!$B$2*M37) -> 0.84379647 | O37: =IF(N37>0,1/N37,"") -> 1.1851199
A38: 1 | B38: =Thiet_ke!$B$20 -> 7 | C38: =Dau_vao!$B$21+(Dau_vao!$B$19-Dau_vao!$B$21)*36/200 -> 1124 | D38: =2*PI()*C38*Thiet_ke!$B$7/(60*Thiet_ke!$B$15*B38) -> 1.8108126 | E38: =D38*3.6 -> 6.5189255 | F38: =Thiet_ke!$B$12*(Dau_vao!$B$22*(C38/Dau_vao!$B$19)+Dau_vao!$B$23*(C38/Dau_vao!$B$19)^2-Dau_vao!$B$24*(C38/Dau_vao!$B$19)^3) -> 48.641243 | G38: =60000*F38/(2*PI()*C38) -> 413.24703 | H38: =G38*Thiet_ke!$B$15*B38*Dau_vao!$B$10/Thiet_ke!$B$7 -> 23906.784 | I38: =IF(D38<=Dau_vao!$B$14,Dau_vao!$B$13,Dau_vao!$B$13*(1+D38^2/1500)) -> 0.015 | J38: =Thiet_ke!$B$8*D38^2 -> 9.5911991 | K38: =Thiet_ke!$B$3*I38+J38 -> 1141.1747 | L38: =(H38-J38)/Thiet_ke!$B$3 -> 0.31677547 | M38: =1.05+0.05*B38^2 -> 3.5 | N38: =(MIN(H38,Thiet_ke!$B$16)-K38)/(Thiet_ke!$B$2*M38) -> 0.84583352 | O38: =IF(N38>0,1/N38,"") -> 1.1822658
A39: 1 | B39: =Thiet_ke!$B$20 -> 7 | C39: =Dau_vao!$B$21+(Dau_vao!$B$19-Dau_vao!$B$21)*37/200 -> 1133 | D39: =2*PI()*C39*Thiet_ke!$B$7/(60*Thiet_ke!$B$15*B39) -> 1.825312 | E39: =D39*3.6 -> 6.5711233 | F39: =Thiet_ke!$B$12*(Dau_vao!$B$22*(C39/Dau_vao!$B$19)+Dau_vao!$B$23*(C39/Dau_vao!$B$19)^2-Dau_vao!$B$24*(C39/Dau_vao!$B$19)^3) -> 49.142257 | G39: =60000*F39/(2*PI()*C39) -> 414.1871 | H39: =G39*Thiet_ke!$B$15*B39*Dau_vao!$B$10/Thiet_ke!$B$7 -> 23961.168 | I39: =IF(D39<=Dau_vao!$B$14,Dau_vao!$B$13,Dau_vao!$B$13*(1+D39^2/1500)) -> 0.015 | J39: =Thiet_ke!$B$8*D39^2 -> 9.7454098 | K39: =Thiet_ke!$B$3*I39+J39 -> 1141.3289 | L39: =(H39-J39)/Thiet_ke!$B$3 -> 0.31749433 | M39: =1.05+0.05*B39^2 -> 3.5 | N39: =(MIN(H39,Thiet_ke!$B$16)-K39)/(Thiet_ke!$B$2*M39) -> 0.84784838 | O39: =IF(N39>0,1/N39,"") -> 1.1794562
A40: 1 | B40: =Thiet_ke!$B$20 -> 7 | C40: =Dau_vao!$B$21+(Dau_vao!$B$19-Dau_vao!$B$21)*38/200 -> 1142 | D40: =2*PI()*C40*Thiet_ke!$B$7/(60*Thiet_ke!$B$15*B40) -> 1.8398114 | E40: =D40*3.6 -> 6.6233211 | F40: =Thiet_ke!$B$12*(Dau_vao!$B$22*(C40/Dau_vao!$B$19)+Dau_vao!$B$23*(C40/Dau_vao!$B$19)^2-Dau_vao!$B$24*(C40/Dau_vao!$B$19)^3) -> 49.64381 | G40: =60000*F40/(2*PI()*C40) -> 415.11687 | H40: =G40*Thiet_ke!$B$15*B40*Dau_vao!$B$10/Thiet_ke!$B$7 -> 24014.956 | I40: =IF(D40<=Dau_vao!$B$14,Dau_vao!$B$13,Dau_vao!$B$13*(1+D40^2/1500)) -> 0.015 | J40: =Thiet_ke!$B$8*D40^2 -> 9.9008503 | K40: =Thiet_ke!$B$3*I40+J40 -> 1141.4844 | L40: =(H40-J40)/Thiet_ke!$B$3 -> 0.31820527 | M40: =1.05+0.05*B40^2 -> 3.5 | N40: =(MIN(H40,Thiet_ke!$B$16)-K40)/(Thiet_ke!$B$2*M40) -> 0.84984106 | O40: =IF(N40>0,1/N40,"") -> 1.1766906
...

Sheet Bieu_do_dong

Sheet Tang_toc
A1: BẢN KẾT QUẢ CỐ ĐỊNH — sửa JSON và chạy Python để tính lại
A3: Giai đoạn | B3: Số | C3: t (s) | D3: v (m/s) | E3: S (m) | F3: n (rpm) | G3: j (m/s²)
A4: Bắt đầu | B4: 1 | C4: 0 | D4: 1.2888346 | E4: 0 | F4: 800 | G4: 0.75852499
A5: Kéo | B5: 1 | C5: 0.0081910461 | D5: 1.2950527 | E5: 0.01058235 | F5: 803.85965 | G5: 0.75973425
A6: Kéo | B6: 1 | C6: 0.016369087 | D6: 1.3012707 | E6: 0.021198749 | F6: 807.7193 | G6: 0.76093943
A7: Kéo | B7: 1 | C7: 0.024534207 | D7: 1.3074888 | E7: 0.031849147 | F7: 811.57895 | G7: 0.76214052
A8: Kéo | B8: 1 | C8: 0.032686492 | D8: 1.3137069 | E8: 0.042533494 | F8: 815.4386 | G8: 0.76333754
A9: Kéo | B9: 1 | C9: 0.040826024 | D9: 1.3199249 | E9: 0.05325174 | F9: 819.29825 | G9: 0.76453048
A10: Kéo | B10: 1 | C10: 0.048952888 | D10: 1.326143 | E10: 0.064003836 | F10: 823.15789 | G10: 0.76571933
A11: Kéo | B11: 1 | C11: 0.057067164 | D11: 1.3323611 | E11: 0.074789736 | F11: 827.01754 | G11: 0.76690411
A12: Kéo | B12: 1 | C12: 0.065168937 | D12: 1.3385791 | E12: 0.085609391 | F12: 830.87719 | G12: 0.76808481
A13: Kéo | B13: 1 | C13: 0.073258286 | D13: 1.3447972 | E13: 0.096462756 | F13: 834.73684 | G13: 0.76926143
A14: Kéo | B14: 1 | C14: 0.081335293 | D14: 1.3510152 | E14: 0.10734978 | F14: 838.59649 | G14: 0.77043397
A15: Kéo | B15: 1 | C15: 0.089400039 | D15: 1.3572333 | E15: 0.11827043 | F15: 842.45614 | G15: 0.77160243
... A2117: Kéo | B2117: 5 | C2117: 108.8976 | D2117: 25.069444 | E2117: 2048.7944 | F2117: 2223 | G2117: 0.034350817

Sheet Cong_thuc_nguon
A1: Số CT bài mẫu | B1: Trang in mẫu | C1: Trang in sách | D1: Công thức chuẩn hóa | E1: Ghi chú
A2: 2.1.1; tải cầu | B2: 1 | C2: 136–138 | D2: m=m0+nc·mn+mh; G=mg; G1=β1G; G2=β2G | E2: Tách kg và N; tải cầu ở trạng thái tĩnh.
A3: 2.2.1 | B3: 2 | C3: 139 | D3: Nv=[G·ψv·vmax+K·A·vmax³]/(1000η) | E3: Nv kW; v m/s; ψv=f(vmax) trên đường bằng.
A4: 2.2.2 | B4: 3 | C4: 140, IV-49 | D4: Nmax=Nv/(aλ+bλ²−cλ³) | E4: Công suất thiết kế cực đại, λ=nv/nN.
A5: 2.2.3 | B5: 3 | C5: 140 (cần phân biệt công suất sử dụng) | D5: Nchọn=kN·Nmax | E5: Bài mẫu chọn kN=1,1–1,25; bài này kN=1 để khép kín vmax=95.
A6: 2.2.4 | B6: 3 | C6: 12, I-3 | D6: Me=60000·Ne/(2πn) | E6: Ne kW, n rpm, Me N·m.
A7: 2.2.5 | B7: 3 | C7: 140–141 | D7: nv=λ·nN | E7: Không coi λ là hằng số cho mọi điểm trên đặc tính.
A8: 2.2.6 | B8: 4 | C8: 11, I-2; 12 | D8: Ne=Nmax[a·x+b·x²−c·x³], x=n/nN | E8: Diesel phun trực tiếp: a=0,5; b=1,5; c=1.
A9: 2.3.1 (i0) | B9: 5 | C9: 141, IV-51 | D9: i0=2π·rb·nv/(60·ih_top·ip·vmax) | E9: ip=1, truyền lực phụ không có.
A10: 2.3.1 (rb; mẫu trùng số) | B10: 5 | C10: 37–38 | D10: r0=(B+d/2)·0,0254; rb=λt·r0 | E10: B,d inch; công thức hình học gần đúng cho lốp kiểu cũ.
A11: 2.3.2 | B11: 5 | C11: 35; 95–96; 127–128 | D11: Pψ+Pw+Pj ≤ Pk ≤ Pφ | E11: Ở vận tốc thấp thường bỏ Pw khi chọn số I.
A12: 2.3.3 | B12: 6 | C12: 127–128 | D12: ih1 ≥ ψmax·G·rb/(Memax·i0·ip·η) | E12: Sau chọn phải kiểm lại Pw ở điểm mômen lớn nhất.
... A36: Bổ sung cho đề 95 km/h | B36: Mẫu 75 km/h không cần | C36: 53, II-16 | D36: f=f0 nếu v≤22,2; f=f0(1+v²/1500) nếu v>22,2 | E36: v m/s; mô hình ghép thực nghiệm có bước nhảy tại ngưỡng.

Sheet Hinh_anh
A1: ĐỒ THỊ CỐ ĐỊNH CỦA BỘ THAM SỐ GỐC
